2015-10-16 09:11:26,942 [ERROR] django.request: Internal Server Error: /api/companylist/1/ownerlist/
Traceback (most recent call last):
  File "/Library/Python/2.7/site-packages/django/core/handlers/base.py", line 111, in get_response
    response = wrapped_callback(request, *callback_args, **callback_kwargs)
  File "/Library/Python/2.7/site-packages/django/views/decorators/csrf.py", line 57, in wrapped_view
    return view_func(*args, **kwargs)
  File "/Library/Python/2.7/site-packages/django/views/generic/base.py", line 69, in view
    return self.dispatch(request, *args, **kwargs)
  File "/Library/Python/2.7/site-packages/rest_framework/views.py", line 407, in dispatch
    response = self.handle_exception(exc)
  File "/Library/Python/2.7/site-packages/rest_framework/views.py", line 404, in dispatch
    response = handler(request, *args, **kwargs)
  File "/Library/Python/2.7/site-packages/rest_framework/decorators.py", line 50, in handler
    return func(*args, **kwargs)
  File "/Users/manoj/Documents/companyinfo/companydetails/views.py", line 83, in OwnerList
    name = serializer.validated_data['company']
KeyError: 'company'
2015-10-16 09:14:51,717 [ERROR] django.request: Internal Server Error: /api/companylist/1/ownerlist/1/
Traceback (most recent call last):
  File "/Library/Python/2.7/site-packages/django/core/handlers/base.py", line 111, in get_response
    response = wrapped_callback(request, *callback_args, **callback_kwargs)
  File "/Library/Python/2.7/site-packages/django/views/decorators/csrf.py", line 57, in wrapped_view
    return view_func(*args, **kwargs)
  File "/Library/Python/2.7/site-packages/django/views/generic/base.py", line 69, in view
    return self.dispatch(request, *args, **kwargs)
  File "/Library/Python/2.7/site-packages/rest_framework/views.py", line 407, in dispatch
    response = self.handle_exception(exc)
  File "/Library/Python/2.7/site-packages/rest_framework/views.py", line 404, in dispatch
    response = handler(request, *args, **kwargs)
  File "/Library/Python/2.7/site-packages/rest_framework/decorators.py", line 50, in handler
    return func(*args, **kwargs)
TypeError: OwnerListDetail() got an unexpected keyword argument 'id'
2015-10-16 09:16:33,616 [ERROR] django.request: Internal Server Error: /api/companylist/1/ownerlist/1/
Traceback (most recent call last):
  File "/Library/Python/2.7/site-packages/django/core/handlers/base.py", line 111, in get_response
    response = wrapped_callback(request, *callback_args, **callback_kwargs)
  File "/Library/Python/2.7/site-packages/django/views/decorators/csrf.py", line 57, in wrapped_view
    return view_func(*args, **kwargs)
  File "/Library/Python/2.7/site-packages/django/views/generic/base.py", line 69, in view
    return self.dispatch(request, *args, **kwargs)
  File "/Library/Python/2.7/site-packages/rest_framework/views.py", line 407, in dispatch
    response = self.handle_exception(exc)
  File "/Library/Python/2.7/site-packages/rest_framework/views.py", line 404, in dispatch
    response = handler(request, *args, **kwargs)
  File "/Library/Python/2.7/site-packages/rest_framework/decorators.py", line 50, in handler
    return func(*args, **kwargs)
TypeError: OwnerListDetail() got an unexpected keyword argument 'name'
2015-10-16 09:16:56,554 [ERROR] django.request: Internal Server Error: /api/companylist/1/ownerlist/1/
Traceback (most recent call last):
  File "/Library/Python/2.7/site-packages/django/core/handlers/base.py", line 98, in get_response
    resolver_match = resolver.resolve(request.path_info)
  File "/Library/Python/2.7/site-packages/django/core/urlresolvers.py", line 343, in resolve
    for pattern in self.url_patterns:
  File "/Library/Python/2.7/site-packages/django/core/urlresolvers.py", line 372, in url_patterns
    patterns = getattr(self.urlconf_module, "urlpatterns", self.urlconf_module)
  File "/Library/Python/2.7/site-packages/django/core/urlresolvers.py", line 366, in urlconf_module
    self._urlconf_module = import_module(self.urlconf_name)
  File "/System/Library/Frameworks/Python.framework/Versions/2.7/lib/python2.7/importlib/__init__.py", line 37, in import_module
    __import__(name)
  File "/Users/manoj/Documents/companyinfo/companyinfo/urls.py", line 9, in <module>
    url(r'^api/', include('companydetails.urls')),
  File "/Library/Python/2.7/site-packages/django/conf/urls/__init__.py", line 28, in include
    urlconf_module = import_module(urlconf_module)
  File "/System/Library/Frameworks/Python.framework/Versions/2.7/lib/python2.7/importlib/__init__.py", line 37, in import_module
    __import__(name)
  File "/Users/manoj/Documents/companyinfo/companydetails/urls.py", line 13, in <module>
    urlpatterns = format_suffix_patterns(urlpatterns)
  File "/Library/Python/2.7/site-packages/rest_framework/urlpatterns.py", line 62, in format_suffix_patterns
    return apply_suffix_patterns(urlpatterns, suffix_pattern, suffix_required)
  File "/Library/Python/2.7/site-packages/rest_framework/urlpatterns.py", line 24, in apply_suffix_patterns
    regex = urlpattern.regex.pattern.rstrip('$') + suffix_pattern
  File "/Library/Python/2.7/site-packages/django/core/urlresolvers.py", line 179, in regex
    (regex, six.text_type(e)))
ImproperlyConfigured: "^companylist/(?P<pk>[0-9]+)/ownerlist/(?P<pk>[0-9]+)/$" is not a valid regular expression: redefinition of group name 'pk' as group 2; was group 1
2015-10-16 09:19:07,777 [ERROR] django.request: Internal Server Error: /api/companylist/1/ownerlist/
Traceback (most recent call last):
  File "/Library/Python/2.7/site-packages/django/core/handlers/base.py", line 111, in get_response
    response = wrapped_callback(request, *callback_args, **callback_kwargs)
  File "/Library/Python/2.7/site-packages/django/views/decorators/csrf.py", line 57, in wrapped_view
    return view_func(*args, **kwargs)
  File "/Library/Python/2.7/site-packages/django/views/generic/base.py", line 69, in view
    return self.dispatch(request, *args, **kwargs)
  File "/Library/Python/2.7/site-packages/rest_framework/views.py", line 407, in dispatch
    response = self.handle_exception(exc)
  File "/Library/Python/2.7/site-packages/rest_framework/views.py", line 404, in dispatch
    response = handler(request, *args, **kwargs)
  File "/Library/Python/2.7/site-packages/rest_framework/decorators.py", line 50, in handler
    return func(*args, **kwargs)
  File "/Users/manoj/Documents/companyinfo/companydetails/views.py", line 77, in OwnerList
    return Response(serializer.data)
  File "/Library/Python/2.7/site-packages/rest_framework/serializers.py", line 615, in data
    ret = super(ListSerializer, self).data
  File "/Library/Python/2.7/site-packages/rest_framework/serializers.py", line 212, in data
    self._data = self.to_representation(self.instance)
  File "/Library/Python/2.7/site-packages/rest_framework/serializers.py", line 565, in to_representation
    self.child.to_representation(item) for item in iterable
  File "/Library/Python/2.7/site-packages/rest_framework/serializers.py", line 419, in to_representation
    fields = [field for field in self.fields.values() if not field.write_only]
  File "/Library/Python/2.7/site-packages/rest_framework/serializers.py", line 312, in fields
    for key, value in self.get_fields().items():
  File "/Library/Python/2.7/site-packages/rest_framework/serializers.py", line 911, in get_fields
    (list(missing_fields)[0], self.__class__.__name__)
AssertionError: Field `company` has been declared on serializer `OwnerSerializer`, but is missing from `Meta.fields`.
2015-10-16 09:21:10,612 [ERROR] django.request: Internal Server Error: /api/companylist/1/ownerlist/
Traceback (most recent call last):
  File "/Library/Python/2.7/site-packages/django/core/handlers/base.py", line 111, in get_response
    response = wrapped_callback(request, *callback_args, **callback_kwargs)
  File "/Library/Python/2.7/site-packages/django/views/decorators/csrf.py", line 57, in wrapped_view
    return view_func(*args, **kwargs)
  File "/Library/Python/2.7/site-packages/django/views/generic/base.py", line 69, in view
    return self.dispatch(request, *args, **kwargs)
  File "/Library/Python/2.7/site-packages/rest_framework/views.py", line 407, in dispatch
    response = self.handle_exception(exc)
  File "/Library/Python/2.7/site-packages/rest_framework/views.py", line 404, in dispatch
    response = handler(request, *args, **kwargs)
  File "/Library/Python/2.7/site-packages/rest_framework/decorators.py", line 50, in handler
    return func(*args, **kwargs)
  File "/Users/manoj/Documents/companyinfo/companydetails/views.py", line 83, in OwnerList
    name = serializer.validated_data['company']
KeyError: 'company'
2015-10-16 09:23:54,305 [ERROR] django.request: Internal Server Error: /api/companylist/1/ownerlist/
Traceback (most recent call last):
  File "/Library/Python/2.7/site-packages/django/core/handlers/base.py", line 98, in get_response
    resolver_match = resolver.resolve(request.path_info)
  File "/Library/Python/2.7/site-packages/django/core/urlresolvers.py", line 343, in resolve
    for pattern in self.url_patterns:
  File "/Library/Python/2.7/site-packages/django/core/urlresolvers.py", line 372, in url_patterns
    patterns = getattr(self.urlconf_module, "urlpatterns", self.urlconf_module)
  File "/Library/Python/2.7/site-packages/django/core/urlresolvers.py", line 366, in urlconf_module
    self._urlconf_module = import_module(self.urlconf_name)
  File "/System/Library/Frameworks/Python.framework/Versions/2.7/lib/python2.7/importlib/__init__.py", line 37, in import_module
    __import__(name)
  File "/Users/manoj/Documents/companyinfo/companyinfo/urls.py", line 9, in <module>
    url(r'^api/', include('companydetails.urls')),
  File "/Library/Python/2.7/site-packages/django/conf/urls/__init__.py", line 28, in include
    urlconf_module = import_module(urlconf_module)
  File "/System/Library/Frameworks/Python.framework/Versions/2.7/lib/python2.7/importlib/__init__.py", line 37, in import_module
    __import__(name)
  File "/Users/manoj/Documents/companyinfo/companydetails/urls.py", line 2, in <module>
    from companydetails.views import CompanyList, CompanyListDetail, OwnerList, OwnerListDetail
  File "/Users/manoj/Documents/companyinfo/companydetails/views.py", line 80
    serializer = OwnerSerializer(data=request.DATA, pk)
SyntaxError: non-keyword arg after keyword arg
2015-10-16 09:25:12,567 [ERROR] django.request: Internal Server Error: /api/companylist/1/ownerlist/
Traceback (most recent call last):
  File "/Library/Python/2.7/site-packages/django/core/handlers/base.py", line 98, in get_response
    resolver_match = resolver.resolve(request.path_info)
  File "/Library/Python/2.7/site-packages/django/core/urlresolvers.py", line 343, in resolve
    for pattern in self.url_patterns:
  File "/Library/Python/2.7/site-packages/django/core/urlresolvers.py", line 372, in url_patterns
    patterns = getattr(self.urlconf_module, "urlpatterns", self.urlconf_module)
  File "/Library/Python/2.7/site-packages/django/core/urlresolvers.py", line 366, in urlconf_module
    self._urlconf_module = import_module(self.urlconf_name)
  File "/System/Library/Frameworks/Python.framework/Versions/2.7/lib/python2.7/importlib/__init__.py", line 37, in import_module
    __import__(name)
  File "/Users/manoj/Documents/companyinfo/companyinfo/urls.py", line 9, in <module>
    url(r'^api/', include('companydetails.urls')),
  File "/Library/Python/2.7/site-packages/django/conf/urls/__init__.py", line 28, in include
    urlconf_module = import_module(urlconf_module)
  File "/System/Library/Frameworks/Python.framework/Versions/2.7/lib/python2.7/importlib/__init__.py", line 37, in import_module
    __import__(name)
  File "/Users/manoj/Documents/companyinfo/companydetails/urls.py", line 2, in <module>
    from companydetails.views import CompanyList, CompanyListDetail, OwnerList, OwnerListDetail
ImportError: cannot import name OwnerListDetail
2015-10-16 09:25:57,131 [ERROR] django.request: Internal Server Error: /api/companylist/1/ownerlist/
Traceback (most recent call last):
  File "/Library/Python/2.7/site-packages/django/core/handlers/base.py", line 111, in get_response
    response = wrapped_callback(request, *callback_args, **callback_kwargs)
  File "/Library/Python/2.7/site-packages/django/views/decorators/csrf.py", line 57, in wrapped_view
    return view_func(*args, **kwargs)
  File "/Library/Python/2.7/site-packages/django/views/generic/base.py", line 69, in view
    return self.dispatch(request, *args, **kwargs)
  File "/Library/Python/2.7/site-packages/rest_framework/views.py", line 407, in dispatch
    response = self.handle_exception(exc)
  File "/Library/Python/2.7/site-packages/rest_framework/views.py", line 404, in dispatch
    response = handler(request, *args, **kwargs)
  File "/Library/Python/2.7/site-packages/rest_framework/decorators.py", line 50, in handler
    return func(*args, **kwargs)
  File "/Users/manoj/Documents/companyinfo/companydetails/views.py", line 84, in OwnerList
    name = serializer.validated_data['company']
KeyError: 'company'
2015-10-16 09:33:12,209 [ERROR] django.request: Internal Server Error: /api/companylist/1/ownerlist/
Traceback (most recent call last):
  File "/Library/Python/2.7/site-packages/django/core/handlers/base.py", line 111, in get_response
    response = wrapped_callback(request, *callback_args, **callback_kwargs)
  File "/Library/Python/2.7/site-packages/django/views/decorators/csrf.py", line 57, in wrapped_view
    return view_func(*args, **kwargs)
  File "/Library/Python/2.7/site-packages/django/views/generic/base.py", line 69, in view
    return self.dispatch(request, *args, **kwargs)
  File "/Library/Python/2.7/site-packages/rest_framework/views.py", line 407, in dispatch
    response = self.handle_exception(exc)
  File "/Library/Python/2.7/site-packages/rest_framework/views.py", line 404, in dispatch
    response = handler(request, *args, **kwargs)
  File "/Library/Python/2.7/site-packages/rest_framework/decorators.py", line 50, in handler
    return func(*args, **kwargs)
  File "/Users/manoj/Documents/companyinfo/companydetails/views.py", line 84, in OwnerList
    serializer.save()
  File "/Library/Python/2.7/site-packages/rest_framework/serializers.py", line 164, in save
    self.instance = self.create(validated_data)
  File "/Users/manoj/Documents/companyinfo/companydetails/serializers.py", line 54, in create
    company = validated_data['company'],
KeyError: 'company'
2015-10-16 09:34:00,115 [DEBUG] django.db.backends: (0.001) SHOW TABLES; args=None
2015-10-16 09:34:00,124 [DEBUG] django.db.backends: (0.002) SELECT `django_migrations`.`app`, `django_migrations`.`name` FROM `django_migrations`; args=()
2015-10-16 09:34:08,378 [DEBUG] django.db.backends: (0.001) SELECT `companydetails_ownerdetails`.`id`, `companydetails_ownerdetails`.`company_id`, `companydetails_ownerdetails`.`name` FROM `companydetails_ownerdetails`; args=()
2015-10-16 09:34:08,410 [DEBUG] MARKDOWN: Successfuly imported extension module "markdown.extensions.headerid".
2015-10-16 09:34:08,411 [DEBUG] MARKDOWN: Successfully loaded extension "markdown.extensions.headerid.HeaderIdExtension".
2015-10-16 09:34:13,752 [DEBUG] JSON: validata:OrderedDict([(u'name', u'Robert')])
2015-10-16 09:34:13,752 [ERROR] django.request: Internal Server Error: /api/companylist/1/ownerlist/
Traceback (most recent call last):
  File "/Library/Python/2.7/site-packages/django/core/handlers/base.py", line 111, in get_response
    response = wrapped_callback(request, *callback_args, **callback_kwargs)
  File "/Library/Python/2.7/site-packages/django/views/decorators/csrf.py", line 57, in wrapped_view
    return view_func(*args, **kwargs)
  File "/Library/Python/2.7/site-packages/django/views/generic/base.py", line 69, in view
    return self.dispatch(request, *args, **kwargs)
  File "/Library/Python/2.7/site-packages/rest_framework/views.py", line 407, in dispatch
    response = self.handle_exception(exc)
  File "/Library/Python/2.7/site-packages/rest_framework/views.py", line 404, in dispatch
    response = handler(request, *args, **kwargs)
  File "/Library/Python/2.7/site-packages/rest_framework/decorators.py", line 50, in handler
    return func(*args, **kwargs)
  File "/Users/manoj/Documents/companyinfo/companydetails/views.py", line 84, in OwnerList
    serializer.save()
  File "/Library/Python/2.7/site-packages/rest_framework/serializers.py", line 164, in save
    self.instance = self.create(validated_data)
  File "/Users/manoj/Documents/companyinfo/companydetails/serializers.py", line 54, in create
    company = validated_data['company'],
KeyError: 'company'
2015-10-16 09:36:04,169 [DEBUG] django.db.backends: (0.001) SHOW TABLES; args=None
2015-10-16 09:36:04,177 [DEBUG] django.db.backends: (0.001) SELECT `django_migrations`.`app`, `django_migrations`.`name` FROM `django_migrations`; args=()
2015-10-16 09:41:22,416 [DEBUG] django.db.backends: (0.001) SELECT `companydetails_ownerdetails`.`id`, `companydetails_ownerdetails`.`company_id`, `companydetails_ownerdetails`.`name` FROM `companydetails_ownerdetails`; args=()
2015-10-16 09:41:22,482 [DEBUG] MARKDOWN: Successfuly imported extension module "markdown.extensions.headerid".
2015-10-16 09:41:22,483 [DEBUG] MARKDOWN: Successfully loaded extension "markdown.extensions.headerid.HeaderIdExtension".
2015-10-16 09:41:27,810 [DEBUG] JSON: Data: {'company': u'1', u'company_id': 1, u'name': u'Robert'}
2015-10-16 09:41:27,814 [DEBUG] JSON: validata:OrderedDict([(u'name', u'Robert')])
2015-10-16 09:41:27,814 [ERROR] django.request: Internal Server Error: /api/companylist/1/ownerlist/
Traceback (most recent call last):
  File "/Library/Python/2.7/site-packages/django/core/handlers/base.py", line 111, in get_response
    response = wrapped_callback(request, *callback_args, **callback_kwargs)
  File "/Library/Python/2.7/site-packages/django/views/decorators/csrf.py", line 57, in wrapped_view
    return view_func(*args, **kwargs)
  File "/Library/Python/2.7/site-packages/django/views/generic/base.py", line 69, in view
    return self.dispatch(request, *args, **kwargs)
  File "/Library/Python/2.7/site-packages/rest_framework/views.py", line 407, in dispatch
    response = self.handle_exception(exc)
  File "/Library/Python/2.7/site-packages/rest_framework/views.py", line 404, in dispatch
    response = handler(request, *args, **kwargs)
  File "/Library/Python/2.7/site-packages/rest_framework/decorators.py", line 50, in handler
    return func(*args, **kwargs)
  File "/Users/manoj/Documents/companyinfo/companydetails/views.py", line 85, in OwnerList
    serializer.save()
  File "/Library/Python/2.7/site-packages/rest_framework/serializers.py", line 164, in save
    self.instance = self.create(validated_data)
  File "/Users/manoj/Documents/companyinfo/companydetails/serializers.py", line 54, in create
    company = validated_data['company'],
KeyError: 'company'
2015-10-16 09:42:15,864 [DEBUG] django.db.backends: (0.001) SHOW TABLES; args=None
2015-10-16 09:42:15,907 [DEBUG] django.db.backends: (0.002) SELECT `django_migrations`.`app`, `django_migrations`.`name` FROM `django_migrations`; args=()
2015-10-16 09:42:31,819 [DEBUG] JSON: Data: {'company': 1, u'company_id': 1, u'name': u'Robert'}
2015-10-16 09:42:31,820 [DEBUG] JSON: validata:OrderedDict([(u'name', u'Robert')])
2015-10-16 09:42:31,821 [ERROR] django.request: Internal Server Error: /api/companylist/1/ownerlist/
Traceback (most recent call last):
  File "/Library/Python/2.7/site-packages/django/core/handlers/base.py", line 111, in get_response
    response = wrapped_callback(request, *callback_args, **callback_kwargs)
  File "/Library/Python/2.7/site-packages/django/views/decorators/csrf.py", line 57, in wrapped_view
    return view_func(*args, **kwargs)
  File "/Library/Python/2.7/site-packages/django/views/generic/base.py", line 69, in view
    return self.dispatch(request, *args, **kwargs)
  File "/Library/Python/2.7/site-packages/rest_framework/views.py", line 407, in dispatch
    response = self.handle_exception(exc)
  File "/Library/Python/2.7/site-packages/rest_framework/views.py", line 404, in dispatch
    response = handler(request, *args, **kwargs)
  File "/Library/Python/2.7/site-packages/rest_framework/decorators.py", line 50, in handler
    return func(*args, **kwargs)
  File "/Users/manoj/Documents/companyinfo/companydetails/views.py", line 85, in OwnerList
    serializer.save()
  File "/Library/Python/2.7/site-packages/rest_framework/serializers.py", line 164, in save
    self.instance = self.create(validated_data)
  File "/Users/manoj/Documents/companyinfo/companydetails/serializers.py", line 54, in create
    company = validated_data['company'],
KeyError: 'company'
2015-10-16 09:42:35,959 [DEBUG] django.db.backends: (0.001) SELECT `companydetails_ownerdetails`.`id`, `companydetails_ownerdetails`.`company_id`, `companydetails_ownerdetails`.`name` FROM `companydetails_ownerdetails`; args=()
2015-10-16 09:42:36,014 [DEBUG] MARKDOWN: Successfuly imported extension module "markdown.extensions.headerid".
2015-10-16 09:42:36,015 [DEBUG] MARKDOWN: Successfully loaded extension "markdown.extensions.headerid.HeaderIdExtension".
2015-10-16 09:42:57,873 [DEBUG] JSON: Data: {'company': 1, u'name': u'Robert'}
2015-10-16 09:42:57,875 [DEBUG] JSON: validata:OrderedDict([(u'name', u'Robert')])
2015-10-16 09:42:57,876 [ERROR] django.request: Internal Server Error: /api/companylist/1/ownerlist/
Traceback (most recent call last):
  File "/Library/Python/2.7/site-packages/django/core/handlers/base.py", line 111, in get_response
    response = wrapped_callback(request, *callback_args, **callback_kwargs)
  File "/Library/Python/2.7/site-packages/django/views/decorators/csrf.py", line 57, in wrapped_view
    return view_func(*args, **kwargs)
  File "/Library/Python/2.7/site-packages/django/views/generic/base.py", line 69, in view
    return self.dispatch(request, *args, **kwargs)
  File "/Library/Python/2.7/site-packages/rest_framework/views.py", line 407, in dispatch
    response = self.handle_exception(exc)
  File "/Library/Python/2.7/site-packages/rest_framework/views.py", line 404, in dispatch
    response = handler(request, *args, **kwargs)
  File "/Library/Python/2.7/site-packages/rest_framework/decorators.py", line 50, in handler
    return func(*args, **kwargs)
  File "/Users/manoj/Documents/companyinfo/companydetails/views.py", line 85, in OwnerList
    serializer.save()
  File "/Library/Python/2.7/site-packages/rest_framework/serializers.py", line 164, in save
    self.instance = self.create(validated_data)
  File "/Users/manoj/Documents/companyinfo/companydetails/serializers.py", line 54, in create
    company = validated_data['company'],
KeyError: 'company'
2015-10-16 09:45:16,451 [DEBUG] django.db.backends: (0.001) SHOW TABLES; args=None
2015-10-16 09:45:16,500 [DEBUG] django.db.backends: (0.001) SELECT `django_migrations`.`app`, `django_migrations`.`name` FROM `django_migrations`; args=()
2015-10-16 09:45:21,225 [DEBUG] django.db.backends: (0.001) SELECT `companydetails_ownerdetails`.`id`, `companydetails_ownerdetails`.`company_id`, `companydetails_ownerdetails`.`name` FROM `companydetails_ownerdetails`; args=()
2015-10-16 09:45:21,250 [DEBUG] MARKDOWN: Successfuly imported extension module "markdown.extensions.headerid".
2015-10-16 09:45:21,251 [DEBUG] MARKDOWN: Successfully loaded extension "markdown.extensions.headerid.HeaderIdExtension".
2015-10-16 09:45:25,440 [DEBUG] JSON: Data: {'company': 1, u'name': u'Robert'}
2015-10-16 09:45:25,444 [DEBUG] JSON: validata:OrderedDict([(u'name', u'Robert')])
2015-10-16 09:45:25,444 [DEBUG] JSON: Serializer validate data: {u'name': u'Robert'}
2015-10-16 09:45:25,445 [ERROR] django.request: Internal Server Error: /api/companylist/1/ownerlist/
Traceback (most recent call last):
  File "/Library/Python/2.7/site-packages/django/core/handlers/base.py", line 111, in get_response
    response = wrapped_callback(request, *callback_args, **callback_kwargs)
  File "/Library/Python/2.7/site-packages/django/views/decorators/csrf.py", line 57, in wrapped_view
    return view_func(*args, **kwargs)
  File "/Library/Python/2.7/site-packages/django/views/generic/base.py", line 69, in view
    return self.dispatch(request, *args, **kwargs)
  File "/Library/Python/2.7/site-packages/rest_framework/views.py", line 407, in dispatch
    response = self.handle_exception(exc)
  File "/Library/Python/2.7/site-packages/rest_framework/views.py", line 404, in dispatch
    response = handler(request, *args, **kwargs)
  File "/Library/Python/2.7/site-packages/rest_framework/decorators.py", line 50, in handler
    return func(*args, **kwargs)
  File "/Users/manoj/Documents/companyinfo/companydetails/views.py", line 85, in OwnerList
    serializer.save()
  File "/Library/Python/2.7/site-packages/rest_framework/serializers.py", line 164, in save
    self.instance = self.create(validated_data)
  File "/Users/manoj/Documents/companyinfo/companydetails/serializers.py", line 58, in create
    company = validated_data['company'],
KeyError: 'company'
2015-10-16 09:46:55,007 [DEBUG] django.db.backends: (0.001) SHOW TABLES; args=None
2015-10-16 09:46:55,017 [DEBUG] django.db.backends: (0.001) SELECT `django_migrations`.`app`, `django_migrations`.`name` FROM `django_migrations`; args=()
2015-10-16 09:48:58,400 [DEBUG] django.db.backends: (0.001) SELECT `companydetails_ownerdetails`.`id`, `companydetails_ownerdetails`.`company_id`, `companydetails_ownerdetails`.`name` FROM `companydetails_ownerdetails`; args=()
2015-10-16 09:48:58,475 [DEBUG] MARKDOWN: Successfuly imported extension module "markdown.extensions.headerid".
2015-10-16 09:48:58,476 [DEBUG] MARKDOWN: Successfully loaded extension "markdown.extensions.headerid.HeaderIdExtension".
2015-10-16 09:49:16,322 [DEBUG] JSON: Data: {'company': 1, u'name': u'Mike'}
2015-10-16 09:49:16,339 [DEBUG] django.db.backends: (0.011) SELECT `companydetails_companydetails`.`id`, `companydetails_companydetails`.`company_id`, `companydetails_companydetails`.`name`, `companydetails_companydetails`.`address`, `companydetails_companydetails`.`city`, `companydetails_companydetails`.`country`, `companydetails_companydetails`.`email`, `companydetails_companydetails`.`phone` FROM `companydetails_companydetails` WHERE `companydetails_companydetails`.`id` = 1 LIMIT 21; args=(1,)
2015-10-16 09:49:16,340 [DEBUG] JSON: validata:OrderedDict([(u'name', u'Mike')])
2015-10-16 09:49:16,356 [DEBUG] django.db.backends: (0.014) UPDATE `companydetails_companydetails` SET `company_id` = 100, `name` = 'Mike', `address` = '52 Street', `city` = 'NewYork', `country` = 'US', `email` = 'alex@mail.com', `phone` = '1234567890' WHERE `companydetails_companydetails`.`id` = 1; args=(100, u'Mike', u'52 Street', u'NewYork', u'US', u'alex@mail.com', u'1234567890', 1)
2015-10-16 09:49:16,362 [DEBUG] MARKDOWN: Successfuly imported extension module "markdown.extensions.headerid".
2015-10-16 09:49:16,362 [DEBUG] MARKDOWN: Successfully loaded extension "markdown.extensions.headerid.HeaderIdExtension".
2015-10-16 09:49:23,221 [DEBUG] django.db.backends: (0.000) SELECT `companydetails_ownerdetails`.`id`, `companydetails_ownerdetails`.`company_id`, `companydetails_ownerdetails`.`name` FROM `companydetails_ownerdetails`; args=()
2015-10-16 09:49:23,224 [DEBUG] MARKDOWN: Successfuly imported extension module "markdown.extensions.headerid".
2015-10-16 09:49:23,224 [DEBUG] MARKDOWN: Successfully loaded extension "markdown.extensions.headerid.HeaderIdExtension".
2015-10-16 09:49:26,232 [DEBUG] django.db.backends: (0.001) SELECT `companydetails_ownerdetails`.`id`, `companydetails_ownerdetails`.`company_id`, `companydetails_ownerdetails`.`name` FROM `companydetails_ownerdetails`; args=()
2015-10-16 09:49:26,238 [DEBUG] MARKDOWN: Successfuly imported extension module "markdown.extensions.headerid".
2015-10-16 09:49:26,238 [DEBUG] MARKDOWN: Successfully loaded extension "markdown.extensions.headerid.HeaderIdExtension".
2015-10-16 09:52:11,857 [DEBUG] django.db.backends: (0.001) SHOW TABLES; args=None
2015-10-16 09:52:11,899 [DEBUG] django.db.backends: (0.002) SELECT `django_migrations`.`app`, `django_migrations`.`name` FROM `django_migrations`; args=()
2015-10-16 09:52:17,262 [DEBUG] django.db.backends: (0.001) SELECT `companydetails_ownerdetails`.`id`, `companydetails_ownerdetails`.`company_id`, `companydetails_ownerdetails`.`name` FROM `companydetails_ownerdetails`; args=()
2015-10-16 09:52:17,295 [DEBUG] MARKDOWN: Successfuly imported extension module "markdown.extensions.headerid".
2015-10-16 09:52:17,296 [DEBUG] MARKDOWN: Successfully loaded extension "markdown.extensions.headerid.HeaderIdExtension".
2015-10-16 09:52:20,863 [DEBUG] JSON: Data: {'company': 1, u'name': u'Mike'}
2015-10-16 09:52:20,873 [DEBUG] django.db.backends: (0.001) SELECT `companydetails_companydetails`.`id`, `companydetails_companydetails`.`company_id`, `companydetails_companydetails`.`name`, `companydetails_companydetails`.`address`, `companydetails_companydetails`.`city`, `companydetails_companydetails`.`country`, `companydetails_companydetails`.`email`, `companydetails_companydetails`.`phone` FROM `companydetails_companydetails` WHERE `companydetails_companydetails`.`id` = 1 LIMIT 21; args=(1,)
2015-10-16 09:52:20,875 [DEBUG] JSON: validata:OrderedDict([(u'name', u'Mike')])
2015-10-16 09:52:20,877 [DEBUG] django.db.backends: (0.001) UPDATE `companydetails_companydetails` SET `company_id` = 100, `name` = 'Mike', `address` = '52 Street', `city` = 'NewYork', `country` = 'US', `email` = 'alex@mail.com', `phone` = '1234567890' WHERE `companydetails_companydetails`.`id` = 1; args=(100, u'Mike', u'52 Street', u'NewYork', u'US', u'alex@mail.com', u'1234567890', 1)
2015-10-16 09:52:20,881 [DEBUG] MARKDOWN: Successfuly imported extension module "markdown.extensions.headerid".
2015-10-16 09:52:20,881 [DEBUG] MARKDOWN: Successfully loaded extension "markdown.extensions.headerid.HeaderIdExtension".
2015-10-16 09:52:57,515 [INFO] JSON: Information
2015-10-16 09:52:57,516 [DEBUG] JSON: Project Start
2015-10-16 09:52:57,520 [DEBUG] django.db.backends: (0.001) SELECT `companydetails_companydetails`.`id`, `companydetails_companydetails`.`company_id`, `companydetails_companydetails`.`name`, `companydetails_companydetails`.`address`, `companydetails_companydetails`.`city`, `companydetails_companydetails`.`country`, `companydetails_companydetails`.`email`, `companydetails_companydetails`.`phone` FROM `companydetails_companydetails`; args=()
2015-10-16 09:54:01,511 [DEBUG] django.db.backends: (0.001) SHOW TABLES; args=None
2015-10-16 09:54:01,522 [DEBUG] django.db.backends: (0.003) SELECT `django_migrations`.`app`, `django_migrations`.`name` FROM `django_migrations`; args=()
2015-10-16 09:54:20,742 [ERROR] django.request: Internal Server Error: /api/companylist/1/ownerlist/
Traceback (most recent call last):
  File "/Library/Python/2.7/site-packages/django/core/handlers/base.py", line 98, in get_response
    resolver_match = resolver.resolve(request.path_info)
  File "/Library/Python/2.7/site-packages/django/core/urlresolvers.py", line 343, in resolve
    for pattern in self.url_patterns:
  File "/Library/Python/2.7/site-packages/django/core/urlresolvers.py", line 372, in url_patterns
    patterns = getattr(self.urlconf_module, "urlpatterns", self.urlconf_module)
  File "/Library/Python/2.7/site-packages/django/core/urlresolvers.py", line 366, in urlconf_module
    self._urlconf_module = import_module(self.urlconf_name)
  File "/System/Library/Frameworks/Python.framework/Versions/2.7/lib/python2.7/importlib/__init__.py", line 37, in import_module
    __import__(name)
  File "/Users/manoj/Documents/companyinfo/companyinfo/urls.py", line 9, in <module>
    url(r'^api/', include('companydetails.urls')),
  File "/Library/Python/2.7/site-packages/django/conf/urls/__init__.py", line 28, in include
    urlconf_module = import_module(urlconf_module)
  File "/System/Library/Frameworks/Python.framework/Versions/2.7/lib/python2.7/importlib/__init__.py", line 37, in import_module
    __import__(name)
  File "/Users/manoj/Documents/companyinfo/companydetails/urls.py", line 2, in <module>
    from companydetails.views import CompanyList, CompanyListDetail, OwnerList
  File "/Users/manoj/Documents/companyinfo/companydetails/views.py", line 83
    serializer = OwnerSerializer(obj, data=request.DATA, pk)
SyntaxError: non-keyword arg after keyword arg
2015-10-16 09:54:44,446 [ERROR] django.request: Internal Server Error: /api/companylist/1/ownerlist/
Traceback (most recent call last):
  File "/Library/Python/2.7/site-packages/django/core/handlers/base.py", line 98, in get_response
    resolver_match = resolver.resolve(request.path_info)
  File "/Library/Python/2.7/site-packages/django/core/urlresolvers.py", line 343, in resolve
    for pattern in self.url_patterns:
  File "/Library/Python/2.7/site-packages/django/core/urlresolvers.py", line 372, in url_patterns
    patterns = getattr(self.urlconf_module, "urlpatterns", self.urlconf_module)
  File "/Library/Python/2.7/site-packages/django/core/urlresolvers.py", line 366, in urlconf_module
    self._urlconf_module = import_module(self.urlconf_name)
  File "/System/Library/Frameworks/Python.framework/Versions/2.7/lib/python2.7/importlib/__init__.py", line 37, in import_module
    __import__(name)
  File "/Users/manoj/Documents/companyinfo/companyinfo/urls.py", line 9, in <module>
    url(r'^api/', include('companydetails.urls')),
  File "/Library/Python/2.7/site-packages/django/conf/urls/__init__.py", line 28, in include
    urlconf_module = import_module(urlconf_module)
  File "/System/Library/Frameworks/Python.framework/Versions/2.7/lib/python2.7/importlib/__init__.py", line 37, in import_module
    __import__(name)
  File "/Users/manoj/Documents/companyinfo/companydetails/urls.py", line 2, in <module>
    from companydetails.views import CompanyList, CompanyListDetail, OwnerList
  File "/Users/manoj/Documents/companyinfo/companydetails/views.py", line 83
    serializer = OwnerSerializer(obj, data=request.DATA, pk)
SyntaxError: non-keyword arg after keyword arg
2015-10-16 09:54:46,421 [ERROR] django.request: Internal Server Error: /api/companylist/1/ownerlist/
Traceback (most recent call last):
  File "/Library/Python/2.7/site-packages/django/core/handlers/base.py", line 98, in get_response
    resolver_match = resolver.resolve(request.path_info)
  File "/Library/Python/2.7/site-packages/django/core/urlresolvers.py", line 343, in resolve
    for pattern in self.url_patterns:
  File "/Library/Python/2.7/site-packages/django/core/urlresolvers.py", line 372, in url_patterns
    patterns = getattr(self.urlconf_module, "urlpatterns", self.urlconf_module)
  File "/Library/Python/2.7/site-packages/django/core/urlresolvers.py", line 366, in urlconf_module
    self._urlconf_module = import_module(self.urlconf_name)
  File "/System/Library/Frameworks/Python.framework/Versions/2.7/lib/python2.7/importlib/__init__.py", line 37, in import_module
    __import__(name)
  File "/Users/manoj/Documents/companyinfo/companyinfo/urls.py", line 9, in <module>
    url(r'^api/', include('companydetails.urls')),
  File "/Library/Python/2.7/site-packages/django/conf/urls/__init__.py", line 28, in include
    urlconf_module = import_module(urlconf_module)
  File "/System/Library/Frameworks/Python.framework/Versions/2.7/lib/python2.7/importlib/__init__.py", line 37, in import_module
    __import__(name)
  File "/Users/manoj/Documents/companyinfo/companydetails/urls.py", line 2, in <module>
    from companydetails.views import CompanyList, CompanyListDetail, OwnerList
  File "/Users/manoj/Documents/companyinfo/companydetails/views.py", line 83
    serializer = OwnerSerializer(obj, data=request.DATA, pk)
SyntaxError: non-keyword arg after keyword arg
2015-10-16 09:55:01,070 [ERROR] django.request: Internal Server Error: /api/companylist/1/ownerlist/
Traceback (most recent call last):
  File "/Library/Python/2.7/site-packages/django/core/handlers/base.py", line 98, in get_response
    resolver_match = resolver.resolve(request.path_info)
  File "/Library/Python/2.7/site-packages/django/core/urlresolvers.py", line 343, in resolve
    for pattern in self.url_patterns:
  File "/Library/Python/2.7/site-packages/django/core/urlresolvers.py", line 372, in url_patterns
    patterns = getattr(self.urlconf_module, "urlpatterns", self.urlconf_module)
  File "/Library/Python/2.7/site-packages/django/core/urlresolvers.py", line 366, in urlconf_module
    self._urlconf_module = import_module(self.urlconf_name)
  File "/System/Library/Frameworks/Python.framework/Versions/2.7/lib/python2.7/importlib/__init__.py", line 37, in import_module
    __import__(name)
  File "/Users/manoj/Documents/companyinfo/companyinfo/urls.py", line 9, in <module>
    url(r'^api/', include('companydetails.urls')),
  File "/Library/Python/2.7/site-packages/django/conf/urls/__init__.py", line 28, in include
    urlconf_module = import_module(urlconf_module)
  File "/System/Library/Frameworks/Python.framework/Versions/2.7/lib/python2.7/importlib/__init__.py", line 37, in import_module
    __import__(name)
  File "/Users/manoj/Documents/companyinfo/companydetails/urls.py", line 2, in <module>
    from companydetails.views import CompanyList, CompanyListDetail, OwnerList
  File "/Users/manoj/Documents/companyinfo/companydetails/views.py", line 83
    serializer = OwnerSerializer(obj, data=request.DATA, p)
SyntaxError: non-keyword arg after keyword arg
2015-10-16 10:01:08,677 [DEBUG] django.db.backends: (0.001) SELECT `companydetails_ownerdetails`.`id`, `companydetails_ownerdetails`.`company_id`, `companydetails_ownerdetails`.`name` FROM `companydetails_ownerdetails`; args=()
2015-10-16 10:01:08,734 [DEBUG] MARKDOWN: Successfuly imported extension module "markdown.extensions.headerid".
2015-10-16 10:01:08,735 [DEBUG] MARKDOWN: Successfully loaded extension "markdown.extensions.headerid.HeaderIdExtension".
2015-10-16 10:01:29,219 [DEBUG] JSON: Data: {'company': 1, u'name': u'Allen'}
2015-10-16 10:01:29,220 [DEBUG] JSON: validata:OrderedDict([(u'name', u'Allen')])
2015-10-16 10:01:29,220 [DEBUG] JSON: Serializer validate data: {'company': 1, u'name': u'Allen'}
2015-10-16 10:01:29,221 [ERROR] django.request: Internal Server Error: /api/companylist/1/ownerlist/
Traceback (most recent call last):
  File "/Library/Python/2.7/site-packages/django/core/handlers/base.py", line 111, in get_response
    response = wrapped_callback(request, *callback_args, **callback_kwargs)
  File "/Library/Python/2.7/site-packages/django/views/decorators/csrf.py", line 57, in wrapped_view
    return view_func(*args, **kwargs)
  File "/Library/Python/2.7/site-packages/django/views/generic/base.py", line 69, in view
    return self.dispatch(request, *args, **kwargs)
  File "/Library/Python/2.7/site-packages/rest_framework/views.py", line 407, in dispatch
    response = self.handle_exception(exc)
  File "/Library/Python/2.7/site-packages/rest_framework/views.py", line 404, in dispatch
    response = handler(request, *args, **kwargs)
  File "/Library/Python/2.7/site-packages/rest_framework/decorators.py", line 50, in handler
    return func(*args, **kwargs)
  File "/Users/manoj/Documents/companyinfo/companydetails/views.py", line 85, in OwnerList
    serializer.save(company=int(pk))
  File "/Library/Python/2.7/site-packages/rest_framework/serializers.py", line 164, in save
    self.instance = self.create(validated_data)
  File "/Users/manoj/Documents/companyinfo/companydetails/serializers.py", line 59, in create
    name = validated_data['name'],
  File "/Library/Python/2.7/site-packages/django/db/models/manager.py", line 92, in manager_method
    return getattr(self.get_queryset(), name)(*args, **kwargs)
  File "/Library/Python/2.7/site-packages/django/db/models/query.py", line 370, in create
    obj = self.model(**kwargs)
  File "/Library/Python/2.7/site-packages/django/db/models/base.py", line 452, in __init__
    raise TypeError("'%s' is an invalid keyword argument for this function" % list(kwargs)[0])
TypeError: 'company' is an invalid keyword argument for this function
2015-10-16 10:01:29,380 [DEBUG] django.db.backends: (0.001) SELECT `companydetails_companydetails`.`id`, `companydetails_companydetails`.`company_id`, `companydetails_companydetails`.`name`, `companydetails_companydetails`.`address`, `companydetails_companydetails`.`city`, `companydetails_companydetails`.`country`, `companydetails_companydetails`.`email`, `companydetails_companydetails`.`phone` FROM `companydetails_companydetails` LIMIT 21; args=()
2015-10-16 10:01:55,270 [DEBUG] django.db.backends: (0.001) SHOW TABLES; args=None
2015-10-16 10:01:55,318 [DEBUG] django.db.backends: (0.002) SELECT `django_migrations`.`app`, `django_migrations`.`name` FROM `django_migrations`; args=()
2015-10-16 10:03:27,595 [DEBUG] django.db.backends: (0.001) SELECT `companydetails_ownerdetails`.`id`, `companydetails_ownerdetails`.`company_id`, `companydetails_ownerdetails`.`name` FROM `companydetails_ownerdetails`; args=()
2015-10-16 10:03:27,667 [DEBUG] MARKDOWN: Successfuly imported extension module "markdown.extensions.headerid".
2015-10-16 10:03:27,668 [DEBUG] MARKDOWN: Successfully loaded extension "markdown.extensions.headerid.HeaderIdExtension".
2015-10-16 10:03:41,084 [DEBUG] JSON: Data: {'company': 1, u'name': u'Robert'}
2015-10-16 10:03:41,087 [DEBUG] JSON: validata:OrderedDict([(u'name', u'Robert')])
2015-10-16 10:03:41,088 [DEBUG] JSON: Serializer validate data: {u'name': u'Robert', 'company_id': 1}
2015-10-16 10:03:41,102 [DEBUG] django.db.backends: (0.011) INSERT INTO `companydetails_companydetails` (`company_id`, `name`, `address`, `city`, `country`, `email`, `phone`) VALUES (NULL, 'Robert', '', '', '', NULL, NULL); args=[None, u'Robert', u'', u'', u'', None, None]
2015-10-16 10:03:41,104 [ERROR] django.request: Internal Server Error: /api/companylist/1/ownerlist/
Traceback (most recent call last):
  File "/Library/Python/2.7/site-packages/django/core/handlers/base.py", line 111, in get_response
    response = wrapped_callback(request, *callback_args, **callback_kwargs)
  File "/Library/Python/2.7/site-packages/django/views/decorators/csrf.py", line 57, in wrapped_view
    return view_func(*args, **kwargs)
  File "/Library/Python/2.7/site-packages/django/views/generic/base.py", line 69, in view
    return self.dispatch(request, *args, **kwargs)
  File "/Library/Python/2.7/site-packages/rest_framework/views.py", line 407, in dispatch
    response = self.handle_exception(exc)
  File "/Library/Python/2.7/site-packages/rest_framework/views.py", line 404, in dispatch
    response = handler(request, *args, **kwargs)
  File "/Library/Python/2.7/site-packages/rest_framework/decorators.py", line 50, in handler
    return func(*args, **kwargs)
  File "/Users/manoj/Documents/companyinfo/companydetails/views.py", line 85, in OwnerList
    serializer.save(company_id=int(pk))
  File "/Library/Python/2.7/site-packages/rest_framework/serializers.py", line 164, in save
    self.instance = self.create(validated_data)
  File "/Users/manoj/Documents/companyinfo/companydetails/serializers.py", line 59, in create
    name = validated_data['name'],
  File "/Library/Python/2.7/site-packages/django/db/models/manager.py", line 92, in manager_method
    return getattr(self.get_queryset(), name)(*args, **kwargs)
  File "/Library/Python/2.7/site-packages/django/db/models/query.py", line 372, in create
    obj.save(force_insert=True, using=self.db)
  File "/Library/Python/2.7/site-packages/django/db/models/base.py", line 589, in save
    force_update=force_update, update_fields=update_fields)
  File "/Library/Python/2.7/site-packages/django/db/models/base.py", line 617, in save_base
    updated = self._save_table(raw, cls, force_insert, force_update, using, update_fields)
  File "/Library/Python/2.7/site-packages/django/db/models/base.py", line 698, in _save_table
    result = self._do_insert(cls._base_manager, using, fields, update_pk, raw)
  File "/Library/Python/2.7/site-packages/django/db/models/base.py", line 731, in _do_insert
    using=using, raw=raw)
  File "/Library/Python/2.7/site-packages/django/db/models/manager.py", line 92, in manager_method
    return getattr(self.get_queryset(), name)(*args, **kwargs)
  File "/Library/Python/2.7/site-packages/django/db/models/query.py", line 921, in _insert
    return query.get_compiler(using=using).execute_sql(return_id)
  File "/Library/Python/2.7/site-packages/django/db/models/sql/compiler.py", line 920, in execute_sql
    cursor.execute(sql, params)
  File "/Library/Python/2.7/site-packages/django/db/backends/utils.py", line 81, in execute
    return super(CursorDebugWrapper, self).execute(sql, params)
  File "/Library/Python/2.7/site-packages/django/db/backends/utils.py", line 65, in execute
    return self.cursor.execute(sql, params)
  File "/Library/Python/2.7/site-packages/mysql/connector/django/base.py", line 135, in execute
    return self._execute_wrapper(self.cursor.execute, query, args)
  File "/Library/Python/2.7/site-packages/mysql/connector/django/base.py", line 121, in _execute_wrapper
    utils.IntegrityError(err.msg), sys.exc_info()[2])
  File "/Library/Python/2.7/site-packages/mysql/connector/django/base.py", line 115, in _execute_wrapper
    return method(query, args)
  File "/Library/Python/2.7/site-packages/mysql/connector/cursor.py", line 507, in execute
    self._handle_result(self._connection.cmd_query(stmt))
  File "/Library/Python/2.7/site-packages/mysql/connector/connection.py", line 722, in cmd_query
    result = self._handle_result(self._send_cmd(ServerCmd.QUERY, query))
  File "/Library/Python/2.7/site-packages/mysql/connector/connection.py", line 640, in _handle_result
    raise errors.get_exception(packet)
IntegrityError: Column 'company_id' cannot be null
2015-10-16 10:03:41,230 [DEBUG] django.db.backends: (0.001) SELECT `companydetails_companydetails`.`id`, `companydetails_companydetails`.`company_id`, `companydetails_companydetails`.`name`, `companydetails_companydetails`.`address`, `companydetails_companydetails`.`city`, `companydetails_companydetails`.`country`, `companydetails_companydetails`.`email`, `companydetails_companydetails`.`phone` FROM `companydetails_companydetails` LIMIT 21; args=()
2015-10-16 10:03:41,234 [DEBUG] django.db.backends: (0.001) SELECT `companydetails_companydetails`.`id`, `companydetails_companydetails`.`company_id`, `companydetails_companydetails`.`name`, `companydetails_companydetails`.`address`, `companydetails_companydetails`.`city`, `companydetails_companydetails`.`country`, `companydetails_companydetails`.`email`, `companydetails_companydetails`.`phone` FROM `companydetails_companydetails` LIMIT 21; args=()
2015-10-16 10:03:59,206 [DEBUG] django.db.backends: (0.001) SHOW TABLES; args=None
2015-10-16 10:03:59,240 [DEBUG] django.db.backends: (0.002) SELECT `django_migrations`.`app`, `django_migrations`.`name` FROM `django_migrations`; args=()
2015-10-16 10:04:21,881 [DEBUG] django.db.backends: (0.001) SELECT `companydetails_ownerdetails`.`id`, `companydetails_ownerdetails`.`company_id`, `companydetails_ownerdetails`.`name` FROM `companydetails_ownerdetails`; args=()
2015-10-16 10:04:21,915 [DEBUG] MARKDOWN: Successfuly imported extension module "markdown.extensions.headerid".
2015-10-16 10:04:21,915 [DEBUG] MARKDOWN: Successfully loaded extension "markdown.extensions.headerid.HeaderIdExtension".
2015-10-16 10:04:52,423 [DEBUG] JSON: Data: {'company': 1, u'name': u'Paul'}
2015-10-16 10:04:52,428 [DEBUG] JSON: validata:OrderedDict([(u'name', u'Paul')])
2015-10-16 10:04:52,428 [DEBUG] JSON: Serializer validate data: {u'name': u'Paul', 'company_id': 1}
2015-10-16 10:04:52,428 [ERROR] django.request: Internal Server Error: /api/companylist/1/ownerlist/
Traceback (most recent call last):
  File "/Library/Python/2.7/site-packages/django/core/handlers/base.py", line 111, in get_response
    response = wrapped_callback(request, *callback_args, **callback_kwargs)
  File "/Library/Python/2.7/site-packages/django/views/decorators/csrf.py", line 57, in wrapped_view
    return view_func(*args, **kwargs)
  File "/Library/Python/2.7/site-packages/django/views/generic/base.py", line 69, in view
    return self.dispatch(request, *args, **kwargs)
  File "/Library/Python/2.7/site-packages/rest_framework/views.py", line 407, in dispatch
    response = self.handle_exception(exc)
  File "/Library/Python/2.7/site-packages/rest_framework/views.py", line 404, in dispatch
    response = handler(request, *args, **kwargs)
  File "/Library/Python/2.7/site-packages/rest_framework/decorators.py", line 50, in handler
    return func(*args, **kwargs)
  File "/Users/manoj/Documents/companyinfo/companydetails/views.py", line 85, in OwnerList
    serializer.save(company_id=int(pk))
  File "/Library/Python/2.7/site-packages/rest_framework/serializers.py", line 164, in save
    self.instance = self.create(validated_data)
  File "/Users/manoj/Documents/companyinfo/companydetails/serializers.py", line 58, in create
    company_id = validated_data['company'],
KeyError: 'company'
2015-10-16 10:05:48,536 [DEBUG] django.db.backends: (0.002) SHOW TABLES; args=None
2015-10-16 10:05:48,579 [DEBUG] django.db.backends: (0.002) SELECT `django_migrations`.`app`, `django_migrations`.`name` FROM `django_migrations`; args=()
2015-10-16 10:05:50,485 [DEBUG] django.db.backends: (0.001) SELECT `companydetails_ownerdetails`.`id`, `companydetails_ownerdetails`.`company_id`, `companydetails_ownerdetails`.`name` FROM `companydetails_ownerdetails`; args=()
2015-10-16 10:05:50,559 [DEBUG] MARKDOWN: Successfuly imported extension module "markdown.extensions.headerid".
2015-10-16 10:05:50,559 [DEBUG] MARKDOWN: Successfully loaded extension "markdown.extensions.headerid.HeaderIdExtension".
2015-10-16 10:06:05,876 [DEBUG] JSON: Data: {'company': 1, u'name': u'Joseph'}
2015-10-16 10:06:05,880 [DEBUG] JSON: validata:OrderedDict([(u'name', u'Joseph')])
2015-10-16 10:06:05,880 [DEBUG] JSON: Serializer validate data: {u'name': u'Joseph', 'company_id': 1}
2015-10-16 10:06:05,886 [DEBUG] django.db.backends: (0.003) INSERT INTO `companydetails_companydetails` (`company_id`, `name`, `address`, `city`, `country`, `email`, `phone`) VALUES (1, 'Joseph', '', '', '', NULL, NULL); args=[1, u'Joseph', u'', u'', u'', None, None]
2015-10-16 10:06:05,892 [DEBUG] MARKDOWN: Successfuly imported extension module "markdown.extensions.headerid".
2015-10-16 10:06:05,893 [DEBUG] MARKDOWN: Successfully loaded extension "markdown.extensions.headerid.HeaderIdExtension".
2015-10-16 10:06:12,358 [DEBUG] django.db.backends: (0.000) SELECT `companydetails_ownerdetails`.`id`, `companydetails_ownerdetails`.`company_id`, `companydetails_ownerdetails`.`name` FROM `companydetails_ownerdetails`; args=()
2015-10-16 10:06:12,363 [DEBUG] MARKDOWN: Successfuly imported extension module "markdown.extensions.headerid".
2015-10-16 10:06:12,364 [DEBUG] MARKDOWN: Successfully loaded extension "markdown.extensions.headerid.HeaderIdExtension".
2015-10-16 10:06:15,087 [DEBUG] django.db.backends: (0.001) SELECT `companydetails_ownerdetails`.`id`, `companydetails_ownerdetails`.`company_id`, `companydetails_ownerdetails`.`name` FROM `companydetails_ownerdetails`; args=()
2015-10-16 10:06:15,090 [DEBUG] MARKDOWN: Successfuly imported extension module "markdown.extensions.headerid".
2015-10-16 10:06:15,090 [DEBUG] MARKDOWN: Successfully loaded extension "markdown.extensions.headerid.HeaderIdExtension".
2015-10-16 10:07:15,472 [DEBUG] django.db.backends: (0.001) SHOW TABLES; args=None
2015-10-16 10:07:15,496 [DEBUG] django.db.backends: (0.001) SELECT `django_migrations`.`app`, `django_migrations`.`name` FROM `django_migrations`; args=()
2015-10-16 10:07:17,258 [DEBUG] django.db.backends: (0.001) SELECT `companydetails_ownerdetails`.`id`, `companydetails_ownerdetails`.`company_id`, `companydetails_ownerdetails`.`name` FROM `companydetails_ownerdetails`; args=()
2015-10-16 10:07:17,292 [DEBUG] MARKDOWN: Successfuly imported extension module "markdown.extensions.headerid".
2015-10-16 10:07:17,293 [DEBUG] MARKDOWN: Successfully loaded extension "markdown.extensions.headerid.HeaderIdExtension".
2015-10-16 10:07:55,813 [DEBUG] JSON: Data: {'company': 1, u'name': u'Lehman'}
2015-10-16 10:07:55,820 [DEBUG] JSON: validata:OrderedDict([(u'name', u'Lehman')])
2015-10-16 10:07:55,821 [DEBUG] JSON: Serializer validate data: {u'name': u'Lehman', 'company_id': 1}
2015-10-16 10:07:55,825 [DEBUG] django.db.backends: (0.001) INSERT INTO `companydetails_ownerdetails` (`company_id`, `name`) VALUES (1, 'Lehman'); args=[1, u'Lehman']
2015-10-16 10:07:55,829 [DEBUG] MARKDOWN: Successfuly imported extension module "markdown.extensions.headerid".
2015-10-16 10:07:55,830 [DEBUG] MARKDOWN: Successfully loaded extension "markdown.extensions.headerid.HeaderIdExtension".
2015-10-16 10:07:59,466 [DEBUG] django.db.backends: (0.001) SELECT `companydetails_ownerdetails`.`id`, `companydetails_ownerdetails`.`company_id`, `companydetails_ownerdetails`.`name` FROM `companydetails_ownerdetails`; args=()
2015-10-16 10:07:59,469 [DEBUG] MARKDOWN: Successfuly imported extension module "markdown.extensions.headerid".
2015-10-16 10:07:59,470 [DEBUG] MARKDOWN: Successfully loaded extension "markdown.extensions.headerid.HeaderIdExtension".
2015-10-16 10:08:13,716 [INFO] JSON: Information
2015-10-16 10:08:13,716 [DEBUG] JSON: Project Start
2015-10-16 10:08:13,720 [DEBUG] django.db.backends: (0.001) SELECT `companydetails_companydetails`.`id`, `companydetails_companydetails`.`company_id`, `companydetails_companydetails`.`name`, `companydetails_companydetails`.`address`, `companydetails_companydetails`.`city`, `companydetails_companydetails`.`country`, `companydetails_companydetails`.`email`, `companydetails_companydetails`.`phone` FROM `companydetails_companydetails`; args=()
2015-10-16 10:08:15,424 [DEBUG] django.db.backends: (0.001) SELECT `companydetails_companydetails`.`id`, `companydetails_companydetails`.`company_id`, `companydetails_companydetails`.`name`, `companydetails_companydetails`.`address`, `companydetails_companydetails`.`city`, `companydetails_companydetails`.`country`, `companydetails_companydetails`.`email`, `companydetails_companydetails`.`phone` FROM `companydetails_companydetails` WHERE `companydetails_companydetails`.`id` = 10 LIMIT 21; args=(10,)
2015-10-16 10:08:15,428 [DEBUG] django.db.backends: (0.002) DELETE FROM `companydetails_ownerdetails` WHERE `companydetails_ownerdetails`.`company_id` IN (10); args=(10,)
2015-10-16 10:08:15,429 [DEBUG] django.db.backends: (0.001) DELETE FROM `companydetails_companydetails` WHERE `companydetails_companydetails`.`id` IN (10); args=(10,)
2015-10-16 10:08:15,440 [INFO] JSON: Information
2015-10-16 10:08:15,440 [DEBUG] JSON: Project Start
2015-10-16 10:08:15,444 [DEBUG] django.db.backends: (0.001) SELECT `companydetails_companydetails`.`id`, `companydetails_companydetails`.`company_id`, `companydetails_companydetails`.`name`, `companydetails_companydetails`.`address`, `companydetails_companydetails`.`city`, `companydetails_companydetails`.`country`, `companydetails_companydetails`.`email`, `companydetails_companydetails`.`phone` FROM `companydetails_companydetails`; args=()
2015-10-16 10:08:23,284 [DEBUG] django.db.backends: (0.001) SHOW TABLES; args=None
2015-10-16 10:08:23,293 [DEBUG] django.db.backends: (0.001) SELECT `django_migrations`.`app`, `django_migrations`.`name` FROM `django_migrations`; args=()
2015-10-16 10:08:33,424 [DEBUG] django.db.backends: (0.001) SELECT `companydetails_ownerdetails`.`id`, `companydetails_ownerdetails`.`company_id`, `companydetails_ownerdetails`.`name` FROM `companydetails_ownerdetails`; args=()
2015-10-16 10:08:33,449 [DEBUG] MARKDOWN: Successfuly imported extension module "markdown.extensions.headerid".
2015-10-16 10:08:33,449 [DEBUG] MARKDOWN: Successfully loaded extension "markdown.extensions.headerid.HeaderIdExtension".
2015-10-16 10:08:36,132 [DEBUG] django.db.backends: (0.001) SELECT `companydetails_ownerdetails`.`id`, `companydetails_ownerdetails`.`company_id`, `companydetails_ownerdetails`.`name` FROM `companydetails_ownerdetails`; args=()
2015-10-16 10:08:36,141 [DEBUG] MARKDOWN: Successfuly imported extension module "markdown.extensions.headerid".
2015-10-16 10:08:36,141 [DEBUG] MARKDOWN: Successfully loaded extension "markdown.extensions.headerid.HeaderIdExtension".
2015-10-16 10:09:04,044 [DEBUG] django.db.backends: (0.000) SELECT `companydetails_ownerdetails`.`id`, `companydetails_ownerdetails`.`company_id`, `companydetails_ownerdetails`.`name` FROM `companydetails_ownerdetails`; args=()
2015-10-16 10:09:04,049 [DEBUG] MARKDOWN: Successfuly imported extension module "markdown.extensions.headerid".
2015-10-16 10:09:04,049 [DEBUG] MARKDOWN: Successfully loaded extension "markdown.extensions.headerid.HeaderIdExtension".
2015-10-16 10:09:19,174 [DEBUG] JSON: Data: {'company': 1, u'name': u'Jessica'}
2015-10-16 10:09:19,177 [DEBUG] JSON: validata:OrderedDict([(u'name', u'Jessica')])
2015-10-16 10:09:19,178 [DEBUG] JSON: Serializer validate data: {u'name': u'Jessica', 'company_id': 1}
2015-10-16 10:09:19,182 [DEBUG] django.db.backends: (0.000) INSERT INTO `companydetails_ownerdetails` (`company_id`, `name`) VALUES (9, 'Jessica'); args=[9, u'Jessica']
2015-10-16 10:09:19,186 [DEBUG] MARKDOWN: Successfuly imported extension module "markdown.extensions.headerid".
2015-10-16 10:09:19,186 [DEBUG] MARKDOWN: Successfully loaded extension "markdown.extensions.headerid.HeaderIdExtension".
2015-10-16 10:09:22,051 [DEBUG] django.db.backends: (0.001) SELECT `companydetails_ownerdetails`.`id`, `companydetails_ownerdetails`.`company_id`, `companydetails_ownerdetails`.`name` FROM `companydetails_ownerdetails`; args=()
2015-10-16 10:09:22,054 [DEBUG] MARKDOWN: Successfuly imported extension module "markdown.extensions.headerid".
2015-10-16 10:09:22,054 [DEBUG] MARKDOWN: Successfully loaded extension "markdown.extensions.headerid.HeaderIdExtension".
2015-10-16 10:40:53,606 [DEBUG] django.db.backends: (0.002) SHOW TABLES; args=None
2015-10-16 10:40:53,648 [DEBUG] django.db.backends: (0.002) SELECT `django_migrations`.`app`, `django_migrations`.`name` FROM `django_migrations`; args=()
2015-10-16 10:54:33,398 [ERROR] django.request: Internal Server Error: /api/companylist/1/ownerlist/
Traceback (most recent call last):
  File "/Library/Python/2.7/site-packages/django/core/handlers/base.py", line 111, in get_response
    response = wrapped_callback(request, *callback_args, **callback_kwargs)
  File "/Library/Python/2.7/site-packages/django/views/decorators/csrf.py", line 57, in wrapped_view
    return view_func(*args, **kwargs)
  File "/Library/Python/2.7/site-packages/django/views/generic/base.py", line 69, in view
    return self.dispatch(request, *args, **kwargs)
  File "/Library/Python/2.7/site-packages/rest_framework/views.py", line 407, in dispatch
    response = self.handle_exception(exc)
  File "/Library/Python/2.7/site-packages/rest_framework/views.py", line 404, in dispatch
    response = handler(request, *args, **kwargs)
  File "/Library/Python/2.7/site-packages/rest_framework/decorators.py", line 50, in handler
    return func(*args, **kwargs)
  File "/Users/manoj/Documents/companyinfo/companydetails/views.py", line 77, in OwnerList
    return Response(serializer.data)
  File "/Library/Python/2.7/site-packages/rest_framework/serializers.py", line 615, in data
    ret = super(ListSerializer, self).data
  File "/Library/Python/2.7/site-packages/rest_framework/serializers.py", line 212, in data
    self._data = self.to_representation(self.instance)
  File "/Library/Python/2.7/site-packages/rest_framework/serializers.py", line 565, in to_representation
    self.child.to_representation(item) for item in iterable
TypeError: 'OwnerDetails' object is not iterable
2015-10-16 10:57:59,036 [ERROR] django.request: Internal Server Error: /api/companylist/1/ownerlist/
Traceback (most recent call last):
  File "/Library/Python/2.7/site-packages/django/core/handlers/base.py", line 111, in get_response
    response = wrapped_callback(request, *callback_args, **callback_kwargs)
  File "/Library/Python/2.7/site-packages/django/views/decorators/csrf.py", line 57, in wrapped_view
    return view_func(*args, **kwargs)
  File "/Library/Python/2.7/site-packages/django/views/generic/base.py", line 69, in view
    return self.dispatch(request, *args, **kwargs)
  File "/Library/Python/2.7/site-packages/rest_framework/views.py", line 407, in dispatch
    response = self.handle_exception(exc)
  File "/Library/Python/2.7/site-packages/rest_framework/views.py", line 404, in dispatch
    response = handler(request, *args, **kwargs)
  File "/Library/Python/2.7/site-packages/rest_framework/decorators.py", line 50, in handler
    return func(*args, **kwargs)
  File "/Users/manoj/Documents/companyinfo/companydetails/views.py", line 77, in OwnerList
    serializer = serializer.data.filter(company_id=pk)
AttributeError: 'ReturnList' object has no attribute 'filter'
2015-10-16 10:58:49,915 [ERROR] django.request: Internal Server Error: /api/companylist/1/ownerlist/
Traceback (most recent call last):
  File "/Library/Python/2.7/site-packages/django/core/handlers/base.py", line 111, in get_response
    response = wrapped_callback(request, *callback_args, **callback_kwargs)
  File "/Library/Python/2.7/site-packages/django/views/decorators/csrf.py", line 57, in wrapped_view
    return view_func(*args, **kwargs)
  File "/Library/Python/2.7/site-packages/django/views/generic/base.py", line 69, in view
    return self.dispatch(request, *args, **kwargs)
  File "/Library/Python/2.7/site-packages/rest_framework/views.py", line 407, in dispatch
    response = self.handle_exception(exc)
  File "/Library/Python/2.7/site-packages/rest_framework/views.py", line 404, in dispatch
    response = handler(request, *args, **kwargs)
  File "/Library/Python/2.7/site-packages/rest_framework/decorators.py", line 50, in handler
    return func(*args, **kwargs)
  File "/Users/manoj/Documents/companyinfo/companydetails/views.py", line 77, in OwnerList
    serializer = serializer.data.filter(company_id=pk)
AttributeError: 'ReturnList' object has no attribute 'filter'
2015-10-16 10:59:12,291 [DEBUG] django.db.backends: (0.001) SHOW TABLES; args=None
2015-10-16 10:59:12,301 [DEBUG] django.db.backends: (0.001) SELECT `django_migrations`.`app`, `django_migrations`.`name` FROM `django_migrations`; args=()
2015-10-16 10:59:18,853 [DEBUG] django.db.backends: (0.001) SHOW TABLES; args=None
2015-10-16 10:59:18,862 [DEBUG] django.db.backends: (0.001) SELECT `django_migrations`.`app`, `django_migrations`.`name` FROM `django_migrations`; args=()
2015-10-16 11:00:35,150 [DEBUG] django.db.backends: (0.001) SELECT `companydetails_ownerdetails`.`id`, `companydetails_ownerdetails`.`company_id`, `companydetails_ownerdetails`.`name` FROM `companydetails_ownerdetails`; args=()
2015-10-16 11:00:35,153 [DEBUG] JSON: Get List: [OrderedDict([('id', 1), ('company_id', 1), ('name', u'Robert')]), OrderedDict([('id', 2), ('company_id', 1), ('name', u'Lehman')]), OrderedDict([('id', 3), ('company_id', 9), ('name', u'Jessica')])]
2015-10-16 11:00:35,206 [DEBUG] MARKDOWN: Successfuly imported extension module "markdown.extensions.headerid".
2015-10-16 11:00:35,206 [DEBUG] MARKDOWN: Successfully loaded extension "markdown.extensions.headerid.HeaderIdExtension".
2015-10-16 11:03:03,470 [DEBUG] django.db.backends: (0.002) SHOW TABLES; args=None
2015-10-16 11:03:03,482 [DEBUG] django.db.backends: (0.002) SELECT `django_migrations`.`app`, `django_migrations`.`name` FROM `django_migrations`; args=()
2015-10-16 11:03:04,391 [DEBUG] django.db.backends: (0.001) SELECT `companydetails_ownerdetails`.`id`, `companydetails_ownerdetails`.`company_id`, `companydetails_ownerdetails`.`name` FROM `companydetails_ownerdetails`; args=()
2015-10-16 11:03:04,394 [ERROR] django.request: Internal Server Error: /api/companylist/1/ownerlist/
Traceback (most recent call last):
  File "/Library/Python/2.7/site-packages/django/core/handlers/base.py", line 111, in get_response
    response = wrapped_callback(request, *callback_args, **callback_kwargs)
  File "/Library/Python/2.7/site-packages/django/views/decorators/csrf.py", line 57, in wrapped_view
    return view_func(*args, **kwargs)
  File "/Library/Python/2.7/site-packages/django/views/generic/base.py", line 69, in view
    return self.dispatch(request, *args, **kwargs)
  File "/Library/Python/2.7/site-packages/rest_framework/views.py", line 407, in dispatch
    response = self.handle_exception(exc)
  File "/Library/Python/2.7/site-packages/rest_framework/views.py", line 404, in dispatch
    response = handler(request, *args, **kwargs)
  File "/Library/Python/2.7/site-packages/rest_framework/decorators.py", line 50, in handler
    return func(*args, **kwargs)
  File "/Users/manoj/Documents/companyinfo/companydetails/views.py", line 77, in OwnerList
    ser_dict=dict(serializer.data)
ValueError: dictionary update sequence element #0 has length 3; 2 is required
2015-10-16 11:03:30,490 [DEBUG] django.db.backends: (0.001) SHOW TABLES; args=None
2015-10-16 11:03:30,500 [DEBUG] django.db.backends: (0.002) SELECT `django_migrations`.`app`, `django_migrations`.`name` FROM `django_migrations`; args=()
2015-10-16 11:03:32,546 [DEBUG] django.db.backends: (0.001) SELECT `companydetails_ownerdetails`.`id`, `companydetails_ownerdetails`.`company_id`, `companydetails_ownerdetails`.`name` FROM `companydetails_ownerdetails`; args=()
2015-10-16 11:03:32,549 [ERROR] django.request: Internal Server Error: /api/companylist/1/ownerlist/
Traceback (most recent call last):
  File "/Library/Python/2.7/site-packages/django/core/handlers/base.py", line 111, in get_response
    response = wrapped_callback(request, *callback_args, **callback_kwargs)
  File "/Library/Python/2.7/site-packages/django/views/decorators/csrf.py", line 57, in wrapped_view
    return view_func(*args, **kwargs)
  File "/Library/Python/2.7/site-packages/django/views/generic/base.py", line 69, in view
    return self.dispatch(request, *args, **kwargs)
  File "/Library/Python/2.7/site-packages/rest_framework/views.py", line 407, in dispatch
    response = self.handle_exception(exc)
  File "/Library/Python/2.7/site-packages/rest_framework/views.py", line 404, in dispatch
    response = handler(request, *args, **kwargs)
  File "/Library/Python/2.7/site-packages/rest_framework/decorators.py", line 50, in handler
    return func(*args, **kwargs)
  File "/Users/manoj/Documents/companyinfo/companydetails/views.py", line 78, in OwnerList
    ser_dict=dict(serializer.data)
ValueError: dictionary update sequence element #0 has length 3; 2 is required
2015-10-16 11:03:57,540 [DEBUG] django.db.backends: (0.001) SHOW TABLES; args=None
2015-10-16 11:03:57,550 [DEBUG] django.db.backends: (0.001) SELECT `django_migrations`.`app`, `django_migrations`.`name` FROM `django_migrations`; args=()
2015-10-16 11:03:58,253 [DEBUG] django.db.backends: (0.001) SELECT `companydetails_ownerdetails`.`id`, `companydetails_ownerdetails`.`company_id`, `companydetails_ownerdetails`.`name` FROM `companydetails_ownerdetails`; args=()
2015-10-16 11:03:58,255 [ERROR] django.request: Internal Server Error: /api/companylist/1/ownerlist/
Traceback (most recent call last):
  File "/Library/Python/2.7/site-packages/django/core/handlers/base.py", line 111, in get_response
    response = wrapped_callback(request, *callback_args, **callback_kwargs)
  File "/Library/Python/2.7/site-packages/django/views/decorators/csrf.py", line 57, in wrapped_view
    return view_func(*args, **kwargs)
  File "/Library/Python/2.7/site-packages/django/views/generic/base.py", line 69, in view
    return self.dispatch(request, *args, **kwargs)
  File "/Library/Python/2.7/site-packages/rest_framework/views.py", line 407, in dispatch
    response = self.handle_exception(exc)
  File "/Library/Python/2.7/site-packages/rest_framework/views.py", line 404, in dispatch
    response = handler(request, *args, **kwargs)
  File "/Library/Python/2.7/site-packages/rest_framework/decorators.py", line 50, in handler
    return func(*args, **kwargs)
  File "/Users/manoj/Documents/companyinfo/companydetails/views.py", line 78, in OwnerList
    ser_dict=dict(serializer.data)
ValueError: dictionary update sequence element #0 has length 3; 2 is required
2015-10-16 11:05:42,116 [DEBUG] django.db.backends: (0.001) SHOW TABLES; args=None
2015-10-16 11:05:42,126 [DEBUG] django.db.backends: (0.001) SELECT `django_migrations`.`app`, `django_migrations`.`name` FROM `django_migrations`; args=()
2015-10-16 11:05:44,957 [ERROR] django.request: Internal Server Error: /api/companylist/1/ownerlist/
Traceback (most recent call last):
  File "/Library/Python/2.7/site-packages/django/core/handlers/base.py", line 111, in get_response
    response = wrapped_callback(request, *callback_args, **callback_kwargs)
  File "/Library/Python/2.7/site-packages/django/views/decorators/csrf.py", line 57, in wrapped_view
    return view_func(*args, **kwargs)
  File "/Library/Python/2.7/site-packages/django/views/generic/base.py", line 69, in view
    return self.dispatch(request, *args, **kwargs)
  File "/Library/Python/2.7/site-packages/rest_framework/views.py", line 407, in dispatch
    response = self.handle_exception(exc)
  File "/Library/Python/2.7/site-packages/rest_framework/views.py", line 404, in dispatch
    response = handler(request, *args, **kwargs)
  File "/Library/Python/2.7/site-packages/rest_framework/decorators.py", line 50, in handler
    return func(*args, **kwargs)
  File "/Users/manoj/Documents/companyinfo/companydetails/views.py", line 74, in OwnerList
    obj = OwnerDetails.objects.filte(company_id=pk)
AttributeError: 'Manager' object has no attribute 'filte'
2015-10-16 11:05:57,851 [DEBUG] django.db.backends: (0.001) SHOW TABLES; args=None
2015-10-16 11:05:57,861 [DEBUG] django.db.backends: (0.001) SELECT `django_migrations`.`app`, `django_migrations`.`name` FROM `django_migrations`; args=()
2015-10-16 11:05:58,570 [DEBUG] django.db.backends: (0.008) SELECT `companydetails_ownerdetails`.`id`, `companydetails_ownerdetails`.`company_id`, `companydetails_ownerdetails`.`name` FROM `companydetails_ownerdetails` WHERE `companydetails_ownerdetails`.`company_id` = 1; args=(1,)
2015-10-16 11:05:58,573 [DEBUG] JSON: Get List: [OrderedDict([('id', 1), ('company_id', 1), ('name', u'Robert')]), OrderedDict([('id', 2), ('company_id', 1), ('name', u'Lehman')])]
2015-10-16 11:05:58,599 [DEBUG] MARKDOWN: Successfuly imported extension module "markdown.extensions.headerid".
2015-10-16 11:05:58,600 [DEBUG] MARKDOWN: Successfully loaded extension "markdown.extensions.headerid.HeaderIdExtension".
2015-10-16 11:06:08,243 [DEBUG] django.db.backends: (0.001) SELECT `companydetails_ownerdetails`.`id`, `companydetails_ownerdetails`.`company_id`, `companydetails_ownerdetails`.`name` FROM `companydetails_ownerdetails` WHERE `companydetails_ownerdetails`.`company_id` = 9; args=(9,)
2015-10-16 11:06:08,247 [DEBUG] JSON: Get List: [OrderedDict([('id', 3), ('company_id', 9), ('name', u'Jessica')])]
2015-10-16 11:06:08,249 [DEBUG] MARKDOWN: Successfuly imported extension module "markdown.extensions.headerid".
2015-10-16 11:06:08,249 [DEBUG] MARKDOWN: Successfully loaded extension "markdown.extensions.headerid.HeaderIdExtension".
2015-10-16 11:06:16,391 [DEBUG] django.db.backends: (0.001) SELECT `companydetails_ownerdetails`.`id`, `companydetails_ownerdetails`.`company_id`, `companydetails_ownerdetails`.`name` FROM `companydetails_ownerdetails` WHERE `companydetails_ownerdetails`.`company_id` = 4; args=(4,)
2015-10-16 11:06:16,392 [DEBUG] JSON: Get List: []
2015-10-16 11:06:16,394 [DEBUG] MARKDOWN: Successfuly imported extension module "markdown.extensions.headerid".
2015-10-16 11:06:16,395 [DEBUG] MARKDOWN: Successfully loaded extension "markdown.extensions.headerid.HeaderIdExtension".
2015-10-16 11:06:24,857 [DEBUG] django.db.backends: (0.001) SHOW TABLES; args=None
2015-10-16 11:06:24,865 [DEBUG] django.db.backends: (0.001) SELECT `django_migrations`.`app`, `django_migrations`.`name` FROM `django_migrations`; args=()
2015-10-16 11:07:23,896 [DEBUG] JSON: Data: {'company': 4, u'name': u'Simon'}
2015-10-16 11:07:23,897 [DEBUG] JSON: validata:OrderedDict([(u'name', u'Simon')])
2015-10-16 11:07:23,911 [DEBUG] django.db.backends: (0.010) INSERT INTO `companydetails_ownerdetails` (`company_id`, `name`) VALUES (4, 'Simon'); args=[4, u'Simon']
2015-10-16 11:07:23,913 [ERROR] django.request: Internal Server Error: /api/companylist/4/ownerlist/
Traceback (most recent call last):
  File "/Library/Python/2.7/site-packages/django/core/handlers/base.py", line 111, in get_response
    response = wrapped_callback(request, *callback_args, **callback_kwargs)
  File "/Library/Python/2.7/site-packages/django/views/decorators/csrf.py", line 57, in wrapped_view
    return view_func(*args, **kwargs)
  File "/Library/Python/2.7/site-packages/django/views/generic/base.py", line 69, in view
    return self.dispatch(request, *args, **kwargs)
  File "/Library/Python/2.7/site-packages/rest_framework/views.py", line 407, in dispatch
    response = self.handle_exception(exc)
  File "/Library/Python/2.7/site-packages/rest_framework/views.py", line 404, in dispatch
    response = handler(request, *args, **kwargs)
  File "/Library/Python/2.7/site-packages/rest_framework/decorators.py", line 50, in handler
    return func(*args, **kwargs)
  File "/Users/manoj/Documents/companyinfo/companydetails/views.py", line 86, in OwnerList
    serializer.save(company_id=int(pk))
  File "/Library/Python/2.7/site-packages/rest_framework/serializers.py", line 164, in save
    self.instance = self.create(validated_data)
  File "/Library/Python/2.7/site-packages/rest_framework/serializers.py", line 768, in create
    instance = ModelClass.objects.create(**validated_data)
  File "/Library/Python/2.7/site-packages/django/db/models/manager.py", line 92, in manager_method
    return getattr(self.get_queryset(), name)(*args, **kwargs)
  File "/Library/Python/2.7/site-packages/django/db/models/query.py", line 372, in create
    obj.save(force_insert=True, using=self.db)
  File "/Library/Python/2.7/site-packages/django/db/models/base.py", line 589, in save
    force_update=force_update, update_fields=update_fields)
  File "/Library/Python/2.7/site-packages/django/db/models/base.py", line 617, in save_base
    updated = self._save_table(raw, cls, force_insert, force_update, using, update_fields)
  File "/Library/Python/2.7/site-packages/django/db/models/base.py", line 698, in _save_table
    result = self._do_insert(cls._base_manager, using, fields, update_pk, raw)
  File "/Library/Python/2.7/site-packages/django/db/models/base.py", line 731, in _do_insert
    using=using, raw=raw)
  File "/Library/Python/2.7/site-packages/django/db/models/manager.py", line 92, in manager_method
    return getattr(self.get_queryset(), name)(*args, **kwargs)
  File "/Library/Python/2.7/site-packages/django/db/models/query.py", line 921, in _insert
    return query.get_compiler(using=using).execute_sql(return_id)
  File "/Library/Python/2.7/site-packages/django/db/models/sql/compiler.py", line 920, in execute_sql
    cursor.execute(sql, params)
  File "/Library/Python/2.7/site-packages/django/db/backends/utils.py", line 81, in execute
    return super(CursorDebugWrapper, self).execute(sql, params)
  File "/Library/Python/2.7/site-packages/django/db/backends/utils.py", line 65, in execute
    return self.cursor.execute(sql, params)
  File "/Library/Python/2.7/site-packages/mysql/connector/django/base.py", line 135, in execute
    return self._execute_wrapper(self.cursor.execute, query, args)
  File "/Library/Python/2.7/site-packages/mysql/connector/django/base.py", line 121, in _execute_wrapper
    utils.IntegrityError(err.msg), sys.exc_info()[2])
  File "/Library/Python/2.7/site-packages/mysql/connector/django/base.py", line 115, in _execute_wrapper
    return method(query, args)
  File "/Library/Python/2.7/site-packages/mysql/connector/cursor.py", line 507, in execute
    self._handle_result(self._connection.cmd_query(stmt))
  File "/Library/Python/2.7/site-packages/mysql/connector/connection.py", line 722, in cmd_query
    result = self._handle_result(self._send_cmd(ServerCmd.QUERY, query))
  File "/Library/Python/2.7/site-packages/mysql/connector/connection.py", line 640, in _handle_result
    raise errors.get_exception(packet)
IntegrityError: Cannot add or update a child row: a foreign key constraint fails (`companyinfo`.`companydetails_ownerdetails`, CONSTRAINT `company_id_422034f4422a8de2_fk_companydetails_companydetails_id` FOREIGN KEY (`company_id`) REFERENCES `companydetails_companydetails` )
2015-10-16 11:07:23,990 [DEBUG] django.db.backends: (0.001) SELECT `companydetails_ownerdetails`.`id`, `companydetails_ownerdetails`.`company_id`, `companydetails_ownerdetails`.`name` FROM `companydetails_ownerdetails` LIMIT 21; args=()
2015-10-16 11:07:23,994 [DEBUG] django.db.backends: (0.001) SELECT `companydetails_ownerdetails`.`id`, `companydetails_ownerdetails`.`company_id`, `companydetails_ownerdetails`.`name` FROM `companydetails_ownerdetails` LIMIT 21; args=()
2015-10-16 11:20:11,786 [DEBUG] django.db.backends: (0.001) SHOW TABLES; args=None
2015-10-16 11:20:11,829 [DEBUG] django.db.backends: (0.002) SELECT `django_migrations`.`app`, `django_migrations`.`name` FROM `django_migrations`; args=()
2015-10-16 11:20:14,806 [DEBUG] django.db.backends: (0.001) SELECT `companydetails_ownerdetails`.`id`, `companydetails_ownerdetails`.`company_id`, `companydetails_ownerdetails`.`name` FROM `companydetails_ownerdetails` WHERE `companydetails_ownerdetails`.`company_id` = 4; args=(4,)
2015-10-16 11:20:14,807 [DEBUG] JSON: Get List: []
2015-10-16 11:20:14,874 [DEBUG] MARKDOWN: Successfuly imported extension module "markdown.extensions.headerid".
2015-10-16 11:20:14,875 [DEBUG] MARKDOWN: Successfully loaded extension "markdown.extensions.headerid.HeaderIdExtension".
2015-10-16 11:21:08,299 [DEBUG] JSON: Data: {'company': 4, u'name': u'Anthony'}
2015-10-16 11:21:08,300 [DEBUG] JSON: validata:OrderedDict([(u'name', u'Anthony')])
2015-10-16 11:21:08,301 [DEBUG] JSON: Serializer validate data: {u'name': u'Anthony', 'company_id': 4}
2015-10-16 11:21:08,307 [DEBUG] django.db.backends: (0.001) INSERT INTO `companydetails_ownerdetails` (`company_id`, `name`) VALUES (9, 'Anthony'); args=[9, u'Anthony']
2015-10-16 11:21:08,312 [DEBUG] MARKDOWN: Successfuly imported extension module "markdown.extensions.headerid".
2015-10-16 11:21:08,312 [DEBUG] MARKDOWN: Successfully loaded extension "markdown.extensions.headerid.HeaderIdExtension".
2015-10-16 11:21:53,261 [DEBUG] django.db.backends: (0.001) SELECT `companydetails_ownerdetails`.`id`, `companydetails_ownerdetails`.`company_id`, `companydetails_ownerdetails`.`name` FROM `companydetails_ownerdetails` WHERE `companydetails_ownerdetails`.`company_id` = 7; args=(7,)
2015-10-16 11:21:53,261 [DEBUG] JSON: Get List: []
2015-10-16 11:21:53,263 [DEBUG] MARKDOWN: Successfuly imported extension module "markdown.extensions.headerid".
2015-10-16 11:21:53,263 [DEBUG] MARKDOWN: Successfully loaded extension "markdown.extensions.headerid.HeaderIdExtension".
2015-10-16 11:23:25,665 [DEBUG] django.db.backends: (0.001) SHOW TABLES; args=None
2015-10-16 11:23:25,674 [DEBUG] django.db.backends: (0.001) SELECT `django_migrations`.`app`, `django_migrations`.`name` FROM `django_migrations`; args=()
2015-10-16 11:23:45,245 [DEBUG] django.db.backends: (0.001) SELECT `companydetails_ownerdetails`.`id`, `companydetails_ownerdetails`.`company_id`, `companydetails_ownerdetails`.`name` FROM `companydetails_ownerdetails` WHERE `companydetails_ownerdetails`.`company_id` = 7; args=(7,)
2015-10-16 11:23:45,246 [DEBUG] JSON: Get List: []
2015-10-16 11:23:45,278 [DEBUG] MARKDOWN: Successfuly imported extension module "markdown.extensions.headerid".
2015-10-16 11:23:45,279 [DEBUG] MARKDOWN: Successfully loaded extension "markdown.extensions.headerid.HeaderIdExtension".
2015-10-16 11:23:59,061 [DEBUG] JSON: Data: {'company': 7, u'name': u'Albert'}
2015-10-16 11:23:59,063 [DEBUG] JSON: validata:OrderedDict([(u'name', u'Albert')])
2015-10-16 11:23:59,064 [DEBUG] JSON: Serializer validate data: {u'name': u'Albert', 'company_id': 7}
2015-10-16 11:23:59,071 [DEBUG] django.db.backends: (0.001) INSERT INTO `companydetails_ownerdetails` (`company_id`, `name`) VALUES (7, 'Albert'); args=[7, u'Albert']
2015-10-16 11:23:59,076 [DEBUG] MARKDOWN: Successfuly imported extension module "markdown.extensions.headerid".
2015-10-16 11:23:59,077 [DEBUG] MARKDOWN: Successfully loaded extension "markdown.extensions.headerid.HeaderIdExtension".
2015-10-16 11:24:04,455 [DEBUG] django.db.backends: (0.001) SELECT `companydetails_ownerdetails`.`id`, `companydetails_ownerdetails`.`company_id`, `companydetails_ownerdetails`.`name` FROM `companydetails_ownerdetails` WHERE `companydetails_ownerdetails`.`company_id` = 7; args=(7,)
2015-10-16 11:24:04,457 [DEBUG] JSON: Get List: [OrderedDict([('id', 6), ('company_id', 7), ('name', u'Albert')])]
2015-10-16 11:24:04,460 [DEBUG] MARKDOWN: Successfuly imported extension module "markdown.extensions.headerid".
2015-10-16 11:24:04,460 [DEBUG] MARKDOWN: Successfully loaded extension "markdown.extensions.headerid.HeaderIdExtension".
2015-10-16 11:26:39,437 [DEBUG] django.db.backends: (0.001) SHOW TABLES; args=None
2015-10-16 11:26:39,446 [DEBUG] django.db.backends: (0.001) SELECT `django_migrations`.`app`, `django_migrations`.`name` FROM `django_migrations`; args=()
2015-10-16 11:51:17,238 [INFO] JSON: Information
2015-10-16 11:51:17,239 [DEBUG] JSON: Project Start
2015-10-16 11:51:17,245 [DEBUG] django.db.backends: (0.002) SELECT `companydetails_companydetails`.`id`, `companydetails_companydetails`.`company_id`, `companydetails_companydetails`.`name`, `companydetails_companydetails`.`address`, `companydetails_companydetails`.`city`, `companydetails_companydetails`.`country`, `companydetails_companydetails`.`email`, `companydetails_companydetails`.`phone` FROM `companydetails_companydetails`; args=()
2015-10-16 11:51:38,597 [INFO] JSON: Information
2015-10-16 11:51:38,597 [DEBUG] JSON: Project Start
2015-10-16 11:51:38,601 [DEBUG] django.db.backends: (0.001) SELECT `companydetails_companydetails`.`id`, `companydetails_companydetails`.`company_id`, `companydetails_companydetails`.`name`, `companydetails_companydetails`.`address`, `companydetails_companydetails`.`city`, `companydetails_companydetails`.`country`, `companydetails_companydetails`.`email`, `companydetails_companydetails`.`phone` FROM `companydetails_companydetails`; args=()
2015-10-16 11:51:59,944 [INFO] JSON: Information
2015-10-16 11:51:59,945 [DEBUG] JSON: Project Start
2015-10-16 11:51:59,948 [DEBUG] django.db.backends: (0.001) SELECT `companydetails_companydetails`.`id`, `companydetails_companydetails`.`company_id`, `companydetails_companydetails`.`name`, `companydetails_companydetails`.`address`, `companydetails_companydetails`.`city`, `companydetails_companydetails`.`country`, `companydetails_companydetails`.`email`, `companydetails_companydetails`.`phone` FROM `companydetails_companydetails`; args=()
2015-10-16 11:52:01,400 [WARNING] django.request: Not Found: /api/companylist/7ownerslist
2015-10-16 11:52:15,475 [WARNING] django.request: Not Found: /api/companylist/7ownerslist
2015-10-16 11:52:19,250 [WARNING] django.request: Not Found: /api/companylist/8ownerslist
2015-10-16 11:52:23,420 [INFO] JSON: Information
2015-10-16 11:52:23,420 [DEBUG] JSON: Project Start
2015-10-16 11:52:23,424 [DEBUG] django.db.backends: (0.001) SELECT `companydetails_companydetails`.`id`, `companydetails_companydetails`.`company_id`, `companydetails_companydetails`.`name`, `companydetails_companydetails`.`address`, `companydetails_companydetails`.`city`, `companydetails_companydetails`.`country`, `companydetails_companydetails`.`email`, `companydetails_companydetails`.`phone` FROM `companydetails_companydetails`; args=()
2015-10-16 11:52:25,193 [WARNING] django.request: Not Found: /api/companylist/8ownerslist/
2015-10-16 11:52:43,315 [INFO] JSON: Information
2015-10-16 11:52:43,315 [DEBUG] JSON: Project Start
2015-10-16 11:52:43,319 [DEBUG] django.db.backends: (0.001) SELECT `companydetails_companydetails`.`id`, `companydetails_companydetails`.`company_id`, `companydetails_companydetails`.`name`, `companydetails_companydetails`.`address`, `companydetails_companydetails`.`city`, `companydetails_companydetails`.`country`, `companydetails_companydetails`.`email`, `companydetails_companydetails`.`phone` FROM `companydetails_companydetails`; args=()
2015-10-16 11:52:44,195 [WARNING] django.request: Not Found: /api/companylist/7/ownerslist/
2015-10-16 11:53:16,831 [DEBUG] django.db.backends: (0.002) SHOW TABLES; args=None
2015-10-16 11:53:16,880 [DEBUG] django.db.backends: (0.002) SELECT `django_migrations`.`app`, `django_migrations`.`name` FROM `django_migrations`; args=()
2015-10-16 11:55:59,472 [INFO] JSON: Information
2015-10-16 11:55:59,473 [DEBUG] JSON: Project Start
2015-10-16 11:55:59,476 [DEBUG] django.db.backends: (0.001) SELECT `companydetails_companydetails`.`id`, `companydetails_companydetails`.`company_id`, `companydetails_companydetails`.`name`, `companydetails_companydetails`.`address`, `companydetails_companydetails`.`city`, `companydetails_companydetails`.`country`, `companydetails_companydetails`.`email`, `companydetails_companydetails`.`phone` FROM `companydetails_companydetails`; args=()
2015-10-16 11:56:01,484 [WARNING] django.request: Not Found: /api/companylist/1/ownerslist/
2015-10-16 11:57:10,087 [DEBUG] django.db.backends: (0.001) SHOW TABLES; args=None
2015-10-16 11:57:10,096 [DEBUG] django.db.backends: (0.001) SELECT `django_migrations`.`app`, `django_migrations`.`name` FROM `django_migrations`; args=()
2015-10-16 11:57:10,898 [ERROR] django.request: Internal Server Error: /api/companylist/1/ownerslist/
Traceback (most recent call last):
  File "/Library/Python/2.7/site-packages/django/core/handlers/base.py", line 98, in get_response
    resolver_match = resolver.resolve(request.path_info)
  File "/Library/Python/2.7/site-packages/django/core/urlresolvers.py", line 345, in resolve
    sub_match = pattern.resolve(new_path)
  File "/Library/Python/2.7/site-packages/django/core/urlresolvers.py", line 211, in resolve
    match = self.regex.search(path)
  File "/Library/Python/2.7/site-packages/django/core/urlresolvers.py", line 179, in regex
    (regex, six.text_type(e)))
ImproperlyConfigured: "^index/companylist/(?P[0-9]+)/ownerslist$" is not a valid regular expression: unknown specifier: ?P[
2015-10-16 11:57:18,688 [DEBUG] django.db.backends: (0.001) SHOW TABLES; args=None
2015-10-16 11:57:18,696 [DEBUG] django.db.backends: (0.001) SELECT `django_migrations`.`app`, `django_migrations`.`name` FROM `django_migrations`; args=()
2015-10-16 11:57:19,651 [ERROR] django.request: Internal Server Error: /api/companylist/1/ownerslist/
Traceback (most recent call last):
  File "/Library/Python/2.7/site-packages/django/core/handlers/base.py", line 98, in get_response
    resolver_match = resolver.resolve(request.path_info)
  File "/Library/Python/2.7/site-packages/django/core/urlresolvers.py", line 345, in resolve
    sub_match = pattern.resolve(new_path)
  File "/Library/Python/2.7/site-packages/django/core/urlresolvers.py", line 211, in resolve
    match = self.regex.search(path)
  File "/Library/Python/2.7/site-packages/django/core/urlresolvers.py", line 179, in regex
    (regex, six.text_type(e)))
ImproperlyConfigured: "^index/companylist/(?[0-9]+)/ownerslist$" is not a valid regular expression: unexpected end of pattern
2015-10-16 11:58:36,697 [DEBUG] django.db.backends: (0.001) SHOW TABLES; args=None
2015-10-16 11:58:36,706 [DEBUG] django.db.backends: (0.001) SELECT `django_migrations`.`app`, `django_migrations`.`name` FROM `django_migrations`; args=()
2015-10-16 12:00:19,388 [INFO] JSON: Information
2015-10-16 12:00:19,389 [DEBUG] JSON: Project Start
2015-10-16 12:00:19,392 [DEBUG] django.db.backends: (0.001) SELECT `companydetails_companydetails`.`id`, `companydetails_companydetails`.`company_id`, `companydetails_companydetails`.`name`, `companydetails_companydetails`.`address`, `companydetails_companydetails`.`city`, `companydetails_companydetails`.`country`, `companydetails_companydetails`.`email`, `companydetails_companydetails`.`phone` FROM `companydetails_companydetails`; args=()
2015-10-16 12:00:20,660 [WARNING] django.request: Not Found: /api/companylist/8/ownerslist/
2015-10-16 12:00:47,663 [INFO] JSON: Information
2015-10-16 12:00:47,663 [DEBUG] JSON: Project Start
2015-10-16 12:00:47,668 [DEBUG] django.db.backends: (0.001) SELECT `companydetails_companydetails`.`id`, `companydetails_companydetails`.`company_id`, `companydetails_companydetails`.`name`, `companydetails_companydetails`.`address`, `companydetails_companydetails`.`city`, `companydetails_companydetails`.`country`, `companydetails_companydetails`.`email`, `companydetails_companydetails`.`phone` FROM `companydetails_companydetails`; args=()
2015-10-16 12:00:47,909 [WARNING] django.request: Not Found: /index/companylist/7/ownerslist/
2015-10-16 12:01:21,583 [DEBUG] django.db.backends: (0.001) SHOW TABLES; args=None
2015-10-16 12:01:21,592 [DEBUG] django.db.backends: (0.001) SELECT `django_migrations`.`app`, `django_migrations`.`name` FROM `django_migrations`; args=()
2015-10-16 12:01:25,658 [INFO] JSON: Information
2015-10-16 12:01:25,658 [DEBUG] JSON: Project Start
2015-10-16 12:01:25,662 [DEBUG] django.db.backends: (0.001) SELECT `companydetails_companydetails`.`id`, `companydetails_companydetails`.`company_id`, `companydetails_companydetails`.`name`, `companydetails_companydetails`.`address`, `companydetails_companydetails`.`city`, `companydetails_companydetails`.`country`, `companydetails_companydetails`.`email`, `companydetails_companydetails`.`phone` FROM `companydetails_companydetails`; args=()
2015-10-16 12:01:26,386 [ERROR] django.request: Internal Server Error: /index/companylist/9/ownerslist/
Traceback (most recent call last):
  File "/Library/Python/2.7/site-packages/django/core/handlers/base.py", line 111, in get_response
    response = wrapped_callback(request, *callback_args, **callback_kwargs)
TypeError: ownerslist() got an unexpected keyword argument 'pk'
2015-10-16 12:03:37,880 [DEBUG] django.db.backends: (0.001) SHOW TABLES; args=None
2015-10-16 12:03:37,889 [DEBUG] django.db.backends: (0.001) SELECT `django_migrations`.`app`, `django_migrations`.`name` FROM `django_migrations`; args=()
2015-10-16 12:03:38,775 [ERROR] django.request: Internal Server Error: /index/companylist/9/ownerslist/
Traceback (most recent call last):
  File "/Library/Python/2.7/site-packages/django/core/handlers/base.py", line 111, in get_response
    response = wrapped_callback(request, *callback_args, **callback_kwargs)
TypeError: ownerslist() got an unexpected keyword argument 'pk'
2015-10-16 12:04:06,831 [DEBUG] django.db.backends: (0.001) SHOW TABLES; args=None
2015-10-16 12:04:06,840 [DEBUG] django.db.backends: (0.001) SELECT `django_migrations`.`app`, `django_migrations`.`name` FROM `django_migrations`; args=()
2015-10-16 12:05:35,464 [DEBUG] django.db.backends: (0.001) SELECT `companydetails_companydetails`.`id`, `companydetails_companydetails`.`company_id`, `companydetails_companydetails`.`name`, `companydetails_companydetails`.`address`, `companydetails_companydetails`.`city`, `companydetails_companydetails`.`country`, `companydetails_companydetails`.`email`, `companydetails_companydetails`.`phone` FROM `companydetails_companydetails` WHERE `companydetails_companydetails`.`id` = 7 LIMIT 21; args=(7,)
2015-10-16 12:05:35,467 [ERROR] django.request: Internal Server Error: /api/companylist/7/
Traceback (most recent call last):
  File "/Library/Python/2.7/site-packages/django/core/handlers/base.py", line 111, in get_response
    response = wrapped_callback(request, *callback_args, **callback_kwargs)
  File "/Library/Python/2.7/site-packages/django/views/decorators/csrf.py", line 57, in wrapped_view
    return view_func(*args, **kwargs)
  File "/Library/Python/2.7/site-packages/django/views/generic/base.py", line 69, in view
    return self.dispatch(request, *args, **kwargs)
  File "/Library/Python/2.7/site-packages/rest_framework/views.py", line 407, in dispatch
    response = self.handle_exception(exc)
  File "/Library/Python/2.7/site-packages/rest_framework/views.py", line 404, in dispatch
    response = handler(request, *args, **kwargs)
  File "/Library/Python/2.7/site-packages/rest_framework/decorators.py", line 50, in handler
    return func(*args, **kwargs)
  File "/Users/manoj/Documents/companyinfo/companydetails/views.py", line 57, in CompanyListDetail
    return Response(serializer.data)
  File "/Library/Python/2.7/site-packages/rest_framework/serializers.py", line 463, in data
    ret = super(Serializer, self).data
  File "/Library/Python/2.7/site-packages/rest_framework/serializers.py", line 212, in data
    self._data = self.to_representation(self.instance)
  File "/Library/Python/2.7/site-packages/rest_framework/serializers.py", line 432, in to_representation
    ret[field.field_name] = field.to_representation(attribute)
  File "/Library/Python/2.7/site-packages/rest_framework/relations.py", line 240, in to_representation
    "the serializer." % self.__class__.__name__
AssertionError: `HyperlinkedIdentityField` requires the request in the serializer context. Add `context={'request': request}` when instantiating the serializer.
2015-10-16 12:06:37,750 [DEBUG] django.db.backends: (0.002) SHOW TABLES; args=None
2015-10-16 12:06:37,792 [DEBUG] django.db.backends: (0.002) SELECT `django_migrations`.`app`, `django_migrations`.`name` FROM `django_migrations`; args=()
2015-10-16 12:06:39,957 [DEBUG] django.db.backends: (0.001) SELECT `companydetails_companydetails`.`id`, `companydetails_companydetails`.`company_id`, `companydetails_companydetails`.`name`, `companydetails_companydetails`.`address`, `companydetails_companydetails`.`city`, `companydetails_companydetails`.`country`, `companydetails_companydetails`.`email`, `companydetails_companydetails`.`phone` FROM `companydetails_companydetails` WHERE `companydetails_companydetails`.`id` = 7 LIMIT 21; args=(7,)
2015-10-16 12:06:40,037 [DEBUG] MARKDOWN: Successfuly imported extension module "markdown.extensions.headerid".
2015-10-16 12:06:40,038 [DEBUG] MARKDOWN: Successfully loaded extension "markdown.extensions.headerid.HeaderIdExtension".
2015-10-16 12:07:13,197 [DEBUG] django.db.backends: (0.001) SELECT `companydetails_companydetails`.`id`, `companydetails_companydetails`.`company_id`, `companydetails_companydetails`.`name`, `companydetails_companydetails`.`address`, `companydetails_companydetails`.`city`, `companydetails_companydetails`.`country`, `companydetails_companydetails`.`email`, `companydetails_companydetails`.`phone` FROM `companydetails_companydetails`; args=()
2015-10-16 12:07:13,215 [DEBUG] MARKDOWN: Successfuly imported extension module "markdown.extensions.headerid".
2015-10-16 12:07:13,215 [DEBUG] MARKDOWN: Successfully loaded extension "markdown.extensions.headerid.HeaderIdExtension".
2015-10-16 12:07:34,795 [DEBUG] django.db.backends: (0.001) SELECT `companydetails_companydetails`.`id`, `companydetails_companydetails`.`company_id`, `companydetails_companydetails`.`name`, `companydetails_companydetails`.`address`, `companydetails_companydetails`.`city`, `companydetails_companydetails`.`country`, `companydetails_companydetails`.`email`, `companydetails_companydetails`.`phone` FROM `companydetails_companydetails` WHERE `companydetails_companydetails`.`id` = 1 LIMIT 21; args=(1,)
2015-10-16 12:07:34,801 [DEBUG] MARKDOWN: Successfuly imported extension module "markdown.extensions.headerid".
2015-10-16 12:07:34,801 [DEBUG] MARKDOWN: Successfully loaded extension "markdown.extensions.headerid.HeaderIdExtension".
2015-10-16 12:27:02,705 [WARNING] django.request: Not Found: /api/companylist/1/ownerslist/
2015-10-16 12:27:55,941 [WARNING] django.request: Not Found: /api/companylist/1/ownerslist/
2015-10-16 12:29:19,407 [DEBUG] django.db.backends: (0.001) SELECT `companydetails_companydetails`.`id`, `companydetails_companydetails`.`company_id`, `companydetails_companydetails`.`name`, `companydetails_companydetails`.`address`, `companydetails_companydetails`.`city`, `companydetails_companydetails`.`country`, `companydetails_companydetails`.`email`, `companydetails_companydetails`.`phone` FROM `companydetails_companydetails`; args=()
2015-10-16 12:30:24,417 [DEBUG] django.db.backends: (0.001) SELECT `companydetails_companydetails`.`id`, `companydetails_companydetails`.`company_id`, `companydetails_companydetails`.`name`, `companydetails_companydetails`.`address`, `companydetails_companydetails`.`city`, `companydetails_companydetails`.`country`, `companydetails_companydetails`.`email`, `companydetails_companydetails`.`phone` FROM `companydetails_companydetails`; args=()
2015-10-16 12:30:24,429 [DEBUG] MARKDOWN: Successfuly imported extension module "markdown.extensions.headerid".
2015-10-16 12:30:24,430 [DEBUG] MARKDOWN: Successfully loaded extension "markdown.extensions.headerid.HeaderIdExtension".
2015-10-16 12:33:04,183 [DEBUG] django.db.backends: (0.002) INSERT INTO `companydetails_companydetails` (`company_id`, `name`, `address`, `city`, `country`, `email`, `phone`) VALUES (105, 'EuroExpress', '5th Street', 'Stockholm', 'Sweden', 'euroexpress@mail.com', '5133232323232'); args=[105, u'EuroExpress', u'5th Street', u'Stockholm', u'Sweden', u'euroexpress@mail.com', u'5133232323232']
2015-10-16 12:33:04,187 [ERROR] django.request: Internal Server Error: /api/companylist/
Traceback (most recent call last):
  File "/Library/Python/2.7/site-packages/django/core/handlers/base.py", line 111, in get_response
    response = wrapped_callback(request, *callback_args, **callback_kwargs)
  File "/Library/Python/2.7/site-packages/django/views/decorators/csrf.py", line 57, in wrapped_view
    return view_func(*args, **kwargs)
  File "/Library/Python/2.7/site-packages/django/views/generic/base.py", line 69, in view
    return self.dispatch(request, *args, **kwargs)
  File "/Library/Python/2.7/site-packages/rest_framework/views.py", line 407, in dispatch
    response = self.handle_exception(exc)
  File "/Library/Python/2.7/site-packages/rest_framework/views.py", line 404, in dispatch
    response = handler(request, *args, **kwargs)
  File "/Library/Python/2.7/site-packages/rest_framework/decorators.py", line 50, in handler
    return func(*args, **kwargs)
  File "/Users/manoj/Documents/companyinfo/companydetails/views.py", line 42, in CompanyList
    return Response(serializer.data, status=status.HTTP_201_CREATED)
  File "/Library/Python/2.7/site-packages/rest_framework/serializers.py", line 463, in data
    ret = super(Serializer, self).data
  File "/Library/Python/2.7/site-packages/rest_framework/serializers.py", line 212, in data
    self._data = self.to_representation(self.instance)
  File "/Library/Python/2.7/site-packages/rest_framework/serializers.py", line 432, in to_representation
    ret[field.field_name] = field.to_representation(attribute)
  File "/Library/Python/2.7/site-packages/rest_framework/relations.py", line 240, in to_representation
    "the serializer." % self.__class__.__name__
AssertionError: `HyperlinkedIdentityField` requires the request in the serializer context. Add `context={'request': request}` when instantiating the serializer.
2015-10-16 12:34:59,714 [DEBUG] django.db.backends: (0.001) INSERT INTO `companydetails_companydetails` (`company_id`, `name`, `address`, `city`, `country`, `email`, `phone`) VALUES (105, 'EuroExpress', '5th Street', 'Stockholm', 'Sweden', 'euroexpress@mail.com', '5133232323232'); args=[105, u'EuroExpress', u'5th Street', u'Stockholm', u'Sweden', u'euroexpress@mail.com', u'5133232323232']
2015-10-16 12:34:59,716 [ERROR] django.request: Internal Server Error: /api/companylist/
Traceback (most recent call last):
  File "/Library/Python/2.7/site-packages/django/core/handlers/base.py", line 111, in get_response
    response = wrapped_callback(request, *callback_args, **callback_kwargs)
  File "/Library/Python/2.7/site-packages/django/views/decorators/csrf.py", line 57, in wrapped_view
    return view_func(*args, **kwargs)
  File "/Library/Python/2.7/site-packages/django/views/generic/base.py", line 69, in view
    return self.dispatch(request, *args, **kwargs)
  File "/Library/Python/2.7/site-packages/rest_framework/views.py", line 407, in dispatch
    response = self.handle_exception(exc)
  File "/Library/Python/2.7/site-packages/rest_framework/views.py", line 404, in dispatch
    response = handler(request, *args, **kwargs)
  File "/Library/Python/2.7/site-packages/rest_framework/decorators.py", line 50, in handler
    return func(*args, **kwargs)
  File "/Users/manoj/Documents/companyinfo/companydetails/views.py", line 41, in CompanyList
    serializer.save()
  File "/Library/Python/2.7/site-packages/rest_framework/serializers.py", line 164, in save
    self.instance = self.create(validated_data)
  File "/Users/manoj/Documents/companyinfo/companydetails/serializers.py", line 30, in create
    phone = validated_data['phone']
  File "/Library/Python/2.7/site-packages/django/db/models/manager.py", line 92, in manager_method
    return getattr(self.get_queryset(), name)(*args, **kwargs)
  File "/Library/Python/2.7/site-packages/django/db/models/query.py", line 372, in create
    obj.save(force_insert=True, using=self.db)
  File "/Library/Python/2.7/site-packages/django/db/models/base.py", line 589, in save
    force_update=force_update, update_fields=update_fields)
  File "/Library/Python/2.7/site-packages/django/db/models/base.py", line 617, in save_base
    updated = self._save_table(raw, cls, force_insert, force_update, using, update_fields)
  File "/Library/Python/2.7/site-packages/django/db/models/base.py", line 698, in _save_table
    result = self._do_insert(cls._base_manager, using, fields, update_pk, raw)
  File "/Library/Python/2.7/site-packages/django/db/models/base.py", line 731, in _do_insert
    using=using, raw=raw)
  File "/Library/Python/2.7/site-packages/django/db/models/manager.py", line 92, in manager_method
    return getattr(self.get_queryset(), name)(*args, **kwargs)
  File "/Library/Python/2.7/site-packages/django/db/models/query.py", line 921, in _insert
    return query.get_compiler(using=using).execute_sql(return_id)
  File "/Library/Python/2.7/site-packages/django/db/models/sql/compiler.py", line 920, in execute_sql
    cursor.execute(sql, params)
  File "/Library/Python/2.7/site-packages/django/db/backends/utils.py", line 81, in execute
    return super(CursorDebugWrapper, self).execute(sql, params)
  File "/Library/Python/2.7/site-packages/django/db/backends/utils.py", line 65, in execute
    return self.cursor.execute(sql, params)
  File "/Library/Python/2.7/site-packages/mysql/connector/django/base.py", line 135, in execute
    return self._execute_wrapper(self.cursor.execute, query, args)
  File "/Library/Python/2.7/site-packages/mysql/connector/django/base.py", line 121, in _execute_wrapper
    utils.IntegrityError(err.msg), sys.exc_info()[2])
  File "/Library/Python/2.7/site-packages/mysql/connector/django/base.py", line 115, in _execute_wrapper
    return method(query, args)
  File "/Library/Python/2.7/site-packages/mysql/connector/cursor.py", line 507, in execute
    self._handle_result(self._connection.cmd_query(stmt))
  File "/Library/Python/2.7/site-packages/mysql/connector/connection.py", line 722, in cmd_query
    result = self._handle_result(self._send_cmd(ServerCmd.QUERY, query))
  File "/Library/Python/2.7/site-packages/mysql/connector/connection.py", line 640, in _handle_result
    raise errors.get_exception(packet)
IntegrityError: Duplicate entry 'euroexpress@mail.com' for key 'companydetails_companydetails_email_54092f110edbe84c_uniq'
2015-10-16 12:34:59,830 [DEBUG] django.db.backends: (0.001) SELECT `companydetails_companydetails`.`id`, `companydetails_companydetails`.`company_id`, `companydetails_companydetails`.`name`, `companydetails_companydetails`.`address`, `companydetails_companydetails`.`city`, `companydetails_companydetails`.`country`, `companydetails_companydetails`.`email`, `companydetails_companydetails`.`phone` FROM `companydetails_companydetails` LIMIT 21; args=()
2015-10-16 12:34:59,834 [DEBUG] django.db.backends: (0.001) SELECT `companydetails_companydetails`.`id`, `companydetails_companydetails`.`company_id`, `companydetails_companydetails`.`name`, `companydetails_companydetails`.`address`, `companydetails_companydetails`.`city`, `companydetails_companydetails`.`country`, `companydetails_companydetails`.`email`, `companydetails_companydetails`.`phone` FROM `companydetails_companydetails` LIMIT 21; args=()
2015-10-16 12:42:23,615 [ERROR] django.request: Internal Server Error: /api/companylist
Traceback (most recent call last):
  File "/Library/Python/2.7/site-packages/django/core/handlers/base.py", line 87, in get_response
    response = middleware_method(request)
  File "/Library/Python/2.7/site-packages/django/middleware/common.py", line 82, in process_request
    "settings.") % (new_url[0], new_url[1]))
RuntimeError: You called this URL via POST, but the URL doesn't end in a slash and you have APPEND_SLASH set. Django can't redirect to the slash URL while maintaining POST data. Change your form to point to 127.0.0.1:8000/api/companylist/ (note the trailing slash), or set APPEND_SLASH=False in your Django settings.
2015-10-16 12:44:33,177 [ERROR] django.request: Internal Server Error: /api/companylist
Traceback (most recent call last):
  File "/Library/Python/2.7/site-packages/django/core/handlers/base.py", line 87, in get_response
    response = middleware_method(request)
  File "/Library/Python/2.7/site-packages/django/middleware/common.py", line 82, in process_request
    "settings.") % (new_url[0], new_url[1]))
RuntimeError: You called this URL via POST, but the URL doesn't end in a slash and you have APPEND_SLASH set. Django can't redirect to the slash URL while maintaining POST data. Change your form to point to 127.0.0.1:8000/api/companylist/ (note the trailing slash), or set APPEND_SLASH=False in your Django settings.
2015-10-16 12:51:48,492 [DEBUG] django.db.backends: (0.001) SELECT `companydetails_companydetails`.`id`, `companydetails_companydetails`.`company_id`, `companydetails_companydetails`.`name`, `companydetails_companydetails`.`address`, `companydetails_companydetails`.`city`, `companydetails_companydetails`.`country`, `companydetails_companydetails`.`email`, `companydetails_companydetails`.`phone` FROM `companydetails_companydetails`; args=()
2015-10-16 12:55:38,151 [DEBUG] django.db.backends: (0.010) INSERT INTO `companydetails_companydetails` (`company_id`, `name`, `address`, `city`, `country`, `email`, `phone`) VALUES (105, 'EuroExpress', '5th Street', 'Stockholm', 'Sweden', 'euroexpress@mail.com', '5133232323232'); args=[105, u'EuroExpress', u'5th Street', u'Stockholm', u'Sweden', u'euroexpress@mail.com', u'5133232323232']
2015-10-16 12:55:38,153 [ERROR] django.request: Internal Server Error: /api/companylist/
Traceback (most recent call last):
  File "/Library/Python/2.7/site-packages/django/core/handlers/base.py", line 111, in get_response
    response = wrapped_callback(request, *callback_args, **callback_kwargs)
  File "/Library/Python/2.7/site-packages/django/views/decorators/csrf.py", line 57, in wrapped_view
    return view_func(*args, **kwargs)
  File "/Library/Python/2.7/site-packages/django/views/generic/base.py", line 69, in view
    return self.dispatch(request, *args, **kwargs)
  File "/Library/Python/2.7/site-packages/rest_framework/views.py", line 407, in dispatch
    response = self.handle_exception(exc)
  File "/Library/Python/2.7/site-packages/rest_framework/views.py", line 404, in dispatch
    response = handler(request, *args, **kwargs)
  File "/Library/Python/2.7/site-packages/rest_framework/decorators.py", line 50, in handler
    return func(*args, **kwargs)
  File "/Users/manoj/Documents/companyinfo/companydetails/views.py", line 41, in CompanyList
    serializer.save()
  File "/Library/Python/2.7/site-packages/rest_framework/serializers.py", line 164, in save
    self.instance = self.create(validated_data)
  File "/Users/manoj/Documents/companyinfo/companydetails/serializers.py", line 30, in create
    phone = validated_data['phone']
  File "/Library/Python/2.7/site-packages/django/db/models/manager.py", line 92, in manager_method
    return getattr(self.get_queryset(), name)(*args, **kwargs)
  File "/Library/Python/2.7/site-packages/django/db/models/query.py", line 372, in create
    obj.save(force_insert=True, using=self.db)
  File "/Library/Python/2.7/site-packages/django/db/models/base.py", line 589, in save
    force_update=force_update, update_fields=update_fields)
  File "/Library/Python/2.7/site-packages/django/db/models/base.py", line 617, in save_base
    updated = self._save_table(raw, cls, force_insert, force_update, using, update_fields)
  File "/Library/Python/2.7/site-packages/django/db/models/base.py", line 698, in _save_table
    result = self._do_insert(cls._base_manager, using, fields, update_pk, raw)
  File "/Library/Python/2.7/site-packages/django/db/models/base.py", line 731, in _do_insert
    using=using, raw=raw)
  File "/Library/Python/2.7/site-packages/django/db/models/manager.py", line 92, in manager_method
    return getattr(self.get_queryset(), name)(*args, **kwargs)
  File "/Library/Python/2.7/site-packages/django/db/models/query.py", line 921, in _insert
    return query.get_compiler(using=using).execute_sql(return_id)
  File "/Library/Python/2.7/site-packages/django/db/models/sql/compiler.py", line 920, in execute_sql
    cursor.execute(sql, params)
  File "/Library/Python/2.7/site-packages/django/db/backends/utils.py", line 81, in execute
    return super(CursorDebugWrapper, self).execute(sql, params)
  File "/Library/Python/2.7/site-packages/django/db/backends/utils.py", line 65, in execute
    return self.cursor.execute(sql, params)
  File "/Library/Python/2.7/site-packages/mysql/connector/django/base.py", line 135, in execute
    return self._execute_wrapper(self.cursor.execute, query, args)
  File "/Library/Python/2.7/site-packages/mysql/connector/django/base.py", line 121, in _execute_wrapper
    utils.IntegrityError(err.msg), sys.exc_info()[2])
  File "/Library/Python/2.7/site-packages/mysql/connector/django/base.py", line 115, in _execute_wrapper
    return method(query, args)
  File "/Library/Python/2.7/site-packages/mysql/connector/cursor.py", line 507, in execute
    self._handle_result(self._connection.cmd_query(stmt))
  File "/Library/Python/2.7/site-packages/mysql/connector/connection.py", line 722, in cmd_query
    result = self._handle_result(self._send_cmd(ServerCmd.QUERY, query))
  File "/Library/Python/2.7/site-packages/mysql/connector/connection.py", line 640, in _handle_result
    raise errors.get_exception(packet)
IntegrityError: Duplicate entry 'euroexpress@mail.com' for key 'companydetails_companydetails_email_54092f110edbe84c_uniq'
2015-10-16 12:55:38,229 [DEBUG] django.db.backends: (0.001) SELECT `companydetails_companydetails`.`id`, `companydetails_companydetails`.`company_id`, `companydetails_companydetails`.`name`, `companydetails_companydetails`.`address`, `companydetails_companydetails`.`city`, `companydetails_companydetails`.`country`, `companydetails_companydetails`.`email`, `companydetails_companydetails`.`phone` FROM `companydetails_companydetails` LIMIT 21; args=()
2015-10-16 12:55:38,234 [DEBUG] django.db.backends: (0.001) SELECT `companydetails_companydetails`.`id`, `companydetails_companydetails`.`company_id`, `companydetails_companydetails`.`name`, `companydetails_companydetails`.`address`, `companydetails_companydetails`.`city`, `companydetails_companydetails`.`country`, `companydetails_companydetails`.`email`, `companydetails_companydetails`.`phone` FROM `companydetails_companydetails` LIMIT 21; args=()
2015-10-16 12:55:44,583 [DEBUG] django.db.backends: (0.001) INSERT INTO `companydetails_companydetails` (`company_id`, `name`, `address`, `city`, `country`, `email`, `phone`) VALUES (105, 'EuroExpress', '5th Street', 'Stockholm', 'Sweden', 'euroexpress@mail.com', '5133232323232'); args=[105, u'EuroExpress', u'5th Street', u'Stockholm', u'Sweden', u'euroexpress@mail.com', u'5133232323232']
2015-10-16 12:55:44,591 [ERROR] django.request: Internal Server Error: /api/companylist/
Traceback (most recent call last):
  File "/Library/Python/2.7/site-packages/django/core/handlers/base.py", line 111, in get_response
    response = wrapped_callback(request, *callback_args, **callback_kwargs)
  File "/Library/Python/2.7/site-packages/django/views/decorators/csrf.py", line 57, in wrapped_view
    return view_func(*args, **kwargs)
  File "/Library/Python/2.7/site-packages/django/views/generic/base.py", line 69, in view
    return self.dispatch(request, *args, **kwargs)
  File "/Library/Python/2.7/site-packages/rest_framework/views.py", line 407, in dispatch
    response = self.handle_exception(exc)
  File "/Library/Python/2.7/site-packages/rest_framework/views.py", line 404, in dispatch
    response = handler(request, *args, **kwargs)
  File "/Library/Python/2.7/site-packages/rest_framework/decorators.py", line 50, in handler
    return func(*args, **kwargs)
  File "/Users/manoj/Documents/companyinfo/companydetails/views.py", line 41, in CompanyList
    serializer.save()
  File "/Library/Python/2.7/site-packages/rest_framework/serializers.py", line 164, in save
    self.instance = self.create(validated_data)
  File "/Users/manoj/Documents/companyinfo/companydetails/serializers.py", line 30, in create
    phone = validated_data['phone']
  File "/Library/Python/2.7/site-packages/django/db/models/manager.py", line 92, in manager_method
    return getattr(self.get_queryset(), name)(*args, **kwargs)
  File "/Library/Python/2.7/site-packages/django/db/models/query.py", line 372, in create
    obj.save(force_insert=True, using=self.db)
  File "/Library/Python/2.7/site-packages/django/db/models/base.py", line 589, in save
    force_update=force_update, update_fields=update_fields)
  File "/Library/Python/2.7/site-packages/django/db/models/base.py", line 617, in save_base
    updated = self._save_table(raw, cls, force_insert, force_update, using, update_fields)
  File "/Library/Python/2.7/site-packages/django/db/models/base.py", line 698, in _save_table
    result = self._do_insert(cls._base_manager, using, fields, update_pk, raw)
  File "/Library/Python/2.7/site-packages/django/db/models/base.py", line 731, in _do_insert
    using=using, raw=raw)
  File "/Library/Python/2.7/site-packages/django/db/models/manager.py", line 92, in manager_method
    return getattr(self.get_queryset(), name)(*args, **kwargs)
  File "/Library/Python/2.7/site-packages/django/db/models/query.py", line 921, in _insert
    return query.get_compiler(using=using).execute_sql(return_id)
  File "/Library/Python/2.7/site-packages/django/db/models/sql/compiler.py", line 920, in execute_sql
    cursor.execute(sql, params)
  File "/Library/Python/2.7/site-packages/django/db/backends/utils.py", line 81, in execute
    return super(CursorDebugWrapper, self).execute(sql, params)
  File "/Library/Python/2.7/site-packages/django/db/backends/utils.py", line 65, in execute
    return self.cursor.execute(sql, params)
  File "/Library/Python/2.7/site-packages/mysql/connector/django/base.py", line 135, in execute
    return self._execute_wrapper(self.cursor.execute, query, args)
  File "/Library/Python/2.7/site-packages/mysql/connector/django/base.py", line 121, in _execute_wrapper
    utils.IntegrityError(err.msg), sys.exc_info()[2])
  File "/Library/Python/2.7/site-packages/mysql/connector/django/base.py", line 115, in _execute_wrapper
    return method(query, args)
  File "/Library/Python/2.7/site-packages/mysql/connector/cursor.py", line 507, in execute
    self._handle_result(self._connection.cmd_query(stmt))
  File "/Library/Python/2.7/site-packages/mysql/connector/connection.py", line 722, in cmd_query
    result = self._handle_result(self._send_cmd(ServerCmd.QUERY, query))
  File "/Library/Python/2.7/site-packages/mysql/connector/connection.py", line 640, in _handle_result
    raise errors.get_exception(packet)
IntegrityError: Duplicate entry 'euroexpress@mail.com' for key 'companydetails_companydetails_email_54092f110edbe84c_uniq'
2015-10-16 12:55:44,637 [DEBUG] django.db.backends: (0.001) SELECT `companydetails_companydetails`.`id`, `companydetails_companydetails`.`company_id`, `companydetails_companydetails`.`name`, `companydetails_companydetails`.`address`, `companydetails_companydetails`.`city`, `companydetails_companydetails`.`country`, `companydetails_companydetails`.`email`, `companydetails_companydetails`.`phone` FROM `companydetails_companydetails` LIMIT 21; args=()
2015-10-16 12:55:44,641 [DEBUG] django.db.backends: (0.001) SELECT `companydetails_companydetails`.`id`, `companydetails_companydetails`.`company_id`, `companydetails_companydetails`.`name`, `companydetails_companydetails`.`address`, `companydetails_companydetails`.`city`, `companydetails_companydetails`.`country`, `companydetails_companydetails`.`email`, `companydetails_companydetails`.`phone` FROM `companydetails_companydetails` LIMIT 21; args=()
2015-10-16 12:57:13,640 [DEBUG] django.db.backends: (0.001) SELECT `companydetails_companydetails`.`id`, `companydetails_companydetails`.`company_id`, `companydetails_companydetails`.`name`, `companydetails_companydetails`.`address`, `companydetails_companydetails`.`city`, `companydetails_companydetails`.`country`, `companydetails_companydetails`.`email`, `companydetails_companydetails`.`phone` FROM `companydetails_companydetails`; args=()
2015-10-16 12:57:13,649 [DEBUG] MARKDOWN: Successfuly imported extension module "markdown.extensions.headerid".
2015-10-16 12:57:13,649 [DEBUG] MARKDOWN: Successfully loaded extension "markdown.extensions.headerid.HeaderIdExtension".
2015-10-16 12:58:41,985 [DEBUG] django.db.backends: (0.000) INSERT INTO `companydetails_companydetails` (`company_id`, `name`, `address`, `city`, `country`, `email`, `phone`) VALUES (106, 'EuroCouriers', '5th Street', 'Oslo', 'Norway', 'eurocouriers@mail.com', '5133232323454'); args=[106, u'EuroCouriers', u'5th Street', u'Oslo', u'Norway', u'eurocouriers@mail.com', u'5133232323454']
2015-10-16 12:58:41,986 [ERROR] django.request: Internal Server Error: /api/companylist/
Traceback (most recent call last):
  File "/Library/Python/2.7/site-packages/django/core/handlers/base.py", line 111, in get_response
    response = wrapped_callback(request, *callback_args, **callback_kwargs)
  File "/Library/Python/2.7/site-packages/django/views/decorators/csrf.py", line 57, in wrapped_view
    return view_func(*args, **kwargs)
  File "/Library/Python/2.7/site-packages/django/views/generic/base.py", line 69, in view
    return self.dispatch(request, *args, **kwargs)
  File "/Library/Python/2.7/site-packages/rest_framework/views.py", line 407, in dispatch
    response = self.handle_exception(exc)
  File "/Library/Python/2.7/site-packages/rest_framework/views.py", line 404, in dispatch
    response = handler(request, *args, **kwargs)
  File "/Library/Python/2.7/site-packages/rest_framework/decorators.py", line 50, in handler
    return func(*args, **kwargs)
  File "/Users/manoj/Documents/companyinfo/companydetails/views.py", line 42, in CompanyList
    return Response(serializer.data, status=status.HTTP_201_CREATED)
  File "/Library/Python/2.7/site-packages/rest_framework/serializers.py", line 463, in data
    ret = super(Serializer, self).data
  File "/Library/Python/2.7/site-packages/rest_framework/serializers.py", line 212, in data
    self._data = self.to_representation(self.instance)
  File "/Library/Python/2.7/site-packages/rest_framework/serializers.py", line 432, in to_representation
    ret[field.field_name] = field.to_representation(attribute)
  File "/Library/Python/2.7/site-packages/rest_framework/relations.py", line 240, in to_representation
    "the serializer." % self.__class__.__name__
AssertionError: `HyperlinkedIdentityField` requires the request in the serializer context. Add `context={'request': request}` when instantiating the serializer.
2015-10-16 12:58:59,907 [DEBUG] django.db.backends: (0.001) INSERT INTO `companydetails_companydetails` (`company_id`, `name`, `address`, `city`, `country`, `email`, `phone`) VALUES (106, 'EuroCouriers', '5th Street', 'Oslo', 'Norway', 'eurocouriers@mail.com', '5133232323454'); args=[106, u'EuroCouriers', u'5th Street', u'Oslo', u'Norway', u'eurocouriers@mail.com', u'5133232323454']
2015-10-16 12:58:59,915 [ERROR] django.request: Internal Server Error: /api/companylist/
Traceback (most recent call last):
  File "/Library/Python/2.7/site-packages/django/core/handlers/base.py", line 111, in get_response
    response = wrapped_callback(request, *callback_args, **callback_kwargs)
  File "/Library/Python/2.7/site-packages/django/views/decorators/csrf.py", line 57, in wrapped_view
    return view_func(*args, **kwargs)
  File "/Library/Python/2.7/site-packages/django/views/generic/base.py", line 69, in view
    return self.dispatch(request, *args, **kwargs)
  File "/Library/Python/2.7/site-packages/rest_framework/views.py", line 407, in dispatch
    response = self.handle_exception(exc)
  File "/Library/Python/2.7/site-packages/rest_framework/views.py", line 404, in dispatch
    response = handler(request, *args, **kwargs)
  File "/Library/Python/2.7/site-packages/rest_framework/decorators.py", line 50, in handler
    return func(*args, **kwargs)
  File "/Users/manoj/Documents/companyinfo/companydetails/views.py", line 41, in CompanyList
    serializer.save()
  File "/Library/Python/2.7/site-packages/rest_framework/serializers.py", line 164, in save
    self.instance = self.create(validated_data)
  File "/Users/manoj/Documents/companyinfo/companydetails/serializers.py", line 30, in create
    phone = validated_data['phone']
  File "/Library/Python/2.7/site-packages/django/db/models/manager.py", line 92, in manager_method
    return getattr(self.get_queryset(), name)(*args, **kwargs)
  File "/Library/Python/2.7/site-packages/django/db/models/query.py", line 372, in create
    obj.save(force_insert=True, using=self.db)
  File "/Library/Python/2.7/site-packages/django/db/models/base.py", line 589, in save
    force_update=force_update, update_fields=update_fields)
  File "/Library/Python/2.7/site-packages/django/db/models/base.py", line 617, in save_base
    updated = self._save_table(raw, cls, force_insert, force_update, using, update_fields)
  File "/Library/Python/2.7/site-packages/django/db/models/base.py", line 698, in _save_table
    result = self._do_insert(cls._base_manager, using, fields, update_pk, raw)
  File "/Library/Python/2.7/site-packages/django/db/models/base.py", line 731, in _do_insert
    using=using, raw=raw)
  File "/Library/Python/2.7/site-packages/django/db/models/manager.py", line 92, in manager_method
    return getattr(self.get_queryset(), name)(*args, **kwargs)
  File "/Library/Python/2.7/site-packages/django/db/models/query.py", line 921, in _insert
    return query.get_compiler(using=using).execute_sql(return_id)
  File "/Library/Python/2.7/site-packages/django/db/models/sql/compiler.py", line 920, in execute_sql
    cursor.execute(sql, params)
  File "/Library/Python/2.7/site-packages/django/db/backends/utils.py", line 81, in execute
    return super(CursorDebugWrapper, self).execute(sql, params)
  File "/Library/Python/2.7/site-packages/django/db/backends/utils.py", line 65, in execute
    return self.cursor.execute(sql, params)
  File "/Library/Python/2.7/site-packages/mysql/connector/django/base.py", line 135, in execute
    return self._execute_wrapper(self.cursor.execute, query, args)
  File "/Library/Python/2.7/site-packages/mysql/connector/django/base.py", line 121, in _execute_wrapper
    utils.IntegrityError(err.msg), sys.exc_info()[2])
  File "/Library/Python/2.7/site-packages/mysql/connector/django/base.py", line 115, in _execute_wrapper
    return method(query, args)
  File "/Library/Python/2.7/site-packages/mysql/connector/cursor.py", line 507, in execute
    self._handle_result(self._connection.cmd_query(stmt))
  File "/Library/Python/2.7/site-packages/mysql/connector/connection.py", line 722, in cmd_query
    result = self._handle_result(self._send_cmd(ServerCmd.QUERY, query))
  File "/Library/Python/2.7/site-packages/mysql/connector/connection.py", line 640, in _handle_result
    raise errors.get_exception(packet)
IntegrityError: Duplicate entry 'eurocouriers@mail.com' for key 'companydetails_companydetails_email_54092f110edbe84c_uniq'
2015-10-16 12:58:59,960 [DEBUG] django.db.backends: (0.001) SELECT `companydetails_companydetails`.`id`, `companydetails_companydetails`.`company_id`, `companydetails_companydetails`.`name`, `companydetails_companydetails`.`address`, `companydetails_companydetails`.`city`, `companydetails_companydetails`.`country`, `companydetails_companydetails`.`email`, `companydetails_companydetails`.`phone` FROM `companydetails_companydetails` LIMIT 21; args=()
2015-10-16 12:58:59,964 [DEBUG] django.db.backends: (0.001) SELECT `companydetails_companydetails`.`id`, `companydetails_companydetails`.`company_id`, `companydetails_companydetails`.`name`, `companydetails_companydetails`.`address`, `companydetails_companydetails`.`city`, `companydetails_companydetails`.`country`, `companydetails_companydetails`.`email`, `companydetails_companydetails`.`phone` FROM `companydetails_companydetails` LIMIT 21; args=()
2015-10-16 12:59:06,940 [DEBUG] django.db.backends: (0.001) SELECT `companydetails_companydetails`.`id`, `companydetails_companydetails`.`company_id`, `companydetails_companydetails`.`name`, `companydetails_companydetails`.`address`, `companydetails_companydetails`.`city`, `companydetails_companydetails`.`country`, `companydetails_companydetails`.`email`, `companydetails_companydetails`.`phone` FROM `companydetails_companydetails`; args=()
2015-10-16 12:59:06,948 [DEBUG] MARKDOWN: Successfuly imported extension module "markdown.extensions.headerid".
2015-10-16 12:59:06,948 [DEBUG] MARKDOWN: Successfully loaded extension "markdown.extensions.headerid.HeaderIdExtension".
2015-10-16 13:04:27,638 [DEBUG] django.db.backends: (0.002) SELECT `companydetails_companydetails`.`id`, `companydetails_companydetails`.`company_id`, `companydetails_companydetails`.`name`, `companydetails_companydetails`.`address`, `companydetails_companydetails`.`city`, `companydetails_companydetails`.`country`, `companydetails_companydetails`.`email`, `companydetails_companydetails`.`phone` FROM `companydetails_companydetails`; args=()
2015-10-16 13:04:27,649 [DEBUG] MARKDOWN: Successfuly imported extension module "markdown.extensions.headerid".
2015-10-16 13:04:27,650 [DEBUG] MARKDOWN: Successfully loaded extension "markdown.extensions.headerid.HeaderIdExtension".
2015-10-16 13:05:02,693 [DEBUG] django.db.backends: (0.001) SELECT `companydetails_companydetails`.`id`, `companydetails_companydetails`.`company_id`, `companydetails_companydetails`.`name`, `companydetails_companydetails`.`address`, `companydetails_companydetails`.`city`, `companydetails_companydetails`.`country`, `companydetails_companydetails`.`email`, `companydetails_companydetails`.`phone` FROM `companydetails_companydetails`; args=()
2015-10-16 13:05:02,700 [DEBUG] MARKDOWN: Successfuly imported extension module "markdown.extensions.headerid".
2015-10-16 13:05:02,700 [DEBUG] MARKDOWN: Successfully loaded extension "markdown.extensions.headerid.HeaderIdExtension".
2015-10-16 13:05:04,485 [DEBUG] django.db.backends: (0.001) SELECT `companydetails_companydetails`.`id`, `companydetails_companydetails`.`company_id`, `companydetails_companydetails`.`name`, `companydetails_companydetails`.`address`, `companydetails_companydetails`.`city`, `companydetails_companydetails`.`country`, `companydetails_companydetails`.`email`, `companydetails_companydetails`.`phone` FROM `companydetails_companydetails`; args=()
2015-10-16 13:05:04,494 [DEBUG] MARKDOWN: Successfuly imported extension module "markdown.extensions.headerid".
2015-10-16 13:05:04,494 [DEBUG] MARKDOWN: Successfully loaded extension "markdown.extensions.headerid.HeaderIdExtension".
2015-10-16 13:05:25,146 [DEBUG] django.db.backends: (0.001) SELECT `companydetails_companydetails`.`id`, `companydetails_companydetails`.`company_id`, `companydetails_companydetails`.`name`, `companydetails_companydetails`.`address`, `companydetails_companydetails`.`city`, `companydetails_companydetails`.`country`, `companydetails_companydetails`.`email`, `companydetails_companydetails`.`phone` FROM `companydetails_companydetails`; args=()
2015-10-16 13:05:25,154 [DEBUG] MARKDOWN: Successfuly imported extension module "markdown.extensions.headerid".
2015-10-16 13:05:25,154 [DEBUG] MARKDOWN: Successfully loaded extension "markdown.extensions.headerid.HeaderIdExtension".
2015-10-16 13:05:30,781 [DEBUG] django.db.backends: (0.012) SELECT `companydetails_companydetails`.`id`, `companydetails_companydetails`.`company_id`, `companydetails_companydetails`.`name`, `companydetails_companydetails`.`address`, `companydetails_companydetails`.`city`, `companydetails_companydetails`.`country`, `companydetails_companydetails`.`email`, `companydetails_companydetails`.`phone` FROM `companydetails_companydetails` WHERE `companydetails_companydetails`.`id` = 15 LIMIT 21; args=(15,)
2015-10-16 13:05:30,788 [DEBUG] django.db.backends: (0.003) DELETE FROM `companydetails_ownerdetails` WHERE `companydetails_ownerdetails`.`company_id` IN (15); args=(15,)
2015-10-16 13:05:30,793 [DEBUG] django.db.backends: (0.004) DELETE FROM `companydetails_companydetails` WHERE `companydetails_companydetails`.`id` IN (15); args=(15,)
2015-10-16 13:05:36,286 [DEBUG] django.db.backends: (0.002) SELECT `companydetails_companydetails`.`id`, `companydetails_companydetails`.`company_id`, `companydetails_companydetails`.`name`, `companydetails_companydetails`.`address`, `companydetails_companydetails`.`city`, `companydetails_companydetails`.`country`, `companydetails_companydetails`.`email`, `companydetails_companydetails`.`phone` FROM `companydetails_companydetails`; args=()
2015-10-16 13:05:36,296 [DEBUG] MARKDOWN: Successfuly imported extension module "markdown.extensions.headerid".
2015-10-16 13:05:36,296 [DEBUG] MARKDOWN: Successfully loaded extension "markdown.extensions.headerid.HeaderIdExtension".
2015-10-16 13:06:30,839 [DEBUG] django.db.backends: (0.001) SELECT `companydetails_companydetails`.`id`, `companydetails_companydetails`.`company_id`, `companydetails_companydetails`.`name`, `companydetails_companydetails`.`address`, `companydetails_companydetails`.`city`, `companydetails_companydetails`.`country`, `companydetails_companydetails`.`email`, `companydetails_companydetails`.`phone` FROM `companydetails_companydetails`; args=()
2015-10-16 13:06:30,847 [DEBUG] MARKDOWN: Successfuly imported extension module "markdown.extensions.headerid".
2015-10-16 13:06:30,847 [DEBUG] MARKDOWN: Successfully loaded extension "markdown.extensions.headerid.HeaderIdExtension".
2015-10-16 13:07:14,263 [DEBUG] django.db.backends: (0.009) INSERT INTO `companydetails_companydetails` (`company_id`, `name`, `address`, `city`, `country`, `email`, `phone`) VALUES (106, 'EuroCouriers', '5th Street', 'Oslo', 'Norway', 'eurocouriers@mail.com', '5133232323454'); args=[106, u'EuroCouriers', u'5th Street', u'Oslo', u'Norway', u'eurocouriers@mail.com', u'5133232323454']
2015-10-16 13:07:14,265 [ERROR] django.request: Internal Server Error: /api/companylist/
Traceback (most recent call last):
  File "/Library/Python/2.7/site-packages/django/core/handlers/base.py", line 111, in get_response
    response = wrapped_callback(request, *callback_args, **callback_kwargs)
  File "/Library/Python/2.7/site-packages/django/views/decorators/csrf.py", line 57, in wrapped_view
    return view_func(*args, **kwargs)
  File "/Library/Python/2.7/site-packages/django/views/generic/base.py", line 69, in view
    return self.dispatch(request, *args, **kwargs)
  File "/Library/Python/2.7/site-packages/rest_framework/views.py", line 407, in dispatch
    response = self.handle_exception(exc)
  File "/Library/Python/2.7/site-packages/rest_framework/views.py", line 404, in dispatch
    response = handler(request, *args, **kwargs)
  File "/Library/Python/2.7/site-packages/rest_framework/decorators.py", line 50, in handler
    return func(*args, **kwargs)
  File "/Users/manoj/Documents/companyinfo/companydetails/views.py", line 42, in CompanyList
    return Response(serializer.data, status=status.HTTP_201_CREATED)
  File "/Library/Python/2.7/site-packages/rest_framework/serializers.py", line 463, in data
    ret = super(Serializer, self).data
  File "/Library/Python/2.7/site-packages/rest_framework/serializers.py", line 212, in data
    self._data = self.to_representation(self.instance)
  File "/Library/Python/2.7/site-packages/rest_framework/serializers.py", line 432, in to_representation
    ret[field.field_name] = field.to_representation(attribute)
  File "/Library/Python/2.7/site-packages/rest_framework/relations.py", line 240, in to_representation
    "the serializer." % self.__class__.__name__
AssertionError: `HyperlinkedIdentityField` requires the request in the serializer context. Add `context={'request': request}` when instantiating the serializer.
2015-10-16 13:07:19,576 [DEBUG] django.db.backends: (0.001) SELECT `companydetails_companydetails`.`id`, `companydetails_companydetails`.`company_id`, `companydetails_companydetails`.`name`, `companydetails_companydetails`.`address`, `companydetails_companydetails`.`city`, `companydetails_companydetails`.`country`, `companydetails_companydetails`.`email`, `companydetails_companydetails`.`phone` FROM `companydetails_companydetails`; args=()
2015-10-16 13:07:19,584 [DEBUG] MARKDOWN: Successfuly imported extension module "markdown.extensions.headerid".
2015-10-16 13:07:19,584 [DEBUG] MARKDOWN: Successfully loaded extension "markdown.extensions.headerid.HeaderIdExtension".
2015-10-16 13:07:33,545 [DEBUG] django.db.backends: (0.001) SELECT `companydetails_companydetails`.`id`, `companydetails_companydetails`.`company_id`, `companydetails_companydetails`.`name`, `companydetails_companydetails`.`address`, `companydetails_companydetails`.`city`, `companydetails_companydetails`.`country`, `companydetails_companydetails`.`email`, `companydetails_companydetails`.`phone` FROM `companydetails_companydetails` WHERE `companydetails_companydetails`.`id` = 17 LIMIT 21; args=(17,)
2015-10-16 13:07:33,548 [DEBUG] django.db.backends: (0.000) DELETE FROM `companydetails_ownerdetails` WHERE `companydetails_ownerdetails`.`company_id` IN (17); args=(17,)
2015-10-16 13:07:33,549 [DEBUG] django.db.backends: (0.000) DELETE FROM `companydetails_companydetails` WHERE `companydetails_companydetails`.`id` IN (17); args=(17,)
2015-10-16 13:12:41,677 [DEBUG] django.db.backends: (0.001) SELECT `companydetails_companydetails`.`id`, `companydetails_companydetails`.`company_id`, `companydetails_companydetails`.`name`, `companydetails_companydetails`.`address`, `companydetails_companydetails`.`city`, `companydetails_companydetails`.`country`, `companydetails_companydetails`.`email`, `companydetails_companydetails`.`phone` FROM `companydetails_companydetails` WHERE `companydetails_companydetails`.`id` = 1 LIMIT 21; args=(1,)
2015-10-16 13:12:41,680 [ERROR] django.request: Internal Server Error: /api/companylist/1/
Traceback (most recent call last):
  File "/Library/Python/2.7/site-packages/django/core/handlers/base.py", line 111, in get_response
    response = wrapped_callback(request, *callback_args, **callback_kwargs)
  File "/Library/Python/2.7/site-packages/django/views/decorators/csrf.py", line 57, in wrapped_view
    return view_func(*args, **kwargs)
  File "/Library/Python/2.7/site-packages/django/views/generic/base.py", line 69, in view
    return self.dispatch(request, *args, **kwargs)
  File "/Library/Python/2.7/site-packages/rest_framework/views.py", line 407, in dispatch
    response = self.handle_exception(exc)
  File "/Library/Python/2.7/site-packages/rest_framework/views.py", line 404, in dispatch
    response = handler(request, *args, **kwargs)
  File "/Library/Python/2.7/site-packages/rest_framework/decorators.py", line 50, in handler
    return func(*args, **kwargs)
  File "/Users/manoj/Documents/companyinfo/companydetails/views.py", line 63, in CompanyListDetail
    serializer.save()
  File "/Library/Python/2.7/site-packages/rest_framework/serializers.py", line 161, in save
    '`update()` did not return an object instance.'
AssertionError: `update()` did not return an object instance.
2015-10-16 13:12:47,157 [DEBUG] django.db.backends: (0.001) SELECT `companydetails_companydetails`.`id`, `companydetails_companydetails`.`company_id`, `companydetails_companydetails`.`name`, `companydetails_companydetails`.`address`, `companydetails_companydetails`.`city`, `companydetails_companydetails`.`country`, `companydetails_companydetails`.`email`, `companydetails_companydetails`.`phone` FROM `companydetails_companydetails`; args=()
2015-10-16 13:12:47,176 [DEBUG] MARKDOWN: Successfuly imported extension module "markdown.extensions.headerid".
2015-10-16 13:12:47,176 [DEBUG] MARKDOWN: Successfully loaded extension "markdown.extensions.headerid.HeaderIdExtension".
2015-10-16 13:13:28,377 [DEBUG] django.db.backends: (0.001) SELECT `companydetails_companydetails`.`id`, `companydetails_companydetails`.`company_id`, `companydetails_companydetails`.`name`, `companydetails_companydetails`.`address`, `companydetails_companydetails`.`city`, `companydetails_companydetails`.`country`, `companydetails_companydetails`.`email`, `companydetails_companydetails`.`phone` FROM `companydetails_companydetails`; args=()
2015-10-16 13:13:28,386 [DEBUG] MARKDOWN: Successfuly imported extension module "markdown.extensions.headerid".
2015-10-16 13:13:28,386 [DEBUG] MARKDOWN: Successfully loaded extension "markdown.extensions.headerid.HeaderIdExtension".
2015-10-16 13:14:07,432 [DEBUG] django.db.backends: (0.001) SELECT `companydetails_companydetails`.`id`, `companydetails_companydetails`.`company_id`, `companydetails_companydetails`.`name`, `companydetails_companydetails`.`address`, `companydetails_companydetails`.`city`, `companydetails_companydetails`.`country`, `companydetails_companydetails`.`email`, `companydetails_companydetails`.`phone` FROM `companydetails_companydetails` WHERE `companydetails_companydetails`.`id` = 1 LIMIT 21; args=(1,)
2015-10-16 13:14:07,436 [ERROR] django.request: Internal Server Error: /api/companylist/1/
Traceback (most recent call last):
  File "/Library/Python/2.7/site-packages/django/core/handlers/base.py", line 111, in get_response
    response = wrapped_callback(request, *callback_args, **callback_kwargs)
  File "/Library/Python/2.7/site-packages/django/views/decorators/csrf.py", line 57, in wrapped_view
    return view_func(*args, **kwargs)
  File "/Library/Python/2.7/site-packages/django/views/generic/base.py", line 69, in view
    return self.dispatch(request, *args, **kwargs)
  File "/Library/Python/2.7/site-packages/rest_framework/views.py", line 407, in dispatch
    response = self.handle_exception(exc)
  File "/Library/Python/2.7/site-packages/rest_framework/views.py", line 404, in dispatch
    response = handler(request, *args, **kwargs)
  File "/Library/Python/2.7/site-packages/rest_framework/decorators.py", line 50, in handler
    return func(*args, **kwargs)
  File "/Users/manoj/Documents/companyinfo/companydetails/views.py", line 63, in CompanyListDetail
    serializer.save()
  File "/Library/Python/2.7/site-packages/rest_framework/serializers.py", line 161, in save
    '`update()` did not return an object instance.'
AssertionError: `update()` did not return an object instance.
2015-10-16 13:14:11,109 [DEBUG] django.db.backends: (0.001) SELECT `companydetails_companydetails`.`id`, `companydetails_companydetails`.`company_id`, `companydetails_companydetails`.`name`, `companydetails_companydetails`.`address`, `companydetails_companydetails`.`city`, `companydetails_companydetails`.`country`, `companydetails_companydetails`.`email`, `companydetails_companydetails`.`phone` FROM `companydetails_companydetails`; args=()
2015-10-16 13:14:11,117 [DEBUG] MARKDOWN: Successfuly imported extension module "markdown.extensions.headerid".
2015-10-16 13:14:11,117 [DEBUG] MARKDOWN: Successfully loaded extension "markdown.extensions.headerid.HeaderIdExtension".
2015-10-16 13:16:17,539 [DEBUG] django.db.backends: (0.001) SELECT `companydetails_companydetails`.`id`, `companydetails_companydetails`.`company_id`, `companydetails_companydetails`.`name`, `companydetails_companydetails`.`address`, `companydetails_companydetails`.`city`, `companydetails_companydetails`.`country`, `companydetails_companydetails`.`email`, `companydetails_companydetails`.`phone` FROM `companydetails_companydetails` WHERE `companydetails_companydetails`.`id` = 1 LIMIT 21; args=(1,)
2015-10-16 13:16:17,543 [ERROR] django.request: Internal Server Error: /api/companylist/1/
Traceback (most recent call last):
  File "/Library/Python/2.7/site-packages/django/core/handlers/base.py", line 111, in get_response
    response = wrapped_callback(request, *callback_args, **callback_kwargs)
  File "/Library/Python/2.7/site-packages/django/views/decorators/csrf.py", line 57, in wrapped_view
    return view_func(*args, **kwargs)
  File "/Library/Python/2.7/site-packages/django/views/generic/base.py", line 69, in view
    return self.dispatch(request, *args, **kwargs)
  File "/Library/Python/2.7/site-packages/rest_framework/views.py", line 407, in dispatch
    response = self.handle_exception(exc)
  File "/Library/Python/2.7/site-packages/rest_framework/views.py", line 404, in dispatch
    response = handler(request, *args, **kwargs)
  File "/Library/Python/2.7/site-packages/rest_framework/decorators.py", line 50, in handler
    return func(*args, **kwargs)
  File "/Users/manoj/Documents/companyinfo/companydetails/views.py", line 63, in CompanyListDetail
    serializer.save()
  File "/Library/Python/2.7/site-packages/rest_framework/serializers.py", line 161, in save
    '`update()` did not return an object instance.'
AssertionError: `update()` did not return an object instance.
2015-10-16 13:16:24,385 [DEBUG] django.db.backends: (0.001) SELECT `companydetails_companydetails`.`id`, `companydetails_companydetails`.`company_id`, `companydetails_companydetails`.`name`, `companydetails_companydetails`.`address`, `companydetails_companydetails`.`city`, `companydetails_companydetails`.`country`, `companydetails_companydetails`.`email`, `companydetails_companydetails`.`phone` FROM `companydetails_companydetails`; args=()
2015-10-16 13:16:24,392 [DEBUG] MARKDOWN: Successfuly imported extension module "markdown.extensions.headerid".
2015-10-16 13:16:24,392 [DEBUG] MARKDOWN: Successfully loaded extension "markdown.extensions.headerid.HeaderIdExtension".
2015-10-16 13:16:27,803 [DEBUG] django.db.backends: (0.001) SELECT `companydetails_companydetails`.`id`, `companydetails_companydetails`.`company_id`, `companydetails_companydetails`.`name`, `companydetails_companydetails`.`address`, `companydetails_companydetails`.`city`, `companydetails_companydetails`.`country`, `companydetails_companydetails`.`email`, `companydetails_companydetails`.`phone` FROM `companydetails_companydetails`; args=()
2015-10-16 13:16:27,811 [DEBUG] MARKDOWN: Successfuly imported extension module "markdown.extensions.headerid".
2015-10-16 13:16:27,811 [DEBUG] MARKDOWN: Successfully loaded extension "markdown.extensions.headerid.HeaderIdExtension".
2015-10-16 13:16:51,535 [DEBUG] django.db.backends: (0.001) SELECT `companydetails_companydetails`.`id`, `companydetails_companydetails`.`company_id`, `companydetails_companydetails`.`name`, `companydetails_companydetails`.`address`, `companydetails_companydetails`.`city`, `companydetails_companydetails`.`country`, `companydetails_companydetails`.`email`, `companydetails_companydetails`.`phone` FROM `companydetails_companydetails` WHERE `companydetails_companydetails`.`id` = 1 LIMIT 21; args=(1,)
2015-10-16 13:16:51,540 [ERROR] django.request: Internal Server Error: /api/companylist/1/
Traceback (most recent call last):
  File "/Library/Python/2.7/site-packages/django/core/handlers/base.py", line 111, in get_response
    response = wrapped_callback(request, *callback_args, **callback_kwargs)
  File "/Library/Python/2.7/site-packages/django/views/decorators/csrf.py", line 57, in wrapped_view
    return view_func(*args, **kwargs)
  File "/Library/Python/2.7/site-packages/django/views/generic/base.py", line 69, in view
    return self.dispatch(request, *args, **kwargs)
  File "/Library/Python/2.7/site-packages/rest_framework/views.py", line 407, in dispatch
    response = self.handle_exception(exc)
  File "/Library/Python/2.7/site-packages/rest_framework/views.py", line 404, in dispatch
    response = handler(request, *args, **kwargs)
  File "/Library/Python/2.7/site-packages/rest_framework/decorators.py", line 50, in handler
    return func(*args, **kwargs)
  File "/Users/manoj/Documents/companyinfo/companydetails/views.py", line 63, in CompanyListDetail
    serializer.save()
  File "/Library/Python/2.7/site-packages/rest_framework/serializers.py", line 161, in save
    '`update()` did not return an object instance.'
AssertionError: `update()` did not return an object instance.
2015-10-16 13:16:55,964 [DEBUG] django.db.backends: (0.001) SELECT `companydetails_companydetails`.`id`, `companydetails_companydetails`.`company_id`, `companydetails_companydetails`.`name`, `companydetails_companydetails`.`address`, `companydetails_companydetails`.`city`, `companydetails_companydetails`.`country`, `companydetails_companydetails`.`email`, `companydetails_companydetails`.`phone` FROM `companydetails_companydetails`; args=()
2015-10-16 13:16:55,970 [DEBUG] MARKDOWN: Successfuly imported extension module "markdown.extensions.headerid".
2015-10-16 13:16:55,970 [DEBUG] MARKDOWN: Successfully loaded extension "markdown.extensions.headerid.HeaderIdExtension".
2015-10-16 13:16:57,018 [DEBUG] django.db.backends: (0.001) SELECT `companydetails_companydetails`.`id`, `companydetails_companydetails`.`company_id`, `companydetails_companydetails`.`name`, `companydetails_companydetails`.`address`, `companydetails_companydetails`.`city`, `companydetails_companydetails`.`country`, `companydetails_companydetails`.`email`, `companydetails_companydetails`.`phone` FROM `companydetails_companydetails`; args=()
2015-10-16 13:16:57,025 [DEBUG] MARKDOWN: Successfuly imported extension module "markdown.extensions.headerid".
2015-10-16 13:16:57,026 [DEBUG] MARKDOWN: Successfully loaded extension "markdown.extensions.headerid.HeaderIdExtension".
2015-10-16 13:17:54,537 [DEBUG] django.db.backends: (0.001) SELECT `companydetails_companydetails`.`id`, `companydetails_companydetails`.`company_id`, `companydetails_companydetails`.`name`, `companydetails_companydetails`.`address`, `companydetails_companydetails`.`city`, `companydetails_companydetails`.`country`, `companydetails_companydetails`.`email`, `companydetails_companydetails`.`phone` FROM `companydetails_companydetails` WHERE `companydetails_companydetails`.`id` = 1 LIMIT 21; args=(1,)
2015-10-16 13:18:07,098 [DEBUG] django.db.backends: (0.001) SELECT `companydetails_companydetails`.`id`, `companydetails_companydetails`.`company_id`, `companydetails_companydetails`.`name`, `companydetails_companydetails`.`address`, `companydetails_companydetails`.`city`, `companydetails_companydetails`.`country`, `companydetails_companydetails`.`email`, `companydetails_companydetails`.`phone` FROM `companydetails_companydetails`; args=()
2015-10-16 13:18:07,116 [DEBUG] MARKDOWN: Successfuly imported extension module "markdown.extensions.headerid".
2015-10-16 13:18:07,116 [DEBUG] MARKDOWN: Successfully loaded extension "markdown.extensions.headerid.HeaderIdExtension".
2015-10-16 13:18:08,934 [DEBUG] django.db.backends: (0.001) SELECT `companydetails_companydetails`.`id`, `companydetails_companydetails`.`company_id`, `companydetails_companydetails`.`name`, `companydetails_companydetails`.`address`, `companydetails_companydetails`.`city`, `companydetails_companydetails`.`country`, `companydetails_companydetails`.`email`, `companydetails_companydetails`.`phone` FROM `companydetails_companydetails`; args=()
2015-10-16 13:18:08,941 [DEBUG] MARKDOWN: Successfuly imported extension module "markdown.extensions.headerid".
2015-10-16 13:18:08,941 [DEBUG] MARKDOWN: Successfully loaded extension "markdown.extensions.headerid.HeaderIdExtension".
2015-10-16 13:18:28,431 [DEBUG] django.db.backends: (0.001) SELECT `companydetails_companydetails`.`id`, `companydetails_companydetails`.`company_id`, `companydetails_companydetails`.`name`, `companydetails_companydetails`.`address`, `companydetails_companydetails`.`city`, `companydetails_companydetails`.`country`, `companydetails_companydetails`.`email`, `companydetails_companydetails`.`phone` FROM `companydetails_companydetails` WHERE `companydetails_companydetails`.`id` = 1 LIMIT 21; args=(1,)
2015-10-16 13:18:28,435 [ERROR] django.request: Internal Server Error: /api/companylist/1/
Traceback (most recent call last):
  File "/Library/Python/2.7/site-packages/django/core/handlers/base.py", line 111, in get_response
    response = wrapped_callback(request, *callback_args, **callback_kwargs)
  File "/Library/Python/2.7/site-packages/django/views/decorators/csrf.py", line 57, in wrapped_view
    return view_func(*args, **kwargs)
  File "/Library/Python/2.7/site-packages/django/views/generic/base.py", line 69, in view
    return self.dispatch(request, *args, **kwargs)
  File "/Library/Python/2.7/site-packages/rest_framework/views.py", line 407, in dispatch
    response = self.handle_exception(exc)
  File "/Library/Python/2.7/site-packages/rest_framework/views.py", line 404, in dispatch
    response = handler(request, *args, **kwargs)
  File "/Library/Python/2.7/site-packages/rest_framework/decorators.py", line 50, in handler
    return func(*args, **kwargs)
  File "/Users/manoj/Documents/companyinfo/companydetails/views.py", line 63, in CompanyListDetail
    serializer.save()
  File "/Library/Python/2.7/site-packages/rest_framework/serializers.py", line 161, in save
    '`update()` did not return an object instance.'
AssertionError: `update()` did not return an object instance.
2015-10-16 13:18:32,513 [DEBUG] django.db.backends: (0.001) SELECT `companydetails_companydetails`.`id`, `companydetails_companydetails`.`company_id`, `companydetails_companydetails`.`name`, `companydetails_companydetails`.`address`, `companydetails_companydetails`.`city`, `companydetails_companydetails`.`country`, `companydetails_companydetails`.`email`, `companydetails_companydetails`.`phone` FROM `companydetails_companydetails`; args=()
2015-10-16 13:18:32,520 [DEBUG] MARKDOWN: Successfuly imported extension module "markdown.extensions.headerid".
2015-10-16 13:18:32,521 [DEBUG] MARKDOWN: Successfully loaded extension "markdown.extensions.headerid.HeaderIdExtension".
2015-10-16 13:18:34,098 [DEBUG] django.db.backends: (0.001) SELECT `companydetails_companydetails`.`id`, `companydetails_companydetails`.`company_id`, `companydetails_companydetails`.`name`, `companydetails_companydetails`.`address`, `companydetails_companydetails`.`city`, `companydetails_companydetails`.`country`, `companydetails_companydetails`.`email`, `companydetails_companydetails`.`phone` FROM `companydetails_companydetails`; args=()
2015-10-16 13:18:34,106 [DEBUG] MARKDOWN: Successfuly imported extension module "markdown.extensions.headerid".
2015-10-16 13:18:34,106 [DEBUG] MARKDOWN: Successfully loaded extension "markdown.extensions.headerid.HeaderIdExtension".
2015-10-16 13:19:54,589 [DEBUG] django.db.backends: (0.001) SELECT `companydetails_companydetails`.`id`, `companydetails_companydetails`.`company_id`, `companydetails_companydetails`.`name`, `companydetails_companydetails`.`address`, `companydetails_companydetails`.`city`, `companydetails_companydetails`.`country`, `companydetails_companydetails`.`email`, `companydetails_companydetails`.`phone` FROM `companydetails_companydetails`; args=()
2015-10-16 13:19:54,596 [DEBUG] MARKDOWN: Successfuly imported extension module "markdown.extensions.headerid".
2015-10-16 13:19:54,597 [DEBUG] MARKDOWN: Successfully loaded extension "markdown.extensions.headerid.HeaderIdExtension".
2015-10-16 13:19:55,778 [DEBUG] django.db.backends: (0.001) SELECT `companydetails_companydetails`.`id`, `companydetails_companydetails`.`company_id`, `companydetails_companydetails`.`name`, `companydetails_companydetails`.`address`, `companydetails_companydetails`.`city`, `companydetails_companydetails`.`country`, `companydetails_companydetails`.`email`, `companydetails_companydetails`.`phone` FROM `companydetails_companydetails`; args=()
2015-10-16 13:19:55,785 [DEBUG] MARKDOWN: Successfuly imported extension module "markdown.extensions.headerid".
2015-10-16 13:19:55,786 [DEBUG] MARKDOWN: Successfully loaded extension "markdown.extensions.headerid.HeaderIdExtension".
2015-10-16 13:20:22,021 [DEBUG] django.db.backends: (0.001) SELECT `companydetails_companydetails`.`id`, `companydetails_companydetails`.`company_id`, `companydetails_companydetails`.`name`, `companydetails_companydetails`.`address`, `companydetails_companydetails`.`city`, `companydetails_companydetails`.`country`, `companydetails_companydetails`.`email`, `companydetails_companydetails`.`phone` FROM `companydetails_companydetails`; args=()
2015-10-16 13:20:22,029 [DEBUG] MARKDOWN: Successfuly imported extension module "markdown.extensions.headerid".
2015-10-16 13:20:22,029 [DEBUG] MARKDOWN: Successfully loaded extension "markdown.extensions.headerid.HeaderIdExtension".
2015-10-16 13:20:23,144 [DEBUG] django.db.backends: (0.001) SELECT `companydetails_companydetails`.`id`, `companydetails_companydetails`.`company_id`, `companydetails_companydetails`.`name`, `companydetails_companydetails`.`address`, `companydetails_companydetails`.`city`, `companydetails_companydetails`.`country`, `companydetails_companydetails`.`email`, `companydetails_companydetails`.`phone` FROM `companydetails_companydetails`; args=()
2015-10-16 13:20:23,151 [DEBUG] MARKDOWN: Successfuly imported extension module "markdown.extensions.headerid".
2015-10-16 13:20:23,151 [DEBUG] MARKDOWN: Successfully loaded extension "markdown.extensions.headerid.HeaderIdExtension".
2015-10-16 13:20:41,254 [DEBUG] django.db.backends: (0.001) SELECT `companydetails_companydetails`.`id`, `companydetails_companydetails`.`company_id`, `companydetails_companydetails`.`name`, `companydetails_companydetails`.`address`, `companydetails_companydetails`.`city`, `companydetails_companydetails`.`country`, `companydetails_companydetails`.`email`, `companydetails_companydetails`.`phone` FROM `companydetails_companydetails` WHERE `companydetails_companydetails`.`id` = 1 LIMIT 21; args=(1,)
2015-10-16 13:20:41,258 [ERROR] django.request: Internal Server Error: /api/companylist/1/
Traceback (most recent call last):
  File "/Library/Python/2.7/site-packages/django/core/handlers/base.py", line 111, in get_response
    response = wrapped_callback(request, *callback_args, **callback_kwargs)
  File "/Library/Python/2.7/site-packages/django/views/decorators/csrf.py", line 57, in wrapped_view
    return view_func(*args, **kwargs)
  File "/Library/Python/2.7/site-packages/django/views/generic/base.py", line 69, in view
    return self.dispatch(request, *args, **kwargs)
  File "/Library/Python/2.7/site-packages/rest_framework/views.py", line 407, in dispatch
    response = self.handle_exception(exc)
  File "/Library/Python/2.7/site-packages/rest_framework/views.py", line 404, in dispatch
    response = handler(request, *args, **kwargs)
  File "/Library/Python/2.7/site-packages/rest_framework/decorators.py", line 50, in handler
    return func(*args, **kwargs)
  File "/Users/manoj/Documents/companyinfo/companydetails/views.py", line 63, in CompanyListDetail
    serializer.save()
  File "/Library/Python/2.7/site-packages/rest_framework/serializers.py", line 161, in save
    '`update()` did not return an object instance.'
AssertionError: `update()` did not return an object instance.
2015-10-16 13:20:46,711 [DEBUG] django.db.backends: (0.001) SELECT `companydetails_companydetails`.`id`, `companydetails_companydetails`.`company_id`, `companydetails_companydetails`.`name`, `companydetails_companydetails`.`address`, `companydetails_companydetails`.`city`, `companydetails_companydetails`.`country`, `companydetails_companydetails`.`email`, `companydetails_companydetails`.`phone` FROM `companydetails_companydetails`; args=()
2015-10-16 13:20:46,719 [DEBUG] MARKDOWN: Successfuly imported extension module "markdown.extensions.headerid".
2015-10-16 13:20:46,719 [DEBUG] MARKDOWN: Successfully loaded extension "markdown.extensions.headerid.HeaderIdExtension".
2015-10-16 13:20:47,785 [DEBUG] django.db.backends: (0.001) SELECT `companydetails_companydetails`.`id`, `companydetails_companydetails`.`company_id`, `companydetails_companydetails`.`name`, `companydetails_companydetails`.`address`, `companydetails_companydetails`.`city`, `companydetails_companydetails`.`country`, `companydetails_companydetails`.`email`, `companydetails_companydetails`.`phone` FROM `companydetails_companydetails`; args=()
2015-10-16 13:20:47,792 [DEBUG] MARKDOWN: Successfuly imported extension module "markdown.extensions.headerid".
2015-10-16 13:20:47,793 [DEBUG] MARKDOWN: Successfully loaded extension "markdown.extensions.headerid.HeaderIdExtension".
2015-10-16 13:27:35,564 [DEBUG] django.db.backends: (0.001) SELECT `companydetails_companydetails`.`id`, `companydetails_companydetails`.`company_id`, `companydetails_companydetails`.`name`, `companydetails_companydetails`.`address`, `companydetails_companydetails`.`city`, `companydetails_companydetails`.`country`, `companydetails_companydetails`.`email`, `companydetails_companydetails`.`phone` FROM `companydetails_companydetails`; args=()
2015-10-16 13:27:35,573 [DEBUG] MARKDOWN: Successfuly imported extension module "markdown.extensions.headerid".
2015-10-16 13:27:35,573 [DEBUG] MARKDOWN: Successfully loaded extension "markdown.extensions.headerid.HeaderIdExtension".
2015-10-16 13:27:36,833 [DEBUG] django.db.backends: (0.001) SELECT `companydetails_companydetails`.`id`, `companydetails_companydetails`.`company_id`, `companydetails_companydetails`.`name`, `companydetails_companydetails`.`address`, `companydetails_companydetails`.`city`, `companydetails_companydetails`.`country`, `companydetails_companydetails`.`email`, `companydetails_companydetails`.`phone` FROM `companydetails_companydetails`; args=()
2015-10-16 13:27:36,839 [DEBUG] MARKDOWN: Successfuly imported extension module "markdown.extensions.headerid".
2015-10-16 13:27:36,839 [DEBUG] MARKDOWN: Successfully loaded extension "markdown.extensions.headerid.HeaderIdExtension".
2015-10-16 13:28:23,816 [DEBUG] django.db.backends: (0.001) SELECT `companydetails_companydetails`.`id`, `companydetails_companydetails`.`company_id`, `companydetails_companydetails`.`name`, `companydetails_companydetails`.`address`, `companydetails_companydetails`.`city`, `companydetails_companydetails`.`country`, `companydetails_companydetails`.`email`, `companydetails_companydetails`.`phone` FROM `companydetails_companydetails`; args=()
2015-10-16 13:28:23,823 [DEBUG] MARKDOWN: Successfuly imported extension module "markdown.extensions.headerid".
2015-10-16 13:28:23,824 [DEBUG] MARKDOWN: Successfully loaded extension "markdown.extensions.headerid.HeaderIdExtension".
2015-10-16 13:28:34,538 [DEBUG] django.db.backends: (0.001) SELECT `companydetails_companydetails`.`id`, `companydetails_companydetails`.`company_id`, `companydetails_companydetails`.`name`, `companydetails_companydetails`.`address`, `companydetails_companydetails`.`city`, `companydetails_companydetails`.`country`, `companydetails_companydetails`.`email`, `companydetails_companydetails`.`phone` FROM `companydetails_companydetails` WHERE `companydetails_companydetails`.`id` = 1 LIMIT 21; args=(1,)
2015-10-16 13:28:34,542 [ERROR] django.request: Internal Server Error: /api/companylist/1/
Traceback (most recent call last):
  File "/Library/Python/2.7/site-packages/django/core/handlers/base.py", line 111, in get_response
    response = wrapped_callback(request, *callback_args, **callback_kwargs)
  File "/Library/Python/2.7/site-packages/django/views/decorators/csrf.py", line 57, in wrapped_view
    return view_func(*args, **kwargs)
  File "/Library/Python/2.7/site-packages/django/views/generic/base.py", line 69, in view
    return self.dispatch(request, *args, **kwargs)
  File "/Library/Python/2.7/site-packages/rest_framework/views.py", line 407, in dispatch
    response = self.handle_exception(exc)
  File "/Library/Python/2.7/site-packages/rest_framework/views.py", line 404, in dispatch
    response = handler(request, *args, **kwargs)
  File "/Library/Python/2.7/site-packages/rest_framework/decorators.py", line 50, in handler
    return func(*args, **kwargs)
  File "/Users/manoj/Documents/companyinfo/companydetails/views.py", line 63, in CompanyListDetail
    serializer.save()
  File "/Library/Python/2.7/site-packages/rest_framework/serializers.py", line 161, in save
    '`update()` did not return an object instance.'
AssertionError: `update()` did not return an object instance.
2015-10-16 13:28:38,805 [DEBUG] django.db.backends: (0.001) SELECT `companydetails_companydetails`.`id`, `companydetails_companydetails`.`company_id`, `companydetails_companydetails`.`name`, `companydetails_companydetails`.`address`, `companydetails_companydetails`.`city`, `companydetails_companydetails`.`country`, `companydetails_companydetails`.`email`, `companydetails_companydetails`.`phone` FROM `companydetails_companydetails`; args=()
2015-10-16 13:28:38,811 [DEBUG] MARKDOWN: Successfuly imported extension module "markdown.extensions.headerid".
2015-10-16 13:28:38,812 [DEBUG] MARKDOWN: Successfully loaded extension "markdown.extensions.headerid.HeaderIdExtension".
2015-10-16 13:52:25,084 [ERROR] django.request: Internal Server Error: /index/companylist/9/ownerslist/
Traceback (most recent call last):
  File "/Library/Python/2.7/site-packages/django/core/handlers/base.py", line 111, in get_response
    response = wrapped_callback(request, *callback_args, **callback_kwargs)
TypeError: ownerslist() got an unexpected keyword argument 'pk'
2015-10-16 13:56:13,544 [DEBUG] django.db.backends: (0.003) SHOW TABLES; args=None
2015-10-16 13:56:13,585 [DEBUG] django.db.backends: (0.003) SELECT `django_migrations`.`app`, `django_migrations`.`name` FROM `django_migrations`; args=()
2015-10-16 13:56:20,447 [ERROR] django.request: Internal Server Error: /index/companylist/9/ownerslist/
Traceback (most recent call last):
  File "/Library/Python/2.7/site-packages/django/core/handlers/base.py", line 111, in get_response
    response = wrapped_callback(request, *callback_args, **callback_kwargs)
TypeError: ownerslist() takes no arguments (2 given)
2015-10-16 13:56:30,489 [DEBUG] django.db.backends: (0.001) SHOW TABLES; args=None
2015-10-16 13:56:30,500 [DEBUG] django.db.backends: (0.001) SELECT `django_migrations`.`app`, `django_migrations`.`name` FROM `django_migrations`; args=()
2015-10-16 13:57:06,465 [ERROR] django.request: Internal Server Error: /index/companylist/9/ownerslist/
Traceback (most recent call last):
  File "/Library/Python/2.7/site-packages/django/core/handlers/base.py", line 111, in get_response
    response = wrapped_callback(request, *callback_args, **callback_kwargs)
TypeError: ownerslist() got an unexpected keyword argument 'pk'
2015-10-16 13:57:14,340 [ERROR] django.request: Internal Server Error: /index/companylist/9/ownerslist/
Traceback (most recent call last):
  File "/Library/Python/2.7/site-packages/django/core/handlers/base.py", line 111, in get_response
    response = wrapped_callback(request, *callback_args, **callback_kwargs)
TypeError: ownerslist() got an unexpected keyword argument 'pk'
2015-10-16 13:57:16,091 [ERROR] django.request: Internal Server Error: /index/companylist/9/ownerslist/
Traceback (most recent call last):
  File "/Library/Python/2.7/site-packages/django/core/handlers/base.py", line 111, in get_response
    response = wrapped_callback(request, *callback_args, **callback_kwargs)
TypeError: ownerslist() got an unexpected keyword argument 'pk'
2015-10-16 13:58:36,058 [DEBUG] django.db.backends: (0.002) SHOW TABLES; args=None
2015-10-16 13:58:36,098 [DEBUG] django.db.backends: (0.001) SELECT `django_migrations`.`app`, `django_migrations`.`name` FROM `django_migrations`; args=()
2015-10-16 13:58:39,639 [DEBUG] django.db.backends: (0.001) SELECT `companydetails_companydetails`.`id`, `companydetails_companydetails`.`company_id`, `companydetails_companydetails`.`name`, `companydetails_companydetails`.`address`, `companydetails_companydetails`.`city`, `companydetails_companydetails`.`country`, `companydetails_companydetails`.`email`, `companydetails_companydetails`.`phone` FROM `companydetails_companydetails`; args=()
2015-10-16 13:58:44,010 [DEBUG] django.db.backends: (0.001) SELECT `companydetails_companydetails`.`id`, `companydetails_companydetails`.`company_id`, `companydetails_companydetails`.`name`, `companydetails_companydetails`.`address`, `companydetails_companydetails`.`city`, `companydetails_companydetails`.`country`, `companydetails_companydetails`.`email`, `companydetails_companydetails`.`phone` FROM `companydetails_companydetails`; args=()
2015-10-16 14:01:42,705 [DEBUG] django.db.backends: (0.002) SHOW TABLES; args=None
2015-10-16 14:01:42,748 [DEBUG] django.db.backends: (0.001) SELECT `django_migrations`.`app`, `django_migrations`.`name` FROM `django_migrations`; args=()
2015-10-16 14:02:37,005 [DEBUG] django.db.backends: (0.001) SELECT `companydetails_companydetails`.`id`, `companydetails_companydetails`.`company_id`, `companydetails_companydetails`.`name`, `companydetails_companydetails`.`address`, `companydetails_companydetails`.`city`, `companydetails_companydetails`.`country`, `companydetails_companydetails`.`email`, `companydetails_companydetails`.`phone` FROM `companydetails_companydetails`; args=()
2015-10-16 14:02:50,973 [DEBUG] django.db.backends: (0.001) SELECT `companydetails_companydetails`.`id`, `companydetails_companydetails`.`company_id`, `companydetails_companydetails`.`name`, `companydetails_companydetails`.`address`, `companydetails_companydetails`.`city`, `companydetails_companydetails`.`country`, `companydetails_companydetails`.`email`, `companydetails_companydetails`.`phone` FROM `companydetails_companydetails` WHERE `companydetails_companydetails`.`id` = 11 LIMIT 21; args=(11,)
2015-10-16 14:02:50,977 [DEBUG] django.db.backends: (0.000) DELETE FROM `companydetails_ownerdetails` WHERE `companydetails_ownerdetails`.`company_id` IN (11); args=(11,)
2015-10-16 14:02:50,980 [DEBUG] django.db.backends: (0.002) DELETE FROM `companydetails_companydetails` WHERE `companydetails_companydetails`.`id` IN (11); args=(11,)
2015-10-16 14:02:51,005 [DEBUG] django.db.backends: (0.001) SELECT `companydetails_companydetails`.`id`, `companydetails_companydetails`.`company_id`, `companydetails_companydetails`.`name`, `companydetails_companydetails`.`address`, `companydetails_companydetails`.`city`, `companydetails_companydetails`.`country`, `companydetails_companydetails`.`email`, `companydetails_companydetails`.`phone` FROM `companydetails_companydetails`; args=()
2015-10-16 14:03:46,017 [DEBUG] django.db.backends: (0.001) INSERT INTO `companydetails_companydetails` (`company_id`, `name`, `address`, `city`, `country`, `email`, `phone`) VALUES (105, 'EuroExpress', '5th Street', 'Stockholm', 'Sweden', 'euroexpress@mail.com', '547836543534'); args=[105, u'EuroExpress', u'5th Street', u'Stockholm', u'Sweden', u'euroexpress@mail.com', u'547836543534']
2015-10-16 14:03:46,020 [ERROR] django.request: Internal Server Error: /api/companylist/
Traceback (most recent call last):
  File "/Library/Python/2.7/site-packages/django/core/handlers/base.py", line 111, in get_response
    response = wrapped_callback(request, *callback_args, **callback_kwargs)
  File "/Library/Python/2.7/site-packages/django/views/decorators/csrf.py", line 57, in wrapped_view
    return view_func(*args, **kwargs)
  File "/Library/Python/2.7/site-packages/django/views/generic/base.py", line 69, in view
    return self.dispatch(request, *args, **kwargs)
  File "/Library/Python/2.7/site-packages/rest_framework/views.py", line 407, in dispatch
    response = self.handle_exception(exc)
  File "/Library/Python/2.7/site-packages/rest_framework/views.py", line 404, in dispatch
    response = handler(request, *args, **kwargs)
  File "/Library/Python/2.7/site-packages/rest_framework/decorators.py", line 50, in handler
    return func(*args, **kwargs)
  File "/Users/manoj/Documents/companyinfo/companydetails/views.py", line 39, in CompanyList
    return Response(serializer.data, status=status.HTTP_201_CREATED)
  File "/Library/Python/2.7/site-packages/rest_framework/serializers.py", line 463, in data
    ret = super(Serializer, self).data
  File "/Library/Python/2.7/site-packages/rest_framework/serializers.py", line 212, in data
    self._data = self.to_representation(self.instance)
  File "/Library/Python/2.7/site-packages/rest_framework/serializers.py", line 432, in to_representation
    ret[field.field_name] = field.to_representation(attribute)
  File "/Library/Python/2.7/site-packages/rest_framework/relations.py", line 240, in to_representation
    "the serializer." % self.__class__.__name__
AssertionError: `HyperlinkedIdentityField` requires the request in the serializer context. Add `context={'request': request}` when instantiating the serializer.
2015-10-16 14:04:13,981 [DEBUG] django.db.backends: (0.001) INSERT INTO `companydetails_companydetails` (`company_id`, `name`, `address`, `city`, `country`, `email`, `phone`) VALUES (105, 'EuroExpress', '5th Street', 'Stockholm', 'Sweden', 'euroexpress@mail.com', '547836543534'); args=[105, u'EuroExpress', u'5th Street', u'Stockholm', u'Sweden', u'euroexpress@mail.com', u'547836543534']
2015-10-16 14:04:13,983 [ERROR] django.request: Internal Server Error: /api/companylist/
Traceback (most recent call last):
  File "/Library/Python/2.7/site-packages/django/core/handlers/base.py", line 111, in get_response
    response = wrapped_callback(request, *callback_args, **callback_kwargs)
  File "/Library/Python/2.7/site-packages/django/views/decorators/csrf.py", line 57, in wrapped_view
    return view_func(*args, **kwargs)
  File "/Library/Python/2.7/site-packages/django/views/generic/base.py", line 69, in view
    return self.dispatch(request, *args, **kwargs)
  File "/Library/Python/2.7/site-packages/rest_framework/views.py", line 407, in dispatch
    response = self.handle_exception(exc)
  File "/Library/Python/2.7/site-packages/rest_framework/views.py", line 404, in dispatch
    response = handler(request, *args, **kwargs)
  File "/Library/Python/2.7/site-packages/rest_framework/decorators.py", line 50, in handler
    return func(*args, **kwargs)
  File "/Users/manoj/Documents/companyinfo/companydetails/views.py", line 38, in CompanyList
    serializer.save()
  File "/Library/Python/2.7/site-packages/rest_framework/serializers.py", line 164, in save
    self.instance = self.create(validated_data)
  File "/Users/manoj/Documents/companyinfo/companydetails/serializers.py", line 30, in create
    phone = validated_data['phone']
  File "/Library/Python/2.7/site-packages/django/db/models/manager.py", line 92, in manager_method
    return getattr(self.get_queryset(), name)(*args, **kwargs)
  File "/Library/Python/2.7/site-packages/django/db/models/query.py", line 372, in create
    obj.save(force_insert=True, using=self.db)
  File "/Library/Python/2.7/site-packages/django/db/models/base.py", line 589, in save
    force_update=force_update, update_fields=update_fields)
  File "/Library/Python/2.7/site-packages/django/db/models/base.py", line 617, in save_base
    updated = self._save_table(raw, cls, force_insert, force_update, using, update_fields)
  File "/Library/Python/2.7/site-packages/django/db/models/base.py", line 698, in _save_table
    result = self._do_insert(cls._base_manager, using, fields, update_pk, raw)
  File "/Library/Python/2.7/site-packages/django/db/models/base.py", line 731, in _do_insert
    using=using, raw=raw)
  File "/Library/Python/2.7/site-packages/django/db/models/manager.py", line 92, in manager_method
    return getattr(self.get_queryset(), name)(*args, **kwargs)
  File "/Library/Python/2.7/site-packages/django/db/models/query.py", line 921, in _insert
    return query.get_compiler(using=using).execute_sql(return_id)
  File "/Library/Python/2.7/site-packages/django/db/models/sql/compiler.py", line 920, in execute_sql
    cursor.execute(sql, params)
  File "/Library/Python/2.7/site-packages/django/db/backends/utils.py", line 81, in execute
    return super(CursorDebugWrapper, self).execute(sql, params)
  File "/Library/Python/2.7/site-packages/django/db/backends/utils.py", line 65, in execute
    return self.cursor.execute(sql, params)
  File "/Library/Python/2.7/site-packages/mysql/connector/django/base.py", line 135, in execute
    return self._execute_wrapper(self.cursor.execute, query, args)
  File "/Library/Python/2.7/site-packages/mysql/connector/django/base.py", line 121, in _execute_wrapper
    utils.IntegrityError(err.msg), sys.exc_info()[2])
  File "/Library/Python/2.7/site-packages/mysql/connector/django/base.py", line 115, in _execute_wrapper
    return method(query, args)
  File "/Library/Python/2.7/site-packages/mysql/connector/cursor.py", line 507, in execute
    self._handle_result(self._connection.cmd_query(stmt))
  File "/Library/Python/2.7/site-packages/mysql/connector/connection.py", line 722, in cmd_query
    result = self._handle_result(self._send_cmd(ServerCmd.QUERY, query))
  File "/Library/Python/2.7/site-packages/mysql/connector/connection.py", line 640, in _handle_result
    raise errors.get_exception(packet)
IntegrityError: Duplicate entry 'euroexpress@mail.com' for key 'companydetails_companydetails_email_54092f110edbe84c_uniq'
2015-10-16 14:04:14,179 [DEBUG] django.db.backends: (0.001) SELECT `companydetails_companydetails`.`id`, `companydetails_companydetails`.`company_id`, `companydetails_companydetails`.`name`, `companydetails_companydetails`.`address`, `companydetails_companydetails`.`city`, `companydetails_companydetails`.`country`, `companydetails_companydetails`.`email`, `companydetails_companydetails`.`phone` FROM `companydetails_companydetails` LIMIT 21; args=()
2015-10-16 14:04:14,185 [DEBUG] django.db.backends: (0.001) SELECT `companydetails_companydetails`.`id`, `companydetails_companydetails`.`company_id`, `companydetails_companydetails`.`name`, `companydetails_companydetails`.`address`, `companydetails_companydetails`.`city`, `companydetails_companydetails`.`country`, `companydetails_companydetails`.`email`, `companydetails_companydetails`.`phone` FROM `companydetails_companydetails` LIMIT 21; args=()
2015-10-16 14:04:48,302 [DEBUG] django.db.backends: (0.001) SELECT `companydetails_companydetails`.`id`, `companydetails_companydetails`.`company_id`, `companydetails_companydetails`.`name`, `companydetails_companydetails`.`address`, `companydetails_companydetails`.`city`, `companydetails_companydetails`.`country`, `companydetails_companydetails`.`email`, `companydetails_companydetails`.`phone` FROM `companydetails_companydetails`; args=()
2015-10-16 14:06:04,609 [DEBUG] django.db.backends: (0.001) INSERT INTO `companydetails_companydetails` (`company_id`, `name`, `address`, `city`, `country`, `email`, `phone`) VALUES (106, 'Food&Beverages', '15th Street', 'Berlin', 'Germany', 'foodnbeverages@mail.com', '6875467854654'); args=[106, u'Food&Beverages', u'15th Street', u'Berlin', u'Germany', u'foodnbeverages@mail.com', u'6875467854654']
2015-10-16 14:06:04,610 [ERROR] django.request: Internal Server Error: /api/companylist/
Traceback (most recent call last):
  File "/Library/Python/2.7/site-packages/django/core/handlers/base.py", line 111, in get_response
    response = wrapped_callback(request, *callback_args, **callback_kwargs)
  File "/Library/Python/2.7/site-packages/django/views/decorators/csrf.py", line 57, in wrapped_view
    return view_func(*args, **kwargs)
  File "/Library/Python/2.7/site-packages/django/views/generic/base.py", line 69, in view
    return self.dispatch(request, *args, **kwargs)
  File "/Library/Python/2.7/site-packages/rest_framework/views.py", line 407, in dispatch
    response = self.handle_exception(exc)
  File "/Library/Python/2.7/site-packages/rest_framework/views.py", line 404, in dispatch
    response = handler(request, *args, **kwargs)
  File "/Library/Python/2.7/site-packages/rest_framework/decorators.py", line 50, in handler
    return func(*args, **kwargs)
  File "/Users/manoj/Documents/companyinfo/companydetails/views.py", line 39, in CompanyList
    return Response(serializer.data, status=status.HTTP_201_CREATED)
  File "/Library/Python/2.7/site-packages/rest_framework/serializers.py", line 463, in data
    ret = super(Serializer, self).data
  File "/Library/Python/2.7/site-packages/rest_framework/serializers.py", line 212, in data
    self._data = self.to_representation(self.instance)
  File "/Library/Python/2.7/site-packages/rest_framework/serializers.py", line 432, in to_representation
    ret[field.field_name] = field.to_representation(attribute)
  File "/Library/Python/2.7/site-packages/rest_framework/relations.py", line 240, in to_representation
    "the serializer." % self.__class__.__name__
AssertionError: `HyperlinkedIdentityField` requires the request in the serializer context. Add `context={'request': request}` when instantiating the serializer.
2015-10-16 14:06:26,216 [DEBUG] django.db.backends: (0.001) SELECT `companydetails_companydetails`.`id`, `companydetails_companydetails`.`company_id`, `companydetails_companydetails`.`name`, `companydetails_companydetails`.`address`, `companydetails_companydetails`.`city`, `companydetails_companydetails`.`country`, `companydetails_companydetails`.`email`, `companydetails_companydetails`.`phone` FROM `companydetails_companydetails`; args=()
2015-10-16 14:08:04,693 [DEBUG] django.db.backends: (0.002) SHOW TABLES; args=None
2015-10-16 14:08:04,733 [DEBUG] django.db.backends: (0.001) SELECT `django_migrations`.`app`, `django_migrations`.`name` FROM `django_migrations`; args=()
2015-10-16 14:10:21,285 [DEBUG] django.db.backends: (0.001) INSERT INTO `companydetails_companydetails` (`company_id`, `name`, `address`, `city`, `country`, `email`, `phone`) VALUES (107, 'BeautyShop', 'CityTower', 'Frankfurt', 'Germany', 'beautyshop@mail.com', '8567575675675'); args=[107, u'BeautyShop', u'CityTower', u'Frankfurt', u'Germany', u'beautyshop@mail.com', u'8567575675675']
2015-10-16 14:10:21,321 [DEBUG] django.db.backends: (0.001) SELECT `companydetails_companydetails`.`id`, `companydetails_companydetails`.`company_id`, `companydetails_companydetails`.`name`, `companydetails_companydetails`.`address`, `companydetails_companydetails`.`city`, `companydetails_companydetails`.`country`, `companydetails_companydetails`.`email`, `companydetails_companydetails`.`phone` FROM `companydetails_companydetails`; args=()
2015-10-16 14:11:15,355 [DEBUG] django.db.backends: (0.001) SELECT `companydetails_companydetails`.`id`, `companydetails_companydetails`.`company_id`, `companydetails_companydetails`.`name`, `companydetails_companydetails`.`address`, `companydetails_companydetails`.`city`, `companydetails_companydetails`.`country`, `companydetails_companydetails`.`email`, `companydetails_companydetails`.`phone` FROM `companydetails_companydetails` WHERE `companydetails_companydetails`.`id` = 8 LIMIT 21; args=(8,)
2015-10-16 14:11:42,472 [DEBUG] django.db.backends: (0.001) SELECT `companydetails_companydetails`.`id`, `companydetails_companydetails`.`company_id`, `companydetails_companydetails`.`name`, `companydetails_companydetails`.`address`, `companydetails_companydetails`.`city`, `companydetails_companydetails`.`country`, `companydetails_companydetails`.`email`, `companydetails_companydetails`.`phone` FROM `companydetails_companydetails` WHERE `companydetails_companydetails`.`id` = 8 LIMIT 21; args=(8,)
2015-10-16 14:11:42,477 [ERROR] django.request: Internal Server Error: /api/companylist/8/
Traceback (most recent call last):
  File "/Library/Python/2.7/site-packages/django/core/handlers/base.py", line 111, in get_response
    response = wrapped_callback(request, *callback_args, **callback_kwargs)
  File "/Library/Python/2.7/site-packages/django/views/decorators/csrf.py", line 57, in wrapped_view
    return view_func(*args, **kwargs)
  File "/Library/Python/2.7/site-packages/django/views/generic/base.py", line 69, in view
    return self.dispatch(request, *args, **kwargs)
  File "/Library/Python/2.7/site-packages/rest_framework/views.py", line 407, in dispatch
    response = self.handle_exception(exc)
  File "/Library/Python/2.7/site-packages/rest_framework/views.py", line 404, in dispatch
    response = handler(request, *args, **kwargs)
  File "/Library/Python/2.7/site-packages/rest_framework/decorators.py", line 50, in handler
    return func(*args, **kwargs)
  File "/Users/manoj/Documents/companyinfo/companydetails/views.py", line 61, in CompanyListDetail
    serializer.save()
  File "/Library/Python/2.7/site-packages/rest_framework/serializers.py", line 161, in save
    '`update()` did not return an object instance.'
AssertionError: `update()` did not return an object instance.
2015-10-16 14:12:07,409 [DEBUG] django.db.backends: (0.001) SELECT `companydetails_companydetails`.`id`, `companydetails_companydetails`.`company_id`, `companydetails_companydetails`.`name`, `companydetails_companydetails`.`address`, `companydetails_companydetails`.`city`, `companydetails_companydetails`.`country`, `companydetails_companydetails`.`email`, `companydetails_companydetails`.`phone` FROM `companydetails_companydetails`; args=()
2015-10-16 14:12:24,736 [DEBUG] django.db.backends: (0.001) SELECT `companydetails_companydetails`.`id`, `companydetails_companydetails`.`company_id`, `companydetails_companydetails`.`name`, `companydetails_companydetails`.`address`, `companydetails_companydetails`.`city`, `companydetails_companydetails`.`country`, `companydetails_companydetails`.`email`, `companydetails_companydetails`.`phone` FROM `companydetails_companydetails` WHERE `companydetails_companydetails`.`id` = 8 LIMIT 21; args=(8,)
2015-10-16 14:12:24,739 [ERROR] django.request: Internal Server Error: /api/companylist/8/
Traceback (most recent call last):
  File "/Library/Python/2.7/site-packages/django/core/handlers/base.py", line 111, in get_response
    response = wrapped_callback(request, *callback_args, **callback_kwargs)
  File "/Library/Python/2.7/site-packages/django/views/decorators/csrf.py", line 57, in wrapped_view
    return view_func(*args, **kwargs)
  File "/Library/Python/2.7/site-packages/django/views/generic/base.py", line 69, in view
    return self.dispatch(request, *args, **kwargs)
  File "/Library/Python/2.7/site-packages/rest_framework/views.py", line 407, in dispatch
    response = self.handle_exception(exc)
  File "/Library/Python/2.7/site-packages/rest_framework/views.py", line 404, in dispatch
    response = handler(request, *args, **kwargs)
  File "/Library/Python/2.7/site-packages/rest_framework/decorators.py", line 50, in handler
    return func(*args, **kwargs)
  File "/Users/manoj/Documents/companyinfo/companydetails/views.py", line 61, in CompanyListDetail
    serializer.save()
  File "/Library/Python/2.7/site-packages/rest_framework/serializers.py", line 161, in save
    '`update()` did not return an object instance.'
AssertionError: `update()` did not return an object instance.
2015-10-16 14:16:01,326 [DEBUG] django.db.backends: (0.001) SHOW TABLES; args=None
2015-10-16 14:16:01,371 [DEBUG] django.db.backends: (0.002) SELECT `django_migrations`.`app`, `django_migrations`.`name` FROM `django_migrations`; args=()
2015-10-16 14:16:17,490 [DEBUG] django.db.backends: (0.001) SELECT `companydetails_companydetails`.`id`, `companydetails_companydetails`.`company_id`, `companydetails_companydetails`.`name`, `companydetails_companydetails`.`address`, `companydetails_companydetails`.`city`, `companydetails_companydetails`.`country`, `companydetails_companydetails`.`email`, `companydetails_companydetails`.`phone` FROM `companydetails_companydetails`; args=()
2015-10-16 14:16:35,078 [DEBUG] django.db.backends: (0.001) SHOW TABLES; args=None
2015-10-16 14:16:35,088 [DEBUG] django.db.backends: (0.001) SELECT `django_migrations`.`app`, `django_migrations`.`name` FROM `django_migrations`; args=()
2015-10-16 14:16:35,460 [DEBUG] django.db.backends: (0.001) SELECT `companydetails_companydetails`.`id`, `companydetails_companydetails`.`company_id`, `companydetails_companydetails`.`name`, `companydetails_companydetails`.`address`, `companydetails_companydetails`.`city`, `companydetails_companydetails`.`country`, `companydetails_companydetails`.`email`, `companydetails_companydetails`.`phone` FROM `companydetails_companydetails` WHERE `companydetails_companydetails`.`id` = 8 LIMIT 21; args=(8,)
2015-10-16 14:16:35,467 [DEBUG] django.db.backends: (0.003) UPDATE `companydetails_companydetails` SET `company_id` = 103, `name` = 'SeasonTravels', `address` = 'Vallensbaek', `city` = 'Copenhagen', `country` = 'Denmark', `email` = 'seasontravels@mail.com', `phone` = '67899000000' WHERE `companydetails_companydetails`.`id` = 8; args=(103, u'SeasonTravels', u'Vallensbaek', u'Copenhagen', u'Denmark', u'seasontravels@mail.com', u'67899000000', 8)
2015-10-16 14:16:35,469 [ERROR] django.request: Internal Server Error: /api/companylist/8/
Traceback (most recent call last):
  File "/Library/Python/2.7/site-packages/django/core/handlers/base.py", line 111, in get_response
    response = wrapped_callback(request, *callback_args, **callback_kwargs)
  File "/Library/Python/2.7/site-packages/django/views/decorators/csrf.py", line 57, in wrapped_view
    return view_func(*args, **kwargs)
  File "/Library/Python/2.7/site-packages/django/views/generic/base.py", line 69, in view
    return self.dispatch(request, *args, **kwargs)
  File "/Library/Python/2.7/site-packages/rest_framework/views.py", line 407, in dispatch
    response = self.handle_exception(exc)
  File "/Library/Python/2.7/site-packages/rest_framework/views.py", line 404, in dispatch
    response = handler(request, *args, **kwargs)
  File "/Library/Python/2.7/site-packages/rest_framework/decorators.py", line 50, in handler
    return func(*args, **kwargs)
  File "/Users/manoj/Documents/companyinfo/companydetails/views.py", line 62, in CompanyListDetail
    return Response(serializer.data)
  File "/Library/Python/2.7/site-packages/rest_framework/serializers.py", line 463, in data
    ret = super(Serializer, self).data
  File "/Library/Python/2.7/site-packages/rest_framework/serializers.py", line 212, in data
    self._data = self.to_representation(self.instance)
  File "/Library/Python/2.7/site-packages/rest_framework/serializers.py", line 432, in to_representation
    ret[field.field_name] = field.to_representation(attribute)
  File "/Library/Python/2.7/site-packages/rest_framework/relations.py", line 240, in to_representation
    "the serializer." % self.__class__.__name__
AssertionError: `HyperlinkedIdentityField` requires the request in the serializer context. Add `context={'request': request}` when instantiating the serializer.
2015-10-16 14:17:07,126 [DEBUG] django.db.backends: (0.001) SHOW TABLES; args=None
2015-10-16 14:17:07,136 [DEBUG] django.db.backends: (0.001) SELECT `django_migrations`.`app`, `django_migrations`.`name` FROM `django_migrations`; args=()
2015-10-16 14:17:18,627 [DEBUG] django.db.backends: (0.001) SELECT `companydetails_companydetails`.`id`, `companydetails_companydetails`.`company_id`, `companydetails_companydetails`.`name`, `companydetails_companydetails`.`address`, `companydetails_companydetails`.`city`, `companydetails_companydetails`.`country`, `companydetails_companydetails`.`email`, `companydetails_companydetails`.`phone` FROM `companydetails_companydetails` WHERE `companydetails_companydetails`.`id` = 8 LIMIT 21; args=(8,)
2015-10-16 14:17:18,633 [DEBUG] django.db.backends: (0.001) UPDATE `companydetails_companydetails` SET `company_id` = 103, `name` = 'SeasonTravels', `address` = 'Vallensbaek', `city` = 'Copenhagen', `country` = 'Denmark', `email` = 'seasontravels@mail.com', `phone` = '67899000000' WHERE `companydetails_companydetails`.`id` = 8; args=(103, u'SeasonTravels', u'Vallensbaek', u'Copenhagen', u'Denmark', u'seasontravels@mail.com', u'67899000000', 8)
2015-10-16 14:17:18,659 [DEBUG] django.db.backends: (0.001) SELECT `companydetails_companydetails`.`id`, `companydetails_companydetails`.`company_id`, `companydetails_companydetails`.`name`, `companydetails_companydetails`.`address`, `companydetails_companydetails`.`city`, `companydetails_companydetails`.`country`, `companydetails_companydetails`.`email`, `companydetails_companydetails`.`phone` FROM `companydetails_companydetails`; args=()
2015-10-16 14:17:48,149 [DEBUG] django.db.backends: (0.001) SELECT `companydetails_companydetails`.`id`, `companydetails_companydetails`.`company_id`, `companydetails_companydetails`.`name`, `companydetails_companydetails`.`address`, `companydetails_companydetails`.`city`, `companydetails_companydetails`.`country`, `companydetails_companydetails`.`email`, `companydetails_companydetails`.`phone` FROM `companydetails_companydetails`; args=()
2015-10-16 14:17:48,220 [DEBUG] MARKDOWN: Successfuly imported extension module "markdown.extensions.headerid".
2015-10-16 14:17:48,220 [DEBUG] MARKDOWN: Successfully loaded extension "markdown.extensions.headerid.HeaderIdExtension".
2015-10-16 14:19:30,262 [DEBUG] MARKDOWN: Successfuly imported extension module "markdown.extensions.headerid".
2015-10-16 14:19:30,263 [DEBUG] MARKDOWN: Successfully loaded extension "markdown.extensions.headerid.HeaderIdExtension".
2015-10-16 14:19:40,011 [DEBUG] django.db.backends: (0.001) SELECT `companydetails_companydetails`.`id`, `companydetails_companydetails`.`company_id`, `companydetails_companydetails`.`name`, `companydetails_companydetails`.`address`, `companydetails_companydetails`.`city`, `companydetails_companydetails`.`country`, `companydetails_companydetails`.`email`, `companydetails_companydetails`.`phone` FROM `companydetails_companydetails`; args=()
2015-10-16 14:19:40,019 [DEBUG] MARKDOWN: Successfuly imported extension module "markdown.extensions.headerid".
2015-10-16 14:19:40,019 [DEBUG] MARKDOWN: Successfully loaded extension "markdown.extensions.headerid.HeaderIdExtension".
2015-10-16 14:19:50,936 [DEBUG] MARKDOWN: Successfuly imported extension module "markdown.extensions.headerid".
2015-10-16 14:19:50,937 [DEBUG] MARKDOWN: Successfully loaded extension "markdown.extensions.headerid.HeaderIdExtension".
2015-10-16 14:20:00,673 [DEBUG] django.db.backends: (0.001) SELECT `companydetails_companydetails`.`id`, `companydetails_companydetails`.`company_id`, `companydetails_companydetails`.`name`, `companydetails_companydetails`.`address`, `companydetails_companydetails`.`city`, `companydetails_companydetails`.`country`, `companydetails_companydetails`.`email`, `companydetails_companydetails`.`phone` FROM `companydetails_companydetails`; args=()
2015-10-16 14:20:00,680 [DEBUG] MARKDOWN: Successfuly imported extension module "markdown.extensions.headerid".
2015-10-16 14:20:00,680 [DEBUG] MARKDOWN: Successfully loaded extension "markdown.extensions.headerid.HeaderIdExtension".
2015-10-16 14:20:35,093 [DEBUG] MARKDOWN: Successfuly imported extension module "markdown.extensions.headerid".
2015-10-16 14:20:35,093 [DEBUG] MARKDOWN: Successfully loaded extension "markdown.extensions.headerid.HeaderIdExtension".
2015-10-16 14:20:45,214 [DEBUG] django.db.backends: (0.001) SELECT `companydetails_companydetails`.`id`, `companydetails_companydetails`.`company_id`, `companydetails_companydetails`.`name`, `companydetails_companydetails`.`address`, `companydetails_companydetails`.`city`, `companydetails_companydetails`.`country`, `companydetails_companydetails`.`email`, `companydetails_companydetails`.`phone` FROM `companydetails_companydetails`; args=()
2015-10-16 14:20:45,221 [DEBUG] MARKDOWN: Successfuly imported extension module "markdown.extensions.headerid".
2015-10-16 14:20:45,221 [DEBUG] MARKDOWN: Successfully loaded extension "markdown.extensions.headerid.HeaderIdExtension".
2015-10-16 14:21:35,564 [DEBUG] django.db.backends: (0.001) SELECT `companydetails_companydetails`.`id`, `companydetails_companydetails`.`company_id`, `companydetails_companydetails`.`name`, `companydetails_companydetails`.`address`, `companydetails_companydetails`.`city`, `companydetails_companydetails`.`country`, `companydetails_companydetails`.`email`, `companydetails_companydetails`.`phone` FROM `companydetails_companydetails` WHERE `companydetails_companydetails`.`id` = 21 LIMIT 21; args=(21,)
2015-10-16 14:21:35,571 [DEBUG] MARKDOWN: Successfuly imported extension module "markdown.extensions.headerid".
2015-10-16 14:21:35,572 [DEBUG] MARKDOWN: Successfully loaded extension "markdown.extensions.headerid.HeaderIdExtension".
2015-10-16 14:21:39,158 [DEBUG] django.db.backends: (0.001) SELECT `companydetails_companydetails`.`id`, `companydetails_companydetails`.`company_id`, `companydetails_companydetails`.`name`, `companydetails_companydetails`.`address`, `companydetails_companydetails`.`city`, `companydetails_companydetails`.`country`, `companydetails_companydetails`.`email`, `companydetails_companydetails`.`phone` FROM `companydetails_companydetails` WHERE `companydetails_companydetails`.`id` = 21 LIMIT 21; args=(21,)
2015-10-16 14:21:39,162 [DEBUG] django.db.backends: (0.000) DELETE FROM `companydetails_ownerdetails` WHERE `companydetails_ownerdetails`.`company_id` IN (21); args=(21,)
2015-10-16 14:21:39,163 [DEBUG] django.db.backends: (0.000) DELETE FROM `companydetails_companydetails` WHERE `companydetails_companydetails`.`id` IN (21); args=(21,)
2015-10-16 14:21:46,130 [DEBUG] django.db.backends: (0.001) SELECT `companydetails_companydetails`.`id`, `companydetails_companydetails`.`company_id`, `companydetails_companydetails`.`name`, `companydetails_companydetails`.`address`, `companydetails_companydetails`.`city`, `companydetails_companydetails`.`country`, `companydetails_companydetails`.`email`, `companydetails_companydetails`.`phone` FROM `companydetails_companydetails` WHERE `companydetails_companydetails`.`id` = 21 LIMIT 21; args=(21,)
2015-10-16 14:21:52,863 [DEBUG] django.db.backends: (0.001) SELECT `companydetails_companydetails`.`id`, `companydetails_companydetails`.`company_id`, `companydetails_companydetails`.`name`, `companydetails_companydetails`.`address`, `companydetails_companydetails`.`city`, `companydetails_companydetails`.`country`, `companydetails_companydetails`.`email`, `companydetails_companydetails`.`phone` FROM `companydetails_companydetails`; args=()
2015-10-16 14:21:52,869 [DEBUG] MARKDOWN: Successfuly imported extension module "markdown.extensions.headerid".
2015-10-16 14:21:52,870 [DEBUG] MARKDOWN: Successfully loaded extension "markdown.extensions.headerid.HeaderIdExtension".
2015-10-16 14:22:04,041 [DEBUG] django.db.backends: (0.001) SELECT `companydetails_companydetails`.`id`, `companydetails_companydetails`.`company_id`, `companydetails_companydetails`.`name`, `companydetails_companydetails`.`address`, `companydetails_companydetails`.`city`, `companydetails_companydetails`.`country`, `companydetails_companydetails`.`email`, `companydetails_companydetails`.`phone` FROM `companydetails_companydetails` WHERE `companydetails_companydetails`.`id` = 20 LIMIT 21; args=(20,)
2015-10-16 14:22:04,048 [DEBUG] MARKDOWN: Successfuly imported extension module "markdown.extensions.headerid".
2015-10-16 14:22:04,048 [DEBUG] MARKDOWN: Successfully loaded extension "markdown.extensions.headerid.HeaderIdExtension".
2015-10-16 14:22:40,317 [DEBUG] django.db.backends: (0.001) SELECT `companydetails_companydetails`.`id`, `companydetails_companydetails`.`company_id`, `companydetails_companydetails`.`name`, `companydetails_companydetails`.`address`, `companydetails_companydetails`.`city`, `companydetails_companydetails`.`country`, `companydetails_companydetails`.`email`, `companydetails_companydetails`.`phone` FROM `companydetails_companydetails` WHERE `companydetails_companydetails`.`id` = 20 LIMIT 21; args=(20,)
2015-10-16 14:22:40,325 [DEBUG] django.db.backends: (0.001) UPDATE `companydetails_companydetails` SET `company_id` = 107, `name` = 'BeautyShop', `address` = 'CityTower', `city` = 'Frankfurt', `country` = 'Germany', `email` = 'beautyshop@mail.com', `phone` = '8567575675675' WHERE `companydetails_companydetails`.`id` = 20; args=(107, u'BeautyShop', u'CityTower', u'Frankfurt', u'Germany', u'beautyshop@mail.com', u'8567575675675', 20)
2015-10-16 14:22:40,330 [DEBUG] MARKDOWN: Successfuly imported extension module "markdown.extensions.headerid".
2015-10-16 14:22:40,331 [DEBUG] MARKDOWN: Successfully loaded extension "markdown.extensions.headerid.HeaderIdExtension".
2015-10-16 14:23:30,568 [DEBUG] django.db.backends: (0.001) SHOW TABLES; args=None
2015-10-16 14:23:30,577 [DEBUG] django.db.backends: (0.001) SELECT `django_migrations`.`app`, `django_migrations`.`name` FROM `django_migrations`; args=()
